<?xml version="1.0" ?>
<!-- =================================================================================== -->
<!-- |    This document was autogenerated by xacro from /home/imbatman/smdw_ws/src/agri_bot/urdf/agri_bot.urdf.xacro | -->
<!-- |    EDITING THIS FILE BY HAND IS NOT RECOMMENDED                                 | -->
<!-- =================================================================================== -->
<robot name="agri_bot">
  <!-- xoxoxoxoxoxoxx                 seee thisss                      xoxoxoxoxoxox -->
  <!-- when you want to launch agri_bot then go to xaarm and smdw_robot_base and comment out lines that, xacro include ros2_control.xaro and gazebo.xacro
   coz we have created both files for this agri_bot, that includes both robot's ros2_control and gazebo.xacro -->
  <!-- <xacro:include filename="$(find smdw_robot_base)/urdf/camera.xacro"/>
  <xacro:include filename="$(find smdw_robot_base)/urdf/lidar.xacro"/> -->
  <!-- if you wannt to launch the robot then uncomment this following lines/ but if you launch agri_bot then dnt forget to comment this  -->
  <!-- <xacro:include filename="$(find smdw_robot_base)/urdf/ros2_control.xacro"/>
  <xacro:include filename="$(find smdw_robot_base)/urdf/gazebo.xacro"/> -->
  <!-- _______________________________________________________________________________________ -->
  <link name="odom">
  </link>
  <joint name="odom_to_base_footprint" type="fixed">
    <origin rpy="0 0 0" xyz="0 0 0"/>
    <parent link="odom"/>
    <child link="base_footprint"/>
  </joint>
  <!-- Fixed joint between base_footprint and base_link -->
  <joint name="base_fixed_joint" type="fixed">
    <origin rpy="0 0 0" xyz="0 0 0.0508"/>
    <parent link="base_footprint"/>
    <child link="base_link"/>
  </joint>
  <!-- Base footprint -->
  <link name="base_footprint"/>
  <!-- Base link -->
  <link name="base_link">
    <inertial>
      <origin rpy="0 0 0" xyz="5.48421351341662E-17 -4.87352495342906E-17 0.0508"/>
      <mass value="32.9182761436536"/>
      <inertia ixx="0.745163960934943" ixy="3.59989002583078E-17" ixz="-2.00803277362423E-19" iyy="1.13620249698633" iyz="1.90637586064413E-17" izz="1.82496934930628"/>
    </inertial>
    <visual>
      <origin rpy="0 0 0" xyz="0 0 0"/>
      <geometry>
        <mesh filename="file:///home/imbatman/smdw_ws/src/smdw_robot_base/meshes/robot_base_link.STL"/>
      </geometry>
      <material name="">
        <color rgba="0.792156862745098 0.819607843137255 0.933333333333333 1"/>
      </material>
    </visual>
    <collision>
      <origin rpy="0 0 0" xyz="0 0 0"/>
      <geometry>
        <mesh filename="file:///home/imbatman/smdw_ws/src/smdw_robot_base/meshes/robot_base_link.STL"/>
      </geometry>
    </collision>
  </link>
  <!-- Define materials -->
  <material name="front_left_base_color">
    <color rgba="0.79216 0.81961 0.93333 1"/>
  </material>
  <material name="front_left_wheel_color">
    <color rgba="0.25098 0.25098 0.25098 1"/>
  </material>
  <!-- Base link -->
  <link name="front_left_base_link">
    <inertial>
      <origin rpy="0 0 0" xyz="-4.3311E-18 1.504E-12 1.7857E-18"/>
      <mass value="1.9429"/>
      <inertia ixx="0.0019245" ixy="8.1609E-21" ixz="-8.1689E-08" iyy="0.0049239" iyz="-7.5092E-20" izz="0.0032216"/>
    </inertial>
    <visual>
      <origin rpy="0 0 0" xyz="0 0 0"/>
      <geometry>
        <mesh filename="file:///home/imbatman/smdw_ws/src/left_smdw/meshes/front_left_wheel_base_link.STL"/>
      </geometry>
      <material name="front_left_wheel_color"/>
    </visual>
    <collision>
      <origin rpy="0 0 0" xyz="0 0 0"/>
      <geometry>
        <mesh filename="file:///home/imbatman/smdw_ws/src/left_smdw/meshes/front_left_wheel_base_link.STL"/>
      </geometry>
    </collision>
  </link>
  <!-- Define materials -->
  <material name="rear_right_base_color">
    <color rgba="0.79216 0.81961 0.93333 1"/>
  </material>
  <material name="rear_right_wheel_color">
    <color rgba="0.25098 0.25098 0.25098 1"/>
  </material>
  <!-- Base link -->
  <link name="rear_right_base_link">
    <inertial>
      <origin rpy="0 0 0" xyz="-4.3311E-18 1.504E-12 1.7857E-18"/>
      <mass value="1.9429"/>
      <inertia ixx="0.0019245" ixy="8.1609E-21" ixz="-8.1689E-08" iyy="0.0049239" iyz="-7.5092E-20" izz="0.0032216"/>
    </inertial>
    <visual>
      <origin rpy="0 0 0" xyz="0 0 0"/>
      <geometry>
        <mesh filename="file:///home/imbatman/smdw_ws/src/left_smdw/meshes/front_left_wheel_base_link.STL"/>
      </geometry>
      <material name="rear_right_wheel_color"/>
    </visual>
    <collision>
      <origin rpy="0 0 0" xyz="0 0 0"/>
      <geometry>
        <mesh filename="file:///home/imbatman/smdw_ws/src/left_smdw/meshes/front_left_wheel_base_link.STL"/>
      </geometry>
    </collision>
  </link>
  <!-- Define materials -->
  <material name="front_right_base_color">
    <color rgba="0.79216 0.81961 0.93333 1"/>
  </material>
  <material name="front_right_wheel_color">
    <color rgba="0.25098 0.25098 0.25098 1"/>
  </material>
  <!-- Base link -->
  <link name="front_right_base_link">
    <inertial>
      <origin rpy="0 0 0" xyz="-4.3311E-18 1.504E-12 1.7857E-18"/>
      <mass value="1.9429"/>
      <inertia ixx="0.0019245" ixy="8.1609E-21" ixz="-8.1689E-08" iyy="0.0049239" iyz="-7.5092E-20" izz="0.0032216"/>
    </inertial>
    <visual>
      <origin rpy="0 0 0" xyz="0 0 0"/>
      <geometry>
        <mesh filename="file:///home/imbatman/smdw_ws/src/right_smdw/meshes/front_right_wheel_base_link.STL"/>
      </geometry>
      <material name="front_right_wheel_color"/>
    </visual>
    <collision>
      <origin rpy="0 0 0" xyz="0 0 0"/>
      <geometry>
        <mesh filename="file:///home/imbatman/smdw_ws/src/right_smdw/meshes/front_right_wheel_base_link.STL"/>
      </geometry>
    </collision>
  </link>
  <!-- Define materials -->
  <material name="rear_left_base_color">
    <color rgba="0.79216 0.81961 0.93333 1"/>
  </material>
  <material name="rear_left_wheel_color">
    <color rgba="0.25098 0.25098 0.25098 1"/>
  </material>
  <!-- Base link -->
  <link name="rear_left_base_link">
    <inertial>
      <origin rpy="0 0 0" xyz="-4.3311E-18 1.504E-12 1.7857E-18"/>
      <mass value="1.9429"/>
      <inertia ixx="0.0019245" ixy="8.1609E-21" ixz="-8.1689E-08" iyy="0.0049239" iyz="-7.5092E-20" izz="0.0032216"/>
    </inertial>
    <visual>
      <origin rpy="0 0 0" xyz="0 0 0"/>
      <geometry>
        <mesh filename="file:///home/imbatman/smdw_ws/src/right_smdw/meshes/front_right_wheel_base_link.STL"/>
      </geometry>
      <material name="rear_left_wheel_color"/>
    </visual>
    <collision>
      <origin rpy="0 0 0" xyz="0 0 0"/>
      <geometry>
        <mesh filename="file:///home/imbatman/smdw_ws/src/right_smdw/meshes/front_right_wheel_base_link.STL"/>
      </geometry>
    </collision>
  </link>
  <!-- Attach wheels to base_link -->
  <joint name="front_left_wheel_joint" type="continuous">
    <parent link="base_link"/>
    <child link="front_left_base_link"/>
    <origin rpy="0 0 0" xyz="0.2159 0.3175 0.0508"/>
    <axis xyz="0 1 0"/>
    <limit effort="100.0" velocity="10.0"/>
    <dynamics friction="0.001"/>
  </joint>
  <joint name="rear_left_wheel_joint" type="continuous">
    <parent link="base_link"/>
    <child link="rear_left_base_link"/>
    <origin rpy="0 0 0" xyz="-0.2159 0.3175 0.0508"/>
    <axis xyz="0 1 0"/>
    <limit effort="100.0" velocity="10.0"/>
    <dynamics friction="0.001"/>
  </joint>
  <joint name="front_right_wheel_joint" type="continuous">
    <parent link="base_link"/>
    <child link="front_right_base_link"/>
    <origin rpy="0 0 0" xyz="0.2159 -0.3175 0.0508"/>
    <axis xyz="0 1 0"/>
    <limit effort="100.0" velocity="10.0"/>
    <dynamics friction="0.001"/>
  </joint>
  <joint name="rear_right_wheel_joint" type="continuous">
    <parent link="base_link"/>
    <child link="rear_right_base_link"/>
    <origin rpy="0 0 0" xyz="-0.2159 -0.3175 0.0508"/>
    <axis xyz="0 1 0"/>
    <limit effort="100.0" velocity="10.0"/>
    <dynamics friction="0.001"/>
  </joint>
  <!-- remove this comment to only use arm/ comment this when to attach with mobile base robot -->
  <!-- 
  <link name="world" />
  <joint name="base_joint" type="fixed">
      <parent link="world" />
      <child link="xaarm_base_link" />
    <origin rpy="0 0 0" xyz="0.0 0.0 0.0" />
  </joint> -->
  <!-- _______________________________________________________________________________________________________________ -->
  <link name="xaarm_base_link">
    <inertial>
      <origin rpy="0 0 0" xyz="0 0.0003 0.0726"/>
      <mass value="8.3079"/>
      <inertia ixx="0.0224" ixy="0" ixz="0" iyy="0.0223" iyz="0.0001" izz="0.0103"/>
    </inertial>
    <visual>
      <origin rpy="0 0 0" xyz="0 0 0"/>
      <geometry>
        <mesh filename="file:///home/imbatman/agribot_ws/src/xaarm/meshes/xaarm_base_link.STL"/>
      </geometry>
      <material name="">
        <color rgba="0.6471 0.6196 0.5882 1"/>
      </material>
    </visual>
    <collision>
      <origin rpy="0 0 0" xyz="0 0 0"/>
      <geometry>
        <mesh filename="file:///home/imbatman/agribot_ws/src/xaarm/meshes/xaarm_base_link.STL"/>
      </geometry>
    </collision>
  </link>
  <link name="link_1">
    <inertial>
      <origin rpy="0 0 0" xyz="-0.0016 -0.0004 0.0844"/>
      <mass value="2.4510"/>
      <inertia ixx="0.0065" ixy="-0.0002" ixz="0.0004" iyy="0.0073" iyz="0.0001" izz="0.0037"/>
    </inertial>
    <visual>
      <origin rpy="0 0 0" xyz="0 0 0"/>
      <geometry>
        <mesh filename="file:///home/imbatman/agribot_ws/src/xaarm/meshes/link_1.STL"/>
      </geometry>
      <material name="">
        <color rgba="1 1 1 1"/>
      </material>
    </visual>
    <collision>
      <origin rpy="0 0 0" xyz="0 0 0"/>
      <geometry>
        <mesh filename="file:///home/imbatman/agribot_ws/src/xaarm/meshes/link_1.STL"/>
      </geometry>
    </collision>
  </link>
  <link name="link_2">
    <inertial>
      <origin rpy="0 0 0" xyz="0.0436 -0.1601 0.0408"/>
      <mass value="5.5903"/>
      <inertia ixx="0.0535" ixy="0.0093" ixz="-0.0030" iyy="0.0208" iyz="0.0144" izz="0.0577"/>
    </inertial>
    <visual>
      <origin rpy="0 0 0" xyz="0 0 0"/>
      <geometry>
        <mesh filename="file:///home/imbatman/agribot_ws/src/xaarm/meshes/link_2.STL"/>
      </geometry>
      <material name="">
        <color rgba="1 1 1 1"/>
      </material>
    </visual>
    <collision>
      <origin rpy="0 0 0" xyz="0 0 0"/>
      <geometry>
        <mesh filename="file:///home/imbatman/agribot_ws/src/xaarm/meshes/link_2.STL"/>
      </geometry>
    </collision>
  </link>
  <link name="link_3">
    <inertial>
      <origin rpy="0 0 0" xyz="-0.0018 0.0824 0.0571"/>
      <mass value="2.7405"/>
      <inertia ixx="0.0123" ixy="-0.0028" ixz="-0.0020" iyy="0.0087" iyz="-0.0043" izz="0.0119"/>
    </inertial>
    <visual>
      <origin rpy="0 0 0" xyz="0 0 0"/>
      <geometry>
        <mesh filename="file:///home/imbatman/agribot_ws/src/xaarm/meshes/link_3.STL"/>
      </geometry>
      <material name="">
        <color rgba="1 1 1 1"/>
      </material>
    </visual>
    <collision>
      <origin rpy="0 0 0" xyz="0 0 0"/>
      <geometry>
        <mesh filename="file:///home/imbatman/agribot_ws/src/xaarm/meshes/link_3.STL"/>
      </geometry>
    </collision>
  </link>
  <link name="link_4">
    <inertial>
      <origin rpy="0 0 0" xyz="-0.0071 0.0238 0.1233"/>
      <mass value="1.2807"/>
      <inertia ixx="0.0094" ixy="0.0001" ixz="0" iyy="0.0091" iyz="-0.0007" izz="0.0014"/>
    </inertial>
    <visual>
      <origin rpy="0 0 0" xyz="0 0 0"/>
      <geometry>
        <mesh filename="file:///home/imbatman/agribot_ws/src/xaarm/meshes/link_4.STL"/>
      </geometry>
      <material name="">
        <color rgba="1 1 1 1"/>
      </material>
    </visual>
    <collision>
      <origin rpy="0 0 0" xyz="0 0 0"/>
      <geometry>
        <mesh filename="file:///home/imbatman/agribot_ws/src/xaarm/meshes/link_4.STL"/>
      </geometry>
    </collision>
  </link>
  <link name="link_5">
    <inertial>
      <origin rpy="0 0 0" xyz="-0.0122 -0.0571 0.0108"/>
      <mass value="1.2585"/>
      <inertia ixx="0.0022" ixy="-0.0004" ixz="0.0001" iyy="0.0015" iyz="-0.0002" izz="0.0027"/>
    </inertial>
    <visual>
      <origin rpy="0 0 0" xyz="0 0 0"/>
      <geometry>
        <mesh filename="file:///home/imbatman/agribot_ws/src/xaarm/meshes/link_5.STL"/>
      </geometry>
      <material name="">
        <color rgba="1 1 1 1"/>
      </material>
    </visual>
    <collision>
      <origin rpy="0 0 0" xyz="0 0 0"/>
      <geometry>
        <mesh filename="file:///home/imbatman/agribot_ws/src/xaarm/meshes/link_5.STL"/>
      </geometry>
    </collision>
  </link>
  <link name="end_effector">
    <inertial>
      <origin rpy="0 0 0" xyz="-0.0001 0 0.0096"/>
      <mass value="0.1516"/>
      <inertia ixx="0.0001" ixy="0" ixz="0" iyy="0.0001" iyz="0" izz="0.0001"/>
    </inertial>
    <visual>
      <origin rpy="0 0 0" xyz="0 0 0"/>
      <geometry>
        <mesh filename="file:///home/imbatman/agribot_ws/src/xaarm/meshes/end_effector.STL"/>
      </geometry>
      <material name="">
        <color rgba="1 1 1 1"/>
      </material>
    </visual>
    <collision>
      <origin rpy="0 0 0" xyz="0 0 0"/>
      <geometry>
        <mesh filename="file:///home/imbatman/agribot_ws/src/xaarm/meshes/end_effector.STL"/>
      </geometry>
    </collision>
  </link>
  <link name="gripper_base">
    <inertial>
      <origin rpy="0 0 0" xyz="0.0002 0 0.0346"/>
      <mass value="0.1959"/>
      <inertia ixx="0.0002" ixy="0" ixz="0" iyy="0.0003" iyz="0" izz="0.0001"/>
    </inertial>
    <visual>
      <origin rpy="0 0 0" xyz="0 0 0"/>
      <geometry>
        <mesh filename="file:///home/imbatman/agribot_ws/src/xaarm/meshes/gripper_base.STL"/>
      </geometry>
      <material name="">
        <color rgba="1 1 1 1"/>
      </material>
    </visual>
    <collision>
      <origin rpy="0 0 0" xyz="0 0 0"/>
      <geometry>
        <mesh filename="file:///home/imbatman/agribot_ws/src/xaarm/meshes/gripper_base.STL"/>
      </geometry>
    </collision>
  </link>
  <link name="right_gripper_arm">
    <inertial>
      <origin rpy="0 0 0" xyz="0.0426 0.0216 0"/>
      <mass value="0.0124"/>
      <inertia ixx="2.10000431804118E-06" ixy="-1.9640172280351E-06" ixz="-1.27319639884162E-20" iyy="8.48619770875024E-06" iyz="-2.01170324972896E-20" izz="1.03749899733759E-05"/>
    </inertial>
    <visual>
      <origin rpy="0 0 0" xyz="0 0 0"/>
      <geometry>
        <mesh filename="file:///home/imbatman/agribot_ws/src/xaarm/meshes/right_gripper_arm.STL"/>
      </geometry>
      <material name="">
        <color rgba="1 1 1 1"/>
      </material>
    </visual>
    <collision>
      <origin rpy="0 0 0" xyz="0 0 0"/>
      <geometry>
        <mesh filename="file:///home/imbatman/agribot_ws/src/xaarm/meshes/right_gripper_arm.STL"/>
      </geometry>
    </collision>
  </link>
  <link name="right_tip">
    <inertial>
      <origin rpy="0 0 0" xyz="0.0225 0.0082 -0.0050"/>
      <mass value="0.0068"/>
      <inertia ixx="0" ixy="-0.0001" ixz="0" iyy="0.0001" iyz="0" izz="0.0001"/>
    </inertial>
    <visual>
      <origin rpy="0 0 0" xyz="0 0 0"/>
      <geometry>
        <mesh filename="file:///home/imbatman/agribot_ws/src/xaarm/meshes/right_tip.STL"/>
      </geometry>
      <material name="">
        <color rgba="0.2510 0.2510 0.2510 1"/>
      </material>
    </visual>
    <collision>
      <origin rpy="0 0 0" xyz="0 0 0"/>
      <geometry>
        <mesh filename="file:///home/imbatman/agribot_ws/src/xaarm/meshes/right_tip.STL"/>
      </geometry>
    </collision>
  </link>
  <link name="left_gripper_arm">
    <inertial>
      <origin rpy="0 0 0" xyz="0.0426 0.0216 0"/>
      <mass value="0.0124"/>
      <inertia ixx="2.10000431804118E-06" ixy="-1.96401722803509E-06" ixz="-5.29395592033938E-23" iyy="8.48619770875023E-06" iyz="-8.470329472543E-22" izz="1.03749899733759E-05"/>
    </inertial>
    <visual>
      <origin rpy="0 0 0" xyz="0 0 0"/>
      <geometry>
        <mesh filename="file:///home/imbatman/agribot_ws/src/xaarm/meshes/left_gripper_arm.STL"/>
      </geometry>
      <material name="">
        <color rgba="1 1 1 1"/>
      </material>
    </visual>
    <collision>
      <origin rpy="0 0 0" xyz="0 0 0"/>
      <geometry>
        <mesh filename="file:///home/imbatman/agribot_ws/src/xaarm/meshes/left_gripper_arm.STL"/>
      </geometry>
    </collision>
  </link>
  <link name="left_tip">
    <inertial>
      <origin rpy="0 0 0" xyz="0.0225 -0.0082 0"/>
      <mass value="0.0068"/>
      <inertia ixx="0" ixy="0.0001" ixz="0" iyy="0.0001" iyz="0" izz="0.0001"/>
    </inertial>
    <visual>
      <origin rpy="0 0 0" xyz="0 0 0"/>
      <geometry>
        <mesh filename="file:///home/imbatman/agribot_ws/src/xaarm/meshes/left_tip.STL"/>
      </geometry>
      <material name="">
        <color rgba="0.2510 0.2510 0.2510 1"/>
      </material>
    </visual>
    <collision>
      <origin rpy="0 0 0" xyz="0 0 0"/>
      <geometry>
        <mesh filename="file:///home/imbatman/agribot_ws/src/xaarm/meshes/left_tip.STL"/>
      </geometry>
    </collision>
  </link>
  <link name="gripper_camera">
    <inertial>
      <origin rpy="0 0 0" xyz="-0.0088 0 0"/>
      <mass value="0.0208"/>
      <inertia ixx="0" ixy="0" ixz="0" iyy="0" iyz="0" izz="0"/>
    </inertial>
    <visual>
      <origin rpy="0 0 0" xyz="0 0 0"/>
      <geometry>
        <mesh filename="file:///home/imbatman/agribot_ws/src/xaarm/meshes/gripper_camera.STL"/>
      </geometry>
      <material name="">
        <color rgba="0.7922 0.8196 0.9333 1"/>
      </material>
    </visual>
    <collision>
      <origin rpy="0 0 0" xyz="0 0 0"/>
      <geometry>
        <mesh filename="file:///home/imbatman/agribot_ws/src/xaarm/meshes/gripper_camera.STL"/>
      </geometry>
    </collision>
  </link>
  <joint name="joint_1" type="revolute">
    <origin rpy="0 0 0" xyz="0 0 0.1540"/>
    <parent link="xaarm_base_link"/>
    <child link="link_1"/>
    <axis xyz="0 0 -1"/>
    <limit effort="11" lower="0" upper="6.28" velocity="5.0"/>
    <dynamics damping="0.5" friction="0.1"/>
  </joint>
  <joint name="joint_2" type="revolute">
    <origin rpy="-1.5708 0 0" xyz="-0.0630 -0.0176 0.1150"/>
    <parent link="link_1"/>
    <child link="link_2"/>
    <axis xyz="0.9633 0 0.2685"/>
    <limit effort="11" lower="0" upper="2.059" velocity="5.0"/>
    <dynamics damping="0.5" friction="0.1"/>
  </joint>
  <joint name="joint_3" type="revolute">
    <origin rpy="0 0 0" xyz="-0.0226 -0.2769 0.0812"/>
    <parent link="link_2"/>
    <child link="link_3"/>
    <axis xyz="0.9633 0 0.2685"/>
    <limit effort="11" lower="0.1" upper="3.8" velocity="5.0"/>
    <dynamics damping="0.5" friction="0.1"/>
  </joint>
  <joint name="joint_4" type="revolute">
    <origin rpy="-1.6771 0 0" xyz="0.0374 0.1795 0.0779"/>
    <parent link="link_3"/>
    <child link="link_4"/>
    <axis xyz="-0.0296 0 -0.9996"/>
    <limit effort="11" lower="0" upper="6.28" velocity="5.0"/>
    <dynamics damping="0.5" friction="0.1"/>
  </joint>
  <joint name="joint_5" type="revolute">
    <origin rpy="1.5837 0 0" xyz="0.0113 -0.0124 0.1998"/>
    <parent link="link_4"/>
    <child link="link_5"/>
    <axis xyz="-0.4001 0 -0.9165"/>
    <limit effort="11" lower="-0.58" upper="2.9" velocity="5.0"/>
    <dynamics damping="0.5" friction="0.1"/>
  </joint>
  <joint name="end_effector_joint" type="revolute">
    <origin rpy="0.6174 1.0599 -2.5487" xyz="-0.0661 -0.0711 0.0289"/>
    <parent link="link_5"/>
    <child link="end_effector"/>
    <axis xyz="0 0 -1"/>
    <limit effort="11" lower="0.271" upper="6.28" velocity="5.0"/>
    <dynamics damping="0.5" friction="0.1"/>
  </joint>
  <joint name="gripper_base_joint" type="fixed">
    <origin rpy="0 0 0" xyz="-0.0002 0 0.0203"/>
    <parent link="end_effector"/>
    <child link="gripper_base"/>
    <axis xyz="0 0 0"/>
  </joint>
  <joint name="right_gripper_arm_joint" type="prismatic">
    <origin rpy="1.5708 -1.5708 0" xyz="-0.0084 0.0010 0.0320"/>
    <parent link="gripper_base"/>
    <child link="right_gripper_arm"/>
    <axis xyz="0 1 0"/>
    <limit effort="2" lower="0.0010" upper="0.0380" velocity="0.5"/>
    <dynamics damping="0.2" friction="0.05"/>
  </joint>
  <joint name="left_gripper_arm_joint" type="prismatic">
    <origin rpy="-1.5708 -1.5708 0" xyz="0.0087 0.0010 0.0320"/>
    <parent link="gripper_base"/>
    <child link="left_gripper_arm"/>
    <axis xyz="0 1 0"/>
    <limit effort="2" lower="0.0010" upper="0.0380" velocity="0.5"/>
    <mimic joint="right_gripper_arm_joint" multiplier="1" offset="0"/>
    <dynamics damping="0.2" friction="0.05"/>
  </joint>
  <joint name="right_tip_joint" type="fixed">
    <origin rpy="3.1416 0 0" xyz="0.0740 0.0060 -0.0050"/>
    <parent link="right_gripper_arm"/>
    <child link="right_tip"/>
    <axis xyz="0 0 0"/>
  </joint>
  <joint name="left_tip_joint" type="fixed">
    <origin rpy="0 0 0" xyz="0.0740 0.0060 0"/>
    <parent link="left_gripper_arm"/>
    <child link="left_tip"/>
    <axis xyz="0 0 0"/>
  </joint>
  <joint name="gripper_camera_joint" type="fixed">
    <origin rpy="1.5708 -1.5708 0" xyz="0.0002 0.0329 0.0612"/>
    <parent link="gripper_base"/>
    <child link="gripper_camera"/>
    <axis xyz="0 0 0"/>
  </joint>
  <!-- remove comment when you want to use this only for arm / when you want to launch agri_bot then dnt forgrt to comment this -->

  <!-- ___________________________________________________________________________________________________ -->
  <ros2_control name="MecanumSystem" type="system">
    <hardware>
      <plugin>gazebo_ros2_control/GazeboSystem</plugin>
    </hardware>
    <!-- wheel_joints -->
    <joint name="front_left_wheel_joint">
      <command_interface name="velocity"/>
      <state_interface name="position"/>
      <state_interface name="velocity"/>
    </joint>
    <joint name="rear_left_wheel_joint">
      <command_interface name="velocity"/>
      <state_interface name="position"/>
      <state_interface name="velocity"/>
    </joint>
    <joint name="front_right_wheel_joint">
      <command_interface name="velocity"/>
      <state_interface name="position"/>
      <state_interface name="velocity"/>
    </joint>
    <joint name="rear_right_wheel_joint">
      <command_interface name="velocity"/>
      <state_interface name="position"/>
      <state_interface name="velocity"/>
    </joint>
    <!-- arm_joints -->
    <!-- <joint name="joint_1">
      <command_interface name="position"/>
      <state_interface name="position"/>
      <state_interface name="velocity"/>
    </joint>
    <joint name="joint_2">
      <command_interface name="position"/>
      <state_interface name="position"/>
      <state_interface name="velocity"/>
    </joint>
    <joint name="joint_3">
      <command_interface name="position"/>
      <state_interface name="position"/>
      <state_interface name="velocity"/>
    </joint>
    <joint name="joint_4">
      <command_interface name="position"/>
      <state_interface name="position"/>
      <state_interface name="velocity"/>
    </joint>
    <joint name="joint_5">
      <command_interface name="position"/>
      <state_interface name="position"/>
      <state_interface name="velocity"/>
    </joint>
    <joint name="end_effector_joint">
      <command_interface name="position"/>
      <state_interface name="position"/>
      <state_interface name="velocity"/>
    </joint>
    <joint name="right_gripper_arm_joint">
      <command_interface name="position"/>
      <state_interface name="position"/>
      <state_interface name="velocity"/>
    </joint>
    <joint name="left_gripper_arm_joint">
      <param name="mimic">right_gripper_arm_joint</param>
      <param name="multiplier">1</param>
      <command_interface name="position"/>
      <state_interface name="position"/>
      <state_interface name="velocity"/>
    </joint> -->
  </ros2_control>
  <gazebo>
    <plugin filename="libgazebo_ros2_control.so" name="gazebo_ros2_control">
      <parameters>/home/imbatman/smdw_ws/src/agri_bot/config/agri_bot_controller.yaml</parameters>
    </plugin>
  </gazebo>
  <!-- wheels_gazebo_tags -->
  <gazebo reference="front_left_base_link">
    <mu1>1.0</mu1>
    <mu2>1.0</mu2>
  </gazebo>
  <gazebo reference="front_right_base_link">
    <mu1>1.0</mu1>
    <mu2>1.0</mu2>
  </gazebo>
  <gazebo reference="rear_left_base_link">
    <mu1>1.0</mu1>
    <mu2>1.0</mu2>
  </gazebo>
  <gazebo reference="rear_right_base_link">
    <mu1>1.0</mu1>
    <mu2>1.0</mu2>
  </gazebo>
  <gazebo reference="front_left_wheel_joint">
    <kp>50.0</kp>
    <ki>0.0</ki>
    <kd>20.0</kd>
  </gazebo>
  <gazebo reference="front_right_wheel_joint">
    <kp>50.0</kp>
    <ki>0.0</ki>
    <kd>20.0</kd>
  </gazebo>
  <gazebo reference="rear_left_wheel_joint">
    <kp>50.0</kp>
    <ki>0.0</ki>
    <kd>20.0</kd>
  </gazebo>
  <gazebo reference="rear_right_wheel_joint">
    <kp>50.0</kp>
    <ki>0.0</ki>
    <kd>20.0</kd>
  </gazebo>
  <!-- arm gazebo tags -->
  <gazebo>
    <plugin filename="libgazebo_mimic_joint_plugin.so" name="mimic_joint_plugin">
      <joint>left_gripper_arm_joint</joint>
      <mimicJoint>right_gripper_arm_joint</mimicJoint>
      <multiplier>1.0</multiplier>
      <offset>0.0</offset>
      <sensitiveness>0.0</sensitiveness>
      <maxEffort>2.0</maxEffort>
      <hasPID/>
    </plugin>
  </gazebo>
  <gazebo reference="xaarm_base_link">
    <material>Gazebo/Grey</material>
  </gazebo>
  <gazebo reference="link_1">
    <material>Gazebo/Blue</material>
  </gazebo>
  <gazebo reference="link_2">
    <material>Gazebo/Blue</material>
  </gazebo>
  <gazebo reference="link_3">
    <material>Gazebo/Blue</material>
  </gazebo>
  <gazebo reference="link_4">
    <material>Gazebo/Blue</material>
  </gazebo>
  <gazebo reference="link_5">
    <material>Gazebo/White</material>
  </gazebo>
  <gazebo reference="end_effector">
    <material>Gazebo/Blue</material>
  </gazebo>
  <gazebo reference="gripper_base">
    <material>Gazebo/Grey</material>
  </gazebo>
  <gazebo reference="left_gripper_arm">
    <material>Gazebo/White</material>
  </gazebo>
  <gazebo reference="left_tip">
    <material>Gazebo/Black</material>
  </gazebo>
  <gazebo reference="right_gripper_arm">
    <material>Gazebo/White</material>
  </gazebo>
  <gazebo reference="right_tip">
    <material>Gazebo/Black</material>
  </gazebo>
  <joint name="smdw_base_to_arm" type="fixed">
    <parent link="base_link"/>
    <child link="xaarm_base_link"/>
    <origin rpy="0 0 0" xyz="0 0 0.1016"/>
  </joint>
</robot>
