<?xml version="1.0" ?>
<!-- =================================================================================== -->
<!-- |    This document was autogenerated by xacro from /home/imbatman/smdw_ws/src/smdw_robot_base/urdf/smdw_robot_base.urdf.xacro | -->
<!-- |    EDITING THIS FILE BY HAND IS NOT RECOMMENDED                                 | -->
<!-- =================================================================================== -->
<robot name="smdw_robot_base">
  <!-- <xacro:include filename="$(find smdw_robot_base)/urdf/camera.xacro"/>
  <xacro:include filename="$(find smdw_robot_base)/urdf/lidar.xacro"/> -->
  <!-- if you wannt to launch the robot then uncomment this following lines/ but if you launch agri_bot then dnt forget to comment this  -->
  <!-- <xacro:include filename="$(find smdw_robot_base)/urdf/ros2_control.xacro"/>
  <xacro:include filename="$(find smdw_robot_base)/urdf/gazebo.xacro"/> -->
  <!-- _______________________________________________________________________________________ -->
  <link name="odom">
  </link>
  <joint name="odom_to_base_footprint" type="fixed">
    <origin rpy="0 0 0" xyz="0 0 0"/>
    <parent link="odom"/>
    <child link="base_footprint"/>
  </joint>
  <!-- Fixed joint between base_footprint and base_link -->
  <joint name="base_fixed_joint" type="fixed">
    <origin rpy="0 0 0" xyz="0 0 0.0508"/>
    <parent link="base_footprint"/>
    <child link="base_link"/>
  </joint>
  <!-- Base footprint -->
  <link name="base_footprint"/>
  <!-- Base link -->
  <link name="base_link">
    <inertial>
      <origin rpy="0 0 0" xyz="5.48421351341662E-17 -4.87352495342906E-17 0.0508"/>
      <mass value="32.9182761436536"/>
      <inertia ixx="0.745163960934943" ixy="3.59989002583078E-17" ixz="-2.00803277362423E-19" iyy="1.13620249698633" iyz="1.90637586064413E-17" izz="1.82496934930628"/>
    </inertial>
    <visual>
      <origin rpy="0 0 0" xyz="0 0 0"/>
      <geometry>
        <mesh filename="file:///home/imbatman/smdw_ws/src/smdw_robot_base/meshes/robot_base_link.STL"/>
      </geometry>
      <material name="">
        <color rgba="0.792156862745098 0.819607843137255 0.933333333333333 1"/>
      </material>
    </visual>
    <collision>
      <origin rpy="0 0 0" xyz="0 0 0"/>
      <geometry>
        <mesh filename="file:///home/imbatman/smdw_ws/src/smdw_robot_base/meshes/robot_base_link.STL"/>
      </geometry>
    </collision>
  </link>
  <!-- Define materials -->
  <material name="front_left_base_color">
    <color rgba="0.79216 0.81961 0.93333 1"/>
  </material>
  <material name="front_left_wheel_color">
    <color rgba="0.25098 0.25098 0.25098 1"/>
  </material>
  <!-- Base link -->
  <link name="front_left_base_link">
    <inertial>
      <origin rpy="0 0 0" xyz="-4.3311E-18 1.504E-12 1.7857E-18"/>
      <mass value="1.9429"/>
      <inertia ixx="0.0019245" ixy="8.1609E-21" ixz="-8.1689E-08" iyy="0.0049239" iyz="-7.5092E-20" izz="0.0032216"/>
    </inertial>
    <visual>
      <origin rpy="0 0 0" xyz="0 0 0"/>
      <geometry>
        <mesh filename="file:///home/imbatman/smdw_ws/src/left_smdw/meshes/front_left_wheel_base_link.STL"/>
      </geometry>
      <material name="front_left_wheel_color"/>
    </visual>
    <collision>
      <origin rpy="0 0 0" xyz="0 0 0"/>
      <geometry>
        <mesh filename="file:///home/imbatman/smdw_ws/src/left_smdw/meshes/front_left_wheel_base_link.STL"/>
      </geometry>
    </collision>
  </link>

  <joint name="front_left_wheel_joint" type="continuous">
    <parent link="base_link"/>
    <child link="front_left_base_link"/>
    <origin rpy="0 0 0" xyz="0.2159 0.3175 0.0508"/>
    <axis xyz="0 1 0"/>
    <limit effort="100.0" velocity="10.0"/>
    <dynamics friction="0.001"/>
  </joint>





  <!-- Define materials -->
  <material name="rear_right_base_color">
    <color rgba="0.79216 0.81961 0.93333 1"/>
  </material>
  <material name="rear_right_wheel_color">
    <color rgba="0.25098 0.25098 0.25098 1"/>
  </material>
  <!-- Base link -->
  <link name="rear_right_base_link">
    <inertial>
      <origin rpy="0 0 0" xyz="-4.3311E-18 1.504E-12 1.7857E-18"/>
      <mass value="1.9429"/>
      <inertia ixx="0.0019245" ixy="8.1609E-21" ixz="-8.1689E-08" iyy="0.0049239" iyz="-7.5092E-20" izz="0.0032216"/>
    </inertial>
    <visual>
      <origin rpy="0 0 0" xyz="0 0 0"/>
      <geometry>
        <mesh filename="file:///home/imbatman/smdw_ws/src/left_smdw/meshes/front_left_wheel_base_link.STL"/>
      </geometry>
      <material name="rear_right_wheel_color"/>
    </visual>
    <collision>
      <origin rpy="0 0 0" xyz="0 0 0"/>
      <geometry>
        <mesh filename="file:///home/imbatman/smdw_ws/src/left_smdw/meshes/front_left_wheel_base_link.STL"/>
      </geometry>
    </collision>
  </link>
  <joint name="rear_right_wheel_joint" type="continuous">
    <parent link="base_link"/>
    <child link="rear_right_base_link"/>
    <origin rpy="0 0 0" xyz="-0.2159 -0.3175 0.0508"/>
    <axis xyz="0 1 0"/>
    <limit effort="100.0" velocity="10.0"/>
    <dynamics friction="0.001"/>
  </joint>





  <!-- Define materials -->
  <material name="front_right_base_color">
    <color rgba="0.79216 0.81961 0.93333 1"/>
  </material>
  <material name="front_right_wheel_color">
    <color rgba="0.25098 0.25098 0.25098 1"/>
  </material>
  <!-- Base link -->
  <link name="front_right_base_link">
    <inertial>
      <origin rpy="0 0 0" xyz="-4.3311E-18 1.504E-12 1.7857E-18"/>
      <mass value="1.9429"/>
      <inertia ixx="0.0019245" ixy="8.1609E-21" ixz="-8.1689E-08" iyy="0.0049239" iyz="-7.5092E-20" izz="0.0032216"/>
    </inertial>
    <visual>
      <origin rpy="0 0 0" xyz="0 0 0"/>
      <geometry>
        <mesh filename="file:///home/imbatman/smdw_ws/src/right_smdw/meshes/front_right_wheel_base_link.STL"/>
      </geometry>
      <material name="front_right_wheel_color"/>
    </visual>
    <collision>
      <origin rpy="0 0 0" xyz="0 0 0"/>
      <geometry>
        <mesh filename="file:///home/imbatman/smdw_ws/src/right_smdw/meshes/front_right_wheel_base_link.STL"/>
      </geometry>
    </collision>
  </link>
  <joint name="front_right_wheel_joint" type="continuous">
    <parent link="base_link"/>
    <child link="front_right_base_link"/>
    <origin rpy="0 0 0" xyz="0.2159 -0.3175 0.0508"/>
    <axis xyz="0 1 0"/>
    <limit effort="100.0" velocity="10.0"/>
    <dynamics friction="0.001"/>
  </joint>





  
  <!-- Define materials -->
  <material name="rear_left_base_color">
    <color rgba="0.79216 0.81961 0.93333 1"/>
  </material>
  <material name="rear_left_wheel_color">
    <color rgba="0.25098 0.25098 0.25098 1"/>
  </material>
  <!-- Base link -->
  <link name="rear_left_base_link">
    <inertial>
      <origin rpy="0 0 0" xyz="-4.3311E-18 1.504E-12 1.7857E-18"/>
      <mass value="1.9429"/>
      <inertia ixx="0.0019245" ixy="8.1609E-21" ixz="-8.1689E-08" iyy="0.0049239" iyz="-7.5092E-20" izz="0.0032216"/>
    </inertial>
    <visual>
      <origin rpy="0 0 0" xyz="0 0 0"/>
      <geometry>
        <mesh filename="file:///home/imbatman/smdw_ws/src/right_smdw/meshes/front_right_wheel_base_link.STL"/>
      </geometry>
      <material name="rear_left_wheel_color"/>
    </visual>
    <collision>
      <origin rpy="0 0 0" xyz="0 0 0"/>
      <geometry>
        <mesh filename="file:///home/imbatman/smdw_ws/src/right_smdw/meshes/front_right_wheel_base_link.STL"/>
      </geometry>
    </collision>
  </link>
  <!-- Attach wheels to base_link -->

  <joint name="rear_left_wheel_joint" type="continuous">
    <parent link="base_link"/>
    <child link="rear_left_base_link"/>
    <origin rpy="0 0 0" xyz="-0.2159 0.3175 0.0508"/>
    <axis xyz="0 1 0"/>
    <limit effort="100.0" velocity="10.0"/>
    <dynamics friction="0.001"/>
  </joint>


</robot>
