<?xml version="1.0" ?>
<!-- =================================================================================== -->
<!-- |    This document was autogenerated by xacro from /home/imbatman/smdw_ws/src/smdw_robot_base/urdf/smdw_robot_base.urdf.xacro | -->
<!-- |    EDITING THIS FILE BY HAND IS NOT RECOMMENDED                                 | -->
<!-- =================================================================================== -->
<robot name="smdw_robot_base">
  <ros2_control name="MecanumSystem" type="system">
    <hardware>
      <plugin>gazebo_ros2_control/GazeboSystem</plugin>
    </hardware>
    <joint name="front_left_wheel_joint">
      <command_interface name="velocity"/>
      <state_interface name="position"/>
      <state_interface name="velocity"/>
    </joint>
    <joint name="rear_left_wheel_joint">
      <command_interface name="velocity"/>
      <state_interface name="position"/>
      <state_interface name="velocity"/>
    </joint>
    <joint name="front_right_wheel_joint">
      <command_interface name="velocity"/>
      <state_interface name="position"/>
      <state_interface name="velocity"/>
    </joint>
    <joint name="rear_right_wheel_joint">
      <command_interface name="velocity"/>
      <state_interface name="position"/>
      <state_interface name="velocity"/>
    </joint>
  </ros2_control>
  <gazebo>
    <plugin filename="libgazebo_ros2_control.so" name="gazebo_ros2_control">
      <parameters>/home/imbatman/smdw_ws/src/robot_base/config/controller.yaml</parameters>
    </plugin>
  </gazebo>
  <gazebo reference="front_left_wheel">
    <mu1>1.2</mu1>
    <mu2>0.2</mu2>
  </gazebo>
  <gazebo reference="front_right_wheel">
    <mu1>1.2</mu1>
    <mu2>0.2</mu2>
  </gazebo>
  <gazebo reference="rear_left_wheel">
    <mu1>1.2</mu1>
    <mu2>0.2</mu2>
  </gazebo>
  <gazebo reference="rear_right_wheel">
    <mu1>1.2</mu1>
    <mu2>0.2</mu2>
  </gazebo>
  <!-- Joint PID gains for velocity control -->
  <gazebo reference="front_left_wheel_joint">
    <kp>10000.0</kp>
    <ki>0.0</ki>
    <kd>10.0</kd>
  </gazebo>
  <gazebo reference="front_right_wheel_joint">
    <kp>10000.0</kp>
    <ki>0.0</ki>
    <kd>10.0</kd>
  </gazebo>
  <gazebo reference="rear_left_wheel_joint">
    <kp>10000.0</kp>
    <ki>0.0</ki>
    <kd>10.0</kd>
  </gazebo>
  <gazebo reference="rear_right_wheel_joint">
    <kp>10000.0</kp>
    <ki>0.0</ki>
    <kd>10.0</kd>
  </gazebo>
  <!-- <xacro:arg name="use_ros2_control" default="true"/>
  <xacro:if value="$(arg use_ros2_control)">
    <xacro:include filename="$(find smdw_robot_base)/urdf/ros2_control.xacro"/>
  </xacro:if>

  <xacro:arg name="use_gazebo" default="true"/>
  <xacro:if value="$(arg use_gazebo)">
    <xacro:include filename="$(find smdw_robot_base)/urdf/gazebo.xacro"/>
  </xacro:if> -->
  <!-- Base footprint -->
  <link name="base_footprint"/>
  <!-- Base link -->
  <link name="base_link">
    <inertial>
      <origin rpy="0 0 0" xyz="5.48421351341662E-17 -4.87352495342906E-17 0.0508"/>
      <mass value="32.9182761436536"/>
      <inertia ixx="0.745163960934943" ixy="3.59989002583078E-17" ixz="-2.00803277362423E-19" iyy="1.13620249698633" iyz="1.90637586064413E-17" izz="1.82496934930628"/>
    </inertial>
    <visual>
      <origin rpy="0 0 0" xyz="0 0 0"/>
      <geometry>
        <mesh filename="file:///home/imbatman/smdw_ws/src/smdw_robot_base/meshes/robot_base_link.STL"/>
      </geometry>
      <material name="">
        <color rgba="0.792156862745098 0.819607843137255 0.933333333333333 1"/>
      </material>
    </visual>
    <collision>
      <origin rpy="0 0 0" xyz="0 0 0"/>
      <geometry>
        <mesh filename="file:///home/imbatman/smdw_ws/src/smdw_robot_base/meshes/robot_base_link.STL"/>
      </geometry>
    </collision>
  </link>
  <!-- Fixed joint between base_footprint and base_link -->
  <joint name="base_fixed_joint" type="fixed">
    <origin rpy="0 0 0" xyz="0 0 0.0508"/>
    <parent link="base_footprint"/>
    <child link="base_link"/>
  </joint>
  <!-- Define materials -->
  <material name="front_left_base_color">
    <color rgba="0.79216 0.81961 0.93333 1"/>
  </material>
  <material name="front_left_wheel_color">
    <color rgba="0.25098 0.25098 0.25098 1"/>
  </material>
  <!-- Base link -->
  <link name="front_left_base_link">
    <inertial>
      <origin rpy="0 0 0" xyz="-4.3311E-18 1.504E-12 1.7857E-18"/>
      <mass value="1.9429"/>
      <inertia ixx="0.0019245" ixy="8.1609E-21" ixz="-8.1689E-08" iyy="0.0049239" iyz="-7.5092E-20" izz="0.0032216"/>
    </inertial>
    <visual>
      <origin rpy="0 0 0" xyz="0 0 0"/>
      <geometry>
        <mesh filename="file:///home/imbatman/smdw_ws/src/left_smdw/meshes/front_left_wheel_base_link.STL"/>
      </geometry>
      <material name="front_left_wheel_color"/>
    </visual>
    <collision>
      <origin rpy="0 0 0" xyz="0 0 0"/>
      <geometry>
        <mesh filename="file:///home/imbatman/smdw_ws/src/left_smdw/meshes/front_left_wheel_base_link.STL"/>
      </geometry>
    </collision>
  </link>
  <link name="front_left_RR_link_1">
    <inertial>
      <origin rpy="0 0 0" xyz="0 0 0"/>
      <mass value="0.0343"/>
      <inertia ixx="0.00001147" ixy="0" ixz="0" iyy="0.000001312" iyz="0" izz="0.00001147"/>
    </inertial>
    <visual>
      <origin rpy="0 0 0" xyz="0 0 0"/>
      <geometry>
        <mesh filename="file:///home/imbatman/smdw_ws/src/left_smdw/meshes/FL_RR_link_1.STL"/>
      </geometry>
      <material name="front_left_base_color"/>
    </visual>
    <collision>
      <origin rpy="0 0 0" xyz="0 0 0"/>
      <geometry>
        <mesh filename="file:///home/imbatman/smdw_ws/src/left_smdw/meshes/FL_RR_link_1.STL"/>
      </geometry>
    </collision>
  </link>
  <joint name="front_left_RR_joint_1" type="continuous">
    <origin rpy="0.0000 0.0000 -0.7854" xyz="0.0000 -0.0279 0.0914"/>
    <parent link="front_left_base_link"/>
    <child link="front_left_RR_link_1"/>
    <axis xyz="0 -1 0"/>
  </joint>
  <gazebo reference="front_left_RR_link_1">
    <material>Gazebo/DarkGrey</material>
    <surface>
      <friction>
        <ode>
          <mu>1.0</mu>
          <mu2>0.1</mu2>
        </ode>
      </friction>
    </surface>
  </gazebo>
  <link name="front_left_RR_link_2">
    <inertial>
      <origin rpy="0 0 0" xyz="0 0 0"/>
      <mass value="0.0343"/>
      <inertia ixx="0.00001147" ixy="0" ixz="0" iyy="0.000001312" iyz="0" izz="0.00001147"/>
    </inertial>
    <visual>
      <origin rpy="0 0 0" xyz="0 0 0"/>
      <geometry>
        <mesh filename="file:///home/imbatman/smdw_ws/src/left_smdw/meshes/FL_RR_link_2.STL"/>
      </geometry>
      <material name="front_left_base_color"/>
    </visual>
    <collision>
      <origin rpy="0 0 0" xyz="0 0 0"/>
      <geometry>
        <mesh filename="file:///home/imbatman/smdw_ws/src/left_smdw/meshes/FL_RR_link_2.STL"/>
      </geometry>
    </collision>
  </link>
  <joint name="front_left_RR_joint_2" type="continuous">
    <origin rpy="-0.2849 0.2740 -0.8249" xyz="0.0350 -0.0279 0.0845"/>
    <parent link="front_left_base_link"/>
    <child link="front_left_RR_link_2"/>
    <axis xyz="0 -1 0"/>
  </joint>
  <gazebo reference="front_left_RR_link_2">
    <material>Gazebo/DarkGrey</material>
    <surface>
      <friction>
        <ode>
          <mu>1.0</mu>
          <mu2>0.1</mu2>
        </ode>
      </friction>
    </surface>
  </gazebo>
  <link name="front_left_RR_link_3">
    <inertial>
      <origin rpy="0 0 0" xyz="0 0 0"/>
      <mass value="0.0343"/>
      <inertia ixx="0.00001147" ixy="0" ixz="0" iyy="0.000001312" iyz="0" izz="0.00001147"/>
    </inertial>
    <visual>
      <origin rpy="0 0 0" xyz="0 0 0"/>
      <geometry>
        <mesh filename="file:///home/imbatman/smdw_ws/src/left_smdw/meshes/FL_RR_link_3.STL"/>
      </geometry>
      <material name="front_left_base_color"/>
    </visual>
    <collision>
      <origin rpy="0 0 0" xyz="0 0 0"/>
      <geometry>
        <mesh filename="file:///home/imbatman/smdw_ws/src/left_smdw/meshes/FL_RR_link_3.STL"/>
      </geometry>
    </collision>
  </link>
  <joint name="front_left_RR_joint_3" type="continuous">
    <origin rpy="-0.6155 0.5236 -0.9553" xyz="0.0647 -0.0279 0.0647"/>
    <parent link="front_left_base_link"/>
    <child link="front_left_RR_link_3"/>
    <axis xyz="0 -1 0"/>
  </joint>
  <gazebo reference="front_left_RR_link_3">
    <material>Gazebo/DarkGrey</material>
    <surface>
      <friction>
        <ode>
          <mu>1.0</mu>
          <mu2>0.1</mu2>
        </ode>
      </friction>
    </surface>
  </gazebo>
  <link name="front_left_RR_link_4">
    <inertial>
      <origin rpy="0 0 0" xyz="0 0 0"/>
      <mass value="0.0343"/>
      <inertia ixx="0.00001147" ixy="0" ixz="0" iyy="0.000001312" iyz="0" izz="0.00001147"/>
    </inertial>
    <visual>
      <origin rpy="0 0 0" xyz="0 0 0"/>
      <geometry>
        <mesh filename="file:///home/imbatman/smdw_ws/src/left_smdw/meshes/FL_RR_link_4.STL"/>
      </geometry>
      <material name="front_left_base_color"/>
    </visual>
    <collision>
      <origin rpy="0 0 0" xyz="0 0 0"/>
      <geometry>
        <mesh filename="file:///home/imbatman/smdw_ws/src/left_smdw/meshes/FL_RR_link_4.STL"/>
      </geometry>
    </collision>
  </link>
  <joint name="front_left_RR_joint_4" type="continuous">
    <origin rpy="-1.0409 0.7119 -1.2053" xyz="0.0845 -0.0279 0.0350"/>
    <parent link="front_left_base_link"/>
    <child link="front_left_RR_link_4"/>
    <axis xyz="0 -1 0"/>
  </joint>
  <gazebo reference="front_left_RR_link_4">
    <material>Gazebo/DarkGrey</material>
    <surface>
      <friction>
        <ode>
          <mu>1.0</mu>
          <mu2>0.1</mu2>
        </ode>
      </friction>
    </surface>
  </gazebo>
  <link name="front_left_RR_link_5">
    <inertial>
      <origin rpy="0 0 0" xyz="0 0 0"/>
      <mass value="0.0343"/>
      <inertia ixx="0.00001147" ixy="0" ixz="0" iyy="0.000001312" iyz="0" izz="0.00001147"/>
    </inertial>
    <visual>
      <origin rpy="0 0 0" xyz="0 0 0"/>
      <geometry>
        <mesh filename="file:///home/imbatman/smdw_ws/src/left_smdw/meshes/FL_RR_link_5.STL"/>
      </geometry>
      <material name="front_left_base_color"/>
    </visual>
    <collision>
      <origin rpy="0 0 0" xyz="0 0 0"/>
      <geometry>
        <mesh filename="file:///home/imbatman/smdw_ws/src/left_smdw/meshes/FL_RR_link_5.STL"/>
      </geometry>
    </collision>
  </link>
  <joint name="front_left_RR_joint_5" type="continuous">
    <origin rpy="-1.5708 0.7854 -1.5708" xyz="0.0914 -0.0279 0.0000"/>
    <parent link="front_left_base_link"/>
    <child link="front_left_RR_link_5"/>
    <axis xyz="0 -1 0"/>
  </joint>
  <gazebo reference="front_left_RR_link_5">
    <material>Gazebo/DarkGrey</material>
    <surface>
      <friction>
        <ode>
          <mu>1.0</mu>
          <mu2>0.1</mu2>
        </ode>
      </friction>
    </surface>
  </gazebo>
  <link name="front_left_RR_link_6">
    <inertial>
      <origin rpy="0 0 0" xyz="0 0 0"/>
      <mass value="0.0343"/>
      <inertia ixx="0.00001147" ixy="0" ixz="0" iyy="0.000001312" iyz="0" izz="0.00001147"/>
    </inertial>
    <visual>
      <origin rpy="0 0 0" xyz="0 0 0"/>
      <geometry>
        <mesh filename="file:///home/imbatman/smdw_ws/src/left_smdw/meshes/FL_RR_link_6.STL"/>
      </geometry>
      <material name="front_left_base_color"/>
    </visual>
    <collision>
      <origin rpy="0 0 0" xyz="0 0 0"/>
      <geometry>
        <mesh filename="file:///home/imbatman/smdw_ws/src/left_smdw/meshes/FL_RR_link_6.STL"/>
      </geometry>
    </collision>
  </link>
  <joint name="front_left_RR_joint_6" type="continuous">
    <origin rpy="-2.7309 0.3798 -2.2762" xyz="0.0671 -0.0279 -0.0370"/>
    <parent link="front_left_base_link"/>
    <child link="front_left_RR_link_6"/>
    <axis xyz="0 -1 0"/>
  </joint>
  <gazebo reference="front_left_RR_link_6">
    <material>Gazebo/DarkGrey</material>
    <surface>
      <friction>
        <ode>
          <mu>1.0</mu>
          <mu2>0.1</mu2>
        </ode>
      </friction>
    </surface>
  </gazebo>
  <link name="front_left_RR_link_7">
    <inertial>
      <origin rpy="0 0 0" xyz="0 0 0"/>
      <mass value="0.0343"/>
      <inertia ixx="0.00001147" ixy="0" ixz="0" iyy="0.000001312" iyz="0" izz="0.00001147"/>
    </inertial>
    <visual>
      <origin rpy="0 0 0" xyz="0 0 0"/>
      <geometry>
        <mesh filename="file:///home/imbatman/smdw_ws/src/left_smdw/meshes/FL_RR_link_7.STL"/>
      </geometry>
      <material name="front_left_base_color"/>
    </visual>
    <collision>
      <origin rpy="0 0 0" xyz="0 0 0"/>
      <geometry>
        <mesh filename="file:///home/imbatman/smdw_ws/src/left_smdw/meshes/FL_RR_link_7.STL"/>
      </geometry>
    </collision>
  </link>
  <joint name="front_left_RR_joint_7" type="continuous">
    <origin rpy="-2.9882 0.1516 -2.3445" xyz="0.0320 -0.0261 -0.0502"/>
    <parent link="front_left_base_link"/>
    <child link="front_left_RR_link_7"/>
    <axis xyz="0 -1 0"/>
  </joint>
  <gazebo reference="front_left_RR_link_7">
    <material>Gazebo/DarkGrey</material>
    <surface>
      <friction>
        <ode>
          <mu>1.0</mu>
          <mu2>0.1</mu2>
        </ode>
      </friction>
    </surface>
  </gazebo>
  <link name="front_left_RR_link_8">
    <inertial>
      <origin rpy="0 0 0" xyz="0 0 0"/>
      <mass value="0.0343"/>
      <inertia ixx="0.00001147" ixy="0" ixz="0" iyy="0.000001312" iyz="0" izz="0.00001147"/>
    </inertial>
    <visual>
      <origin rpy="0 0 0" xyz="0 0 0"/>
      <geometry>
        <mesh filename="file:///home/imbatman/smdw_ws/src/left_smdw/meshes/FL_RR_link_8.STL"/>
      </geometry>
      <material name="front_left_base_color"/>
    </visual>
    <collision>
      <origin rpy="0 0 0" xyz="0 0 0"/>
      <geometry>
        <mesh filename="file:///home/imbatman/smdw_ws/src/left_smdw/meshes/FL_RR_link_8.STL"/>
      </geometry>
    </collision>
  </link>
  <joint name="front_left_RR_joint_8" type="continuous">
    <origin rpy="-3.1416 0.0000 -2.3562" xyz="0.0000 -0.0279 -0.0533"/>
    <parent link="front_left_base_link"/>
    <child link="front_left_RR_link_8"/>
    <axis xyz="0 -1 0"/>
  </joint>
  <gazebo reference="front_left_RR_link_8">
    <material>Gazebo/DarkGrey</material>
    <surface>
      <friction>
        <ode>
          <mu>1.0</mu>
          <mu2>0.1</mu2>
        </ode>
      </friction>
    </surface>
  </gazebo>
  <link name="front_left_RR_link_9">
    <inertial>
      <origin rpy="0 0 0" xyz="0 0 0"/>
      <mass value="0.0343"/>
      <inertia ixx="0.00001147" ixy="0" ixz="0" iyy="0.000001312" iyz="0" izz="0.00001147"/>
    </inertial>
    <visual>
      <origin rpy="0 0 0" xyz="0 0 0"/>
      <geometry>
        <mesh filename="file:///home/imbatman/smdw_ws/src/left_smdw/meshes/FL_RR_link_9.STL"/>
      </geometry>
      <material name="front_left_base_color"/>
    </visual>
    <collision>
      <origin rpy="0 0 0" xyz="0 0 0"/>
      <geometry>
        <mesh filename="file:///home/imbatman/smdw_ws/src/left_smdw/meshes/FL_RR_link_9.STL"/>
      </geometry>
    </collision>
  </link>
  <joint name="front_left_RR_joint_9" type="continuous">
    <origin rpy="2.9882 -0.1517 -2.3445" xyz="-0.0338 -0.0279 -0.0498"/>
    <parent link="front_left_base_link"/>
    <child link="front_left_RR_link_9"/>
    <axis xyz="0 -1 0"/>
  </joint>
  <gazebo reference="front_left_RR_link_9">
    <material>Gazebo/DarkGrey</material>
    <surface>
      <friction>
        <ode>
          <mu>1.0</mu>
          <mu2>0.1</mu2>
        </ode>
      </friction>
    </surface>
  </gazebo>
  <link name="front_left_RR_link_10">
    <inertial>
      <origin rpy="0 0 0" xyz="0 0 0"/>
      <mass value="0.0343"/>
      <inertia ixx="0.00001147" ixy="0" ixz="0" iyy="0.000001312" iyz="0" izz="0.00001147"/>
    </inertial>
    <visual>
      <origin rpy="0 0 0" xyz="0 0 0"/>
      <geometry>
        <mesh filename="file:///home/imbatman/smdw_ws/src/left_smdw/meshes/FL_RR_link_10.STL"/>
      </geometry>
      <material name="front_left_base_color"/>
    </visual>
    <collision>
      <origin rpy="0 0 0" xyz="0 0 0"/>
      <geometry>
        <mesh filename="file:///home/imbatman/smdw_ws/src/left_smdw/meshes/FL_RR_link_10.STL"/>
      </geometry>
    </collision>
  </link>
  <joint name="front_left_RR_joint_10" type="continuous">
    <origin rpy="2.7309 -0.3798 -2.2762" xyz="-0.0671 -0.0279 -0.0370"/>
    <parent link="front_left_base_link"/>
    <child link="front_left_RR_link_10"/>
    <axis xyz="0 -1 0"/>
  </joint>
  <gazebo reference="front_left_RR_link_10">
    <material>Gazebo/DarkGrey</material>
    <surface>
      <friction>
        <ode>
          <mu>1.0</mu>
          <mu2>0.1</mu2>
        </ode>
      </friction>
    </surface>
  </gazebo>
  <link name="front_left_RR_link_11">
    <inertial>
      <origin rpy="0 0 0" xyz="0 0 0"/>
      <mass value="0.0343"/>
      <inertia ixx="0.00001147" ixy="0" ixz="0" iyy="0.000001312" iyz="0" izz="0.00001147"/>
    </inertial>
    <visual>
      <origin rpy="0 0 0" xyz="0 0 0"/>
      <geometry>
        <mesh filename="file:///home/imbatman/smdw_ws/src/left_smdw/meshes/FL_RR_link_11.STL"/>
      </geometry>
      <material name="front_left_base_color"/>
    </visual>
    <collision>
      <origin rpy="0 0 0" xyz="0 0 0"/>
      <geometry>
        <mesh filename="file:///home/imbatman/smdw_ws/src/left_smdw/meshes/FL_RR_link_11.STL"/>
      </geometry>
    </collision>
  </link>
  <joint name="front_left_RR_joint_11" type="continuous">
    <origin rpy="1.5708 -0.7854 -1.5708" xyz="-0.0914 -0.0279 0.0000"/>
    <parent link="front_left_base_link"/>
    <child link="front_left_RR_link_11"/>
    <axis xyz="0 -1 0"/>
  </joint>
  <gazebo reference="front_left_RR_link_11">
    <material>Gazebo/DarkGrey</material>
    <surface>
      <friction>
        <ode>
          <mu>1.0</mu>
          <mu2>0.1</mu2>
        </ode>
      </friction>
    </surface>
  </gazebo>
  <link name="front_left_RR_link_12">
    <inertial>
      <origin rpy="0 0 0" xyz="0 0 0"/>
      <mass value="0.0343"/>
      <inertia ixx="0.00001147" ixy="0" ixz="0" iyy="0.000001312" iyz="0" izz="0.00001147"/>
    </inertial>
    <visual>
      <origin rpy="0 0 0" xyz="0 0 0"/>
      <geometry>
        <mesh filename="file:///home/imbatman/smdw_ws/src/left_smdw/meshes/FL_RR_link_12.STL"/>
      </geometry>
      <material name="front_left_base_color"/>
    </visual>
    <collision>
      <origin rpy="0 0 0" xyz="0 0 0"/>
      <geometry>
        <mesh filename="file:///home/imbatman/smdw_ws/src/left_smdw/meshes/FL_RR_link_12.STL"/>
      </geometry>
    </collision>
  </link>
  <joint name="front_left_RR_joint_12" type="continuous">
    <origin rpy="1.0409 -0.7119 -1.2053" xyz="-0.0845 -0.0279 0.0350"/>
    <parent link="front_left_base_link"/>
    <child link="front_left_RR_link_12"/>
    <axis xyz="0 -1 0"/>
  </joint>
  <gazebo reference="front_left_RR_link_12">
    <material>Gazebo/DarkGrey</material>
    <surface>
      <friction>
        <ode>
          <mu>1.0</mu>
          <mu2>0.1</mu2>
        </ode>
      </friction>
    </surface>
  </gazebo>
  <link name="front_left_RR_link_13">
    <inertial>
      <origin rpy="0 0 0" xyz="0 0 0"/>
      <mass value="0.0343"/>
      <inertia ixx="0.00001147" ixy="0" ixz="0" iyy="0.000001312" iyz="0" izz="0.00001147"/>
    </inertial>
    <visual>
      <origin rpy="0 0 0" xyz="0 0 0"/>
      <geometry>
        <mesh filename="file:///home/imbatman/smdw_ws/src/left_smdw/meshes/FL_RR_link_13.STL"/>
      </geometry>
      <material name="front_left_base_color"/>
    </visual>
    <collision>
      <origin rpy="0 0 0" xyz="0 0 0"/>
      <geometry>
        <mesh filename="file:///home/imbatman/smdw_ws/src/left_smdw/meshes/FL_RR_link_13.STL"/>
      </geometry>
    </collision>
  </link>
  <joint name="front_left_RR_joint_13" type="continuous">
    <origin rpy="0.6155 -0.5236 -0.9553" xyz="-0.0647 -0.0279 0.0647"/>
    <parent link="front_left_base_link"/>
    <child link="front_left_RR_link_13"/>
    <axis xyz="0 -1 0"/>
  </joint>
  <gazebo reference="front_left_RR_link_13">
    <material>Gazebo/DarkGrey</material>
    <surface>
      <friction>
        <ode>
          <mu>1.0</mu>
          <mu2>0.1</mu2>
        </ode>
      </friction>
    </surface>
  </gazebo>
  <link name="front_left_RR_link_14">
    <inertial>
      <origin rpy="0 0 0" xyz="0 0 0"/>
      <mass value="0.0343"/>
      <inertia ixx="0.00001147" ixy="0" ixz="0" iyy="0.000001312" iyz="0" izz="0.00001147"/>
    </inertial>
    <visual>
      <origin rpy="0 0 0" xyz="0 0 0"/>
      <geometry>
        <mesh filename="file:///home/imbatman/smdw_ws/src/left_smdw/meshes/FL_RR_link_14.STL"/>
      </geometry>
      <material name="front_left_base_color"/>
    </visual>
    <collision>
      <origin rpy="0 0 0" xyz="0 0 0"/>
      <geometry>
        <mesh filename="file:///home/imbatman/smdw_ws/src/left_smdw/meshes/FL_RR_link_14.STL"/>
      </geometry>
    </collision>
  </link>
  <joint name="front_left_RR_joint_14" type="continuous">
    <origin rpy="0.2849 -0.2740 -0.8249" xyz="-0.0350 -0.0279 0.0845"/>
    <parent link="front_left_base_link"/>
    <child link="front_left_RR_link_14"/>
    <axis xyz="0 -1 0"/>
  </joint>
  <gazebo reference="front_left_RR_link_14">
    <material>Gazebo/DarkGrey</material>
    <surface>
      <friction>
        <ode>
          <mu>1.0</mu>
          <mu2>0.1</mu2>
        </ode>
      </friction>
    </surface>
  </gazebo>
  <link name="front_left_LR_link_1">
    <inertial>
      <origin rpy="0 0 0" xyz="0 0 0"/>
      <mass value="0.0343"/>
      <inertia ixx="0.00001147" ixy="0" ixz="0" iyy="0.000001312" iyz="0" izz="0.00001147"/>
    </inertial>
    <visual>
      <origin rpy="0 0 0" xyz="0 0 0"/>
      <geometry>
        <mesh filename="file:///home/imbatman/smdw_ws/src/left_smdw/meshes/FL_LR_link_1.STL"/>
      </geometry>
      <material name="front_left_base_color"/>
    </visual>
    <collision>
      <origin rpy="0 0 0" xyz="0 0 0"/>
      <geometry>
        <mesh filename="file:///home/imbatman/smdw_ws/src/left_smdw/meshes/FL_LR_link_1.STL"/>
      </geometry>
    </collision>
  </link>
  <joint name="front_left_LR_joint_1" type="continuous">
    <origin rpy="0.0000 0.0000 -0.7854" xyz="0.0000 0.0279 0.0533"/>
    <parent link="front_left_base_link"/>
    <child link="front_left_LR_link_1"/>
    <axis xyz="0 -1 0"/>
  </joint>
  <gazebo reference="front_left_LR_link_1">
    <material>Gazebo/DarkGrey</material>
    <surface>
      <friction>
        <ode>
          <mu>1.0</mu>
          <mu2>0.1</mu2>
        </ode>
      </friction>
    </surface>
  </gazebo>
  <link name="front_left_LR_link_2">
    <inertial>
      <origin rpy="0 0 0" xyz="0 0 0"/>
      <mass value="0.0343"/>
      <inertia ixx="0.00001147" ixy="0" ixz="0" iyy="0.000001312" iyz="0" izz="0.00001147"/>
    </inertial>
    <visual>
      <origin rpy="0 0 0" xyz="0 0 0"/>
      <geometry>
        <mesh filename="file:///home/imbatman/smdw_ws/src/left_smdw/meshes/FL_LR_link_2.STL"/>
      </geometry>
      <material name="front_left_base_color"/>
    </visual>
    <collision>
      <origin rpy="0 0 0" xyz="0 0 0"/>
      <geometry>
        <mesh filename="file:///home/imbatman/smdw_ws/src/left_smdw/meshes/FL_LR_link_2.STL"/>
      </geometry>
    </collision>
  </link>
  <joint name="front_left_LR_joint_2" type="continuous">
    <origin rpy="-0.1534 0.1517 -0.7971" xyz="0.0338 0.0279 0.0498"/>
    <parent link="front_left_base_link"/>
    <child link="front_left_LR_link_2"/>
    <axis xyz="0 -1 0"/>
  </joint>
  <gazebo reference="front_left_LR_link_2">
    <material>Gazebo/DarkGrey</material>
    <surface>
      <friction>
        <ode>
          <mu>1.0</mu>
          <mu2>0.1</mu2>
        </ode>
      </friction>
    </surface>
  </gazebo>
  <link name="front_left_LR_link_3">
    <inertial>
      <origin rpy="0 0 0" xyz="0 0 0"/>
      <mass value="0.0343"/>
      <inertia ixx="0.00001147" ixy="0" ixz="0" iyy="0.000001312" iyz="0" izz="0.00001147"/>
    </inertial>
    <visual>
      <origin rpy="0 0 0" xyz="0 0 0"/>
      <geometry>
        <mesh filename="file:///home/imbatman/smdw_ws/src/left_smdw/meshes/FL_LR_link_3.STL"/>
      </geometry>
      <material name="front_left_base_color"/>
    </visual>
    <collision>
      <origin rpy="0 0 0" xyz="0 0 0"/>
      <geometry>
        <mesh filename="file:///home/imbatman/smdw_ws/src/left_smdw/meshes/FL_LR_link_3.STL"/>
      </geometry>
    </collision>
  </link>
  <joint name="front_left_LR_joint_3" type="continuous">
    <origin rpy="-0.4107 0.3798 -0.8654" xyz="0.0671 0.0279 0.0370"/>
    <parent link="front_left_base_link"/>
    <child link="front_left_LR_link_3"/>
    <axis xyz="0 -1 0"/>
  </joint>
  <gazebo reference="front_left_LR_link_3">
    <material>Gazebo/DarkGrey</material>
    <surface>
      <friction>
        <ode>
          <mu>1.0</mu>
          <mu2>0.1</mu2>
        </ode>
      </friction>
    </surface>
  </gazebo>
  <link name="front_left_LR_link_4">
    <inertial>
      <origin rpy="0 0 0" xyz="0 0 0"/>
      <mass value="0.0343"/>
      <inertia ixx="0.00001147" ixy="0" ixz="0" iyy="0.000001312" iyz="0" izz="0.00001147"/>
    </inertial>
    <visual>
      <origin rpy="0 0 0" xyz="0 0 0"/>
      <geometry>
        <mesh filename="file:///home/imbatman/smdw_ws/src/left_smdw/meshes/FL_LR_link_4.STL"/>
      </geometry>
      <material name="front_left_base_color"/>
    </visual>
    <collision>
      <origin rpy="0 0 0" xyz="0 0 0"/>
      <geometry>
        <mesh filename="file:///home/imbatman/smdw_ws/src/left_smdw/meshes/FL_LR_link_4.STL"/>
      </geometry>
    </collision>
  </link>
  <joint name="front_left_LR_joint_4" type="continuous">
    <origin rpy="-1.5708 0.7854 -1.5708" xyz="0.0914 0.0279 0.0000"/>
    <parent link="front_left_base_link"/>
    <child link="front_left_LR_link_4"/>
    <axis xyz="0 -1 0"/>
  </joint>
  <gazebo reference="front_left_LR_link_4">
    <material>Gazebo/DarkGrey</material>
    <surface>
      <friction>
        <ode>
          <mu>1.0</mu>
          <mu2>0.1</mu2>
        </ode>
      </friction>
    </surface>
  </gazebo>
  <link name="front_left_LR_link_5">
    <inertial>
      <origin rpy="0 0 0" xyz="0 0 0"/>
      <mass value="0.0343"/>
      <inertia ixx="0.00001147" ixy="0" ixz="0" iyy="0.000001312" iyz="0" izz="0.00001147"/>
    </inertial>
    <visual>
      <origin rpy="0 0 0" xyz="0 0 0"/>
      <geometry>
        <mesh filename="file:///home/imbatman/smdw_ws/src/left_smdw/meshes/FL_LR_link_5.STL"/>
      </geometry>
      <material name="front_left_base_color"/>
    </visual>
    <collision>
      <origin rpy="0 0 0" xyz="0 0 0"/>
      <geometry>
        <mesh filename="file:///home/imbatman/smdw_ws/src/left_smdw/meshes/FL_LR_link_5.STL"/>
      </geometry>
    </collision>
  </link>
  <joint name="front_left_LR_joint_5" type="continuous">
    <origin rpy="-2.1007 0.7119 -1.9363" xyz="0.0845 0.0279 -0.0350"/>
    <parent link="front_left_base_link"/>
    <child link="front_left_LR_link_5"/>
    <axis xyz="0 -1 0"/>
  </joint>
  <gazebo reference="front_left_LR_link_5">
    <material>Gazebo/DarkGrey</material>
    <surface>
      <friction>
        <ode>
          <mu>1.0</mu>
          <mu2>0.1</mu2>
        </ode>
      </friction>
    </surface>
  </gazebo>
  <link name="front_left_LR_link_6">
    <inertial>
      <origin rpy="0 0 0" xyz="0 0 0"/>
      <mass value="0.0343"/>
      <inertia ixx="0.00001147" ixy="0" ixz="0" iyy="0.000001312" iyz="0" izz="0.00001147"/>
    </inertial>
    <visual>
      <origin rpy="0 0 0" xyz="0 0 0"/>
      <geometry>
        <mesh filename="file:///home/imbatman/smdw_ws/src/left_smdw/meshes/FL_LR_link_6.STL"/>
      </geometry>
      <material name="front_left_base_color"/>
    </visual>
    <collision>
      <origin rpy="0 0 0" xyz="0 0 0"/>
      <geometry>
        <mesh filename="file:///home/imbatman/smdw_ws/src/left_smdw/meshes/FL_LR_link_6.STL"/>
      </geometry>
    </collision>
  </link>
  <joint name="front_left_LR_joint_6" type="continuous">
    <origin rpy="-2.5261 0.5236 -2.1863" xyz="0.0647 0.0279 -0.0647"/>
    <parent link="front_left_base_link"/>
    <child link="front_left_LR_link_6"/>
    <axis xyz="0 -1 0"/>
  </joint>
  <gazebo reference="front_left_LR_link_6">
    <material>Gazebo/DarkGrey</material>
    <surface>
      <friction>
        <ode>
          <mu>1.0</mu>
          <mu2>0.1</mu2>
        </ode>
      </friction>
    </surface>
  </gazebo>
  <link name="front_left_LR_link_7">
    <inertial>
      <origin rpy="0 0 0" xyz="0 0 0"/>
      <mass value="0.0343"/>
      <inertia ixx="0.00001147" ixy="0" ixz="0" iyy="0.000001312" iyz="0" izz="0.00001147"/>
    </inertial>
    <visual>
      <origin rpy="0 0 0" xyz="0 0 0"/>
      <geometry>
        <mesh filename="file:///home/imbatman/smdw_ws/src/left_smdw/meshes/FL_LR_link_7.STL"/>
      </geometry>
      <material name="front_left_base_color"/>
    </visual>
    <collision>
      <origin rpy="0 0 0" xyz="0 0 0"/>
      <geometry>
        <mesh filename="file:///home/imbatman/smdw_ws/src/left_smdw/meshes/FL_LR_link_7.STL"/>
      </geometry>
    </collision>
  </link>
  <joint name="front_left_LR_joint_7" type="continuous">
    <origin rpy="-2.8567 0.2740 -2.3166" xyz="0.0350 0.0279 -0.0845"/>
    <parent link="front_left_base_link"/>
    <child link="front_left_LR_link_7"/>
    <axis xyz="0 -1 0"/>
  </joint>
  <gazebo reference="front_left_LR_link_7">
    <material>Gazebo/DarkGrey</material>
    <surface>
      <friction>
        <ode>
          <mu>1.0</mu>
          <mu2>0.1</mu2>
        </ode>
      </friction>
    </surface>
  </gazebo>
  <link name="front_left_LR_link_8">
    <inertial>
      <origin rpy="0 0 0" xyz="0 0 0"/>
      <mass value="0.0343"/>
      <inertia ixx="0.00001147" ixy="0" ixz="0" iyy="0.000001312" iyz="0" izz="0.00001147"/>
    </inertial>
    <visual>
      <origin rpy="0 0 0" xyz="0 0 0"/>
      <geometry>
        <mesh filename="file:///home/imbatman/smdw_ws/src/left_smdw/meshes/FL_LR_link_8.STL"/>
      </geometry>
      <material name="front_left_base_color"/>
    </visual>
    <collision>
      <origin rpy="0 0 0" xyz="0 0 0"/>
      <geometry>
        <mesh filename="file:///home/imbatman/smdw_ws/src/left_smdw/meshes/FL_LR_link_8.STL"/>
      </geometry>
    </collision>
  </link>
  <joint name="front_left_LR_joint_8" type="continuous">
    <origin rpy="3.1416 0.0000 -2.3562" xyz="0.0000 0.0279 -0.0914"/>
    <parent link="front_left_base_link"/>
    <child link="front_left_LR_link_8"/>
    <axis xyz="0 -1 0"/>
  </joint>
  <gazebo reference="front_left_LR_link_8">
    <material>Gazebo/DarkGrey</material>
    <surface>
      <friction>
        <ode>
          <mu>1.0</mu>
          <mu2>0.1</mu2>
        </ode>
      </friction>
    </surface>
  </gazebo>
  <link name="front_left_LR_link_9">
    <inertial>
      <origin rpy="0 0 0" xyz="0 0 0"/>
      <mass value="0.0343"/>
      <inertia ixx="0.00001147" ixy="0" ixz="0" iyy="0.000001312" iyz="0" izz="0.00001147"/>
    </inertial>
    <visual>
      <origin rpy="0 0 0" xyz="0 0 0"/>
      <geometry>
        <mesh filename="file:///home/imbatman/smdw_ws/src/left_smdw/meshes/FL_LR_link_9.STL"/>
      </geometry>
      <material name="front_left_base_color"/>
    </visual>
    <collision>
      <origin rpy="0 0 0" xyz="0 0 0"/>
      <geometry>
        <mesh filename="file:///home/imbatman/smdw_ws/src/left_smdw/meshes/FL_LR_link_9.STL"/>
      </geometry>
    </collision>
  </link>
  <joint name="front_left_LR_joint_9" type="continuous">
    <origin rpy="2.8567 -0.2740 -2.3166" xyz="-0.0350 0.0279 -0.0845"/>
    <parent link="front_left_base_link"/>
    <child link="front_left_LR_link_9"/>
    <axis xyz="0 -1 0"/>
  </joint>
  <gazebo reference="front_left_LR_link_9">
    <material>Gazebo/DarkGrey</material>
    <surface>
      <friction>
        <ode>
          <mu>1.0</mu>
          <mu2>0.1</mu2>
        </ode>
      </friction>
    </surface>
  </gazebo>
  <link name="front_left_LR_link_10">
    <inertial>
      <origin rpy="0 0 0" xyz="0 0 0"/>
      <mass value="0.0343"/>
      <inertia ixx="0.00001147" ixy="0" ixz="0" iyy="0.000001312" iyz="0" izz="0.00001147"/>
    </inertial>
    <visual>
      <origin rpy="0 0 0" xyz="0 0 0"/>
      <geometry>
        <mesh filename="file:///home/imbatman/smdw_ws/src/left_smdw/meshes/FL_LR_link_10.STL"/>
      </geometry>
      <material name="front_left_base_color"/>
    </visual>
    <collision>
      <origin rpy="0 0 0" xyz="0 0 0"/>
      <geometry>
        <mesh filename="file:///home/imbatman/smdw_ws/src/left_smdw/meshes/FL_LR_link_10.STL"/>
      </geometry>
    </collision>
  </link>
  <joint name="front_left_LR_joint_10" type="continuous">
    <origin rpy="2.5261 -0.5236 -2.1863" xyz="-0.0647 0.0279 -0.0647"/>
    <parent link="front_left_base_link"/>
    <child link="front_left_LR_link_10"/>
    <axis xyz="0 -1 0"/>
  </joint>
  <gazebo reference="front_left_LR_link_10">
    <material>Gazebo/DarkGrey</material>
    <surface>
      <friction>
        <ode>
          <mu>1.0</mu>
          <mu2>0.1</mu2>
        </ode>
      </friction>
    </surface>
  </gazebo>
  <link name="front_left_LR_link_11">
    <inertial>
      <origin rpy="0 0 0" xyz="0 0 0"/>
      <mass value="0.0343"/>
      <inertia ixx="0.00001147" ixy="0" ixz="0" iyy="0.000001312" iyz="0" izz="0.00001147"/>
    </inertial>
    <visual>
      <origin rpy="0 0 0" xyz="0 0 0"/>
      <geometry>
        <mesh filename="file:///home/imbatman/smdw_ws/src/left_smdw/meshes/FL_LR_link_11.STL"/>
      </geometry>
      <material name="front_left_base_color"/>
    </visual>
    <collision>
      <origin rpy="0 0 0" xyz="0 0 0"/>
      <geometry>
        <mesh filename="file:///home/imbatman/smdw_ws/src/left_smdw/meshes/FL_LR_link_11.STL"/>
      </geometry>
    </collision>
  </link>
  <joint name="front_left_LR_joint_11" type="continuous">
    <origin rpy="2.1007 -0.7119 -1.9363" xyz="-0.0845 0.0279 -0.0350"/>
    <parent link="front_left_base_link"/>
    <child link="front_left_LR_link_11"/>
    <axis xyz="0 -1 0"/>
  </joint>
  <gazebo reference="front_left_LR_link_11">
    <material>Gazebo/DarkGrey</material>
    <surface>
      <friction>
        <ode>
          <mu>1.0</mu>
          <mu2>0.1</mu2>
        </ode>
      </friction>
    </surface>
  </gazebo>
  <link name="front_left_LR_link_12">
    <inertial>
      <origin rpy="0 0 0" xyz="0 0 0"/>
      <mass value="0.0343"/>
      <inertia ixx="0.00001147" ixy="0" ixz="0" iyy="0.000001312" iyz="0" izz="0.00001147"/>
    </inertial>
    <visual>
      <origin rpy="0 0 0" xyz="0 0 0"/>
      <geometry>
        <mesh filename="file:///home/imbatman/smdw_ws/src/left_smdw/meshes/FL_LR_link_12.STL"/>
      </geometry>
      <material name="front_left_base_color"/>
    </visual>
    <collision>
      <origin rpy="0 0 0" xyz="0 0 0"/>
      <geometry>
        <mesh filename="file:///home/imbatman/smdw_ws/src/left_smdw/meshes/FL_LR_link_12.STL"/>
      </geometry>
    </collision>
  </link>
  <joint name="front_left_LR_joint_12" type="continuous">
    <origin rpy="1.5708 -0.7854 -1.5708" xyz="-0.0914 0.0279 0.0000"/>
    <parent link="front_left_base_link"/>
    <child link="front_left_LR_link_12"/>
    <axis xyz="0 -1 0"/>
  </joint>
  <gazebo reference="front_left_LR_link_12">
    <material>Gazebo/DarkGrey</material>
    <surface>
      <friction>
        <ode>
          <mu>1.0</mu>
          <mu2>0.1</mu2>
        </ode>
      </friction>
    </surface>
  </gazebo>
  <link name="front_left_LR_link_13">
    <inertial>
      <origin rpy="0 0 0" xyz="0 0 0"/>
      <mass value="0.0343"/>
      <inertia ixx="0.00001147" ixy="0" ixz="0" iyy="0.000001312" iyz="0" izz="0.00001147"/>
    </inertial>
    <visual>
      <origin rpy="0 0 0" xyz="0 0 0"/>
      <geometry>
        <mesh filename="file:///home/imbatman/smdw_ws/src/left_smdw/meshes/FL_LR_link_13.STL"/>
      </geometry>
      <material name="front_left_base_color"/>
    </visual>
    <collision>
      <origin rpy="0 0 0" xyz="0 0 0"/>
      <geometry>
        <mesh filename="file:///home/imbatman/smdw_ws/src/left_smdw/meshes/FL_LR_link_13.STL"/>
      </geometry>
    </collision>
  </link>
  <joint name="front_left_LR_joint_13" type="continuous">
    <origin rpy="0.4107 -0.3798 -0.8654" xyz="-0.0671 0.0279 0.0370"/>
    <parent link="front_left_base_link"/>
    <child link="front_left_LR_link_13"/>
    <axis xyz="0 -1 0"/>
  </joint>
  <gazebo reference="front_left_LR_link_13">
    <material>Gazebo/DarkGrey</material>
    <surface>
      <friction>
        <ode>
          <mu>1.0</mu>
          <mu2>0.1</mu2>
        </ode>
      </friction>
    </surface>
  </gazebo>
  <link name="front_left_LR_link_14">
    <inertial>
      <origin rpy="0 0 0" xyz="0 0 0"/>
      <mass value="0.0343"/>
      <inertia ixx="0.00001147" ixy="0" ixz="0" iyy="0.000001312" iyz="0" izz="0.00001147"/>
    </inertial>
    <visual>
      <origin rpy="0 0 0" xyz="0 0 0"/>
      <geometry>
        <mesh filename="file:///home/imbatman/smdw_ws/src/left_smdw/meshes/FL_LR_link_14.STL"/>
      </geometry>
      <material name="front_left_base_color"/>
    </visual>
    <collision>
      <origin rpy="0 0 0" xyz="0 0 0"/>
      <geometry>
        <mesh filename="file:///home/imbatman/smdw_ws/src/left_smdw/meshes/FL_LR_link_14.STL"/>
      </geometry>
    </collision>
  </link>
  <joint name="front_left_LR_joint_14" type="continuous">
    <origin rpy="0.1534 -0.1517 -0.7971" xyz="-0.0338 0.0279 0.0498"/>
    <parent link="front_left_base_link"/>
    <child link="front_left_LR_link_14"/>
    <axis xyz="0 -1 0"/>
  </joint>
  <gazebo reference="front_left_LR_link_14">
    <material>Gazebo/DarkGrey</material>
    <surface>
      <friction>
        <ode>
          <mu>1.0</mu>
          <mu2>0.1</mu2>
        </ode>
      </friction>
    </surface>
  </gazebo>
  <!-- Define materials -->
  <material name="rear_right_base_color">
    <color rgba="0.79216 0.81961 0.93333 1"/>
  </material>
  <material name="rear_right_wheel_color">
    <color rgba="0.25098 0.25098 0.25098 1"/>
  </material>
  <!-- Base link -->
  <link name="rear_right_base_link">
    <inertial>
      <origin rpy="0 0 0" xyz="-4.3311E-18 1.504E-12 1.7857E-18"/>
      <mass value="1.9429"/>
      <inertia ixx="0.0019245" ixy="8.1609E-21" ixz="-8.1689E-08" iyy="0.0049239" iyz="-7.5092E-20" izz="0.0032216"/>
    </inertial>
    <visual>
      <origin rpy="0 0 0" xyz="0 0 0"/>
      <geometry>
        <mesh filename="file:///home/imbatman/smdw_ws/src/left_smdw/meshes/front_left_wheel_base_link.STL"/>
      </geometry>
      <material name="rear_right_wheel_color"/>
    </visual>
    <collision>
      <origin rpy="0 0 0" xyz="0 0 0"/>
      <geometry>
        <mesh filename="file:///home/imbatman/smdw_ws/src/left_smdw/meshes/front_left_wheel_base_link.STL"/>
      </geometry>
    </collision>
  </link>
  <link name="rear_right_RR_link_1">
    <inertial>
      <origin rpy="0 0 0" xyz="0 0 0"/>
      <mass value="0.0343"/>
      <inertia ixx="0.00001147" ixy="0" ixz="0" iyy="0.000001312" iyz="0" izz="0.00001147"/>
    </inertial>
    <visual>
      <origin rpy="0 0 0" xyz="0 0 0"/>
      <geometry>
        <mesh filename="file:///home/imbatman/smdw_ws/src/left_smdw/meshes/FL_RR_link_1.STL"/>
      </geometry>
      <material name="rear_right_base_color"/>
    </visual>
    <collision>
      <origin rpy="0 0 0" xyz="0 0 0"/>
      <geometry>
        <mesh filename="file:///home/imbatman/smdw_ws/src/left_smdw/meshes/FL_RR_link_1.STL"/>
      </geometry>
    </collision>
  </link>
  <joint name="rear_right_RR_joint_1" type="continuous">
    <origin rpy="0.0000 0.0000 -0.7854" xyz="0.0000 -0.0279 0.0914"/>
    <parent link="rear_right_base_link"/>
    <child link="rear_right_RR_link_1"/>
    <axis xyz="0 -1 0"/>
  </joint>
  <gazebo reference="rear_right_RR_link_1">
    <material>Gazebo/DarkGrey</material>
    <surface>
      <friction>
        <ode>
          <mu>1.0</mu>
          <mu2>0.1</mu2>
        </ode>
      </friction>
    </surface>
  </gazebo>
  <link name="rear_right_RR_link_2">
    <inertial>
      <origin rpy="0 0 0" xyz="0 0 0"/>
      <mass value="0.0343"/>
      <inertia ixx="0.00001147" ixy="0" ixz="0" iyy="0.000001312" iyz="0" izz="0.00001147"/>
    </inertial>
    <visual>
      <origin rpy="0 0 0" xyz="0 0 0"/>
      <geometry>
        <mesh filename="file:///home/imbatman/smdw_ws/src/left_smdw/meshes/FL_RR_link_2.STL"/>
      </geometry>
      <material name="rear_right_base_color"/>
    </visual>
    <collision>
      <origin rpy="0 0 0" xyz="0 0 0"/>
      <geometry>
        <mesh filename="file:///home/imbatman/smdw_ws/src/left_smdw/meshes/FL_RR_link_2.STL"/>
      </geometry>
    </collision>
  </link>
  <joint name="rear_right_RR_joint_2" type="continuous">
    <origin rpy="-0.2849 0.2740 -0.8249" xyz="0.0350 -0.0279 0.0845"/>
    <parent link="rear_right_base_link"/>
    <child link="rear_right_RR_link_2"/>
    <axis xyz="0 -1 0"/>
  </joint>
  <gazebo reference="rear_right_RR_link_2">
    <material>Gazebo/DarkGrey</material>
    <surface>
      <friction>
        <ode>
          <mu>1.0</mu>
          <mu2>0.1</mu2>
        </ode>
      </friction>
    </surface>
  </gazebo>
  <link name="rear_right_RR_link_3">
    <inertial>
      <origin rpy="0 0 0" xyz="0 0 0"/>
      <mass value="0.0343"/>
      <inertia ixx="0.00001147" ixy="0" ixz="0" iyy="0.000001312" iyz="0" izz="0.00001147"/>
    </inertial>
    <visual>
      <origin rpy="0 0 0" xyz="0 0 0"/>
      <geometry>
        <mesh filename="file:///home/imbatman/smdw_ws/src/left_smdw/meshes/FL_RR_link_3.STL"/>
      </geometry>
      <material name="rear_right_base_color"/>
    </visual>
    <collision>
      <origin rpy="0 0 0" xyz="0 0 0"/>
      <geometry>
        <mesh filename="file:///home/imbatman/smdw_ws/src/left_smdw/meshes/FL_RR_link_3.STL"/>
      </geometry>
    </collision>
  </link>
  <joint name="rear_right_RR_joint_3" type="continuous">
    <origin rpy="-0.6155 0.5236 -0.9553" xyz="0.0647 -0.0279 0.0647"/>
    <parent link="rear_right_base_link"/>
    <child link="rear_right_RR_link_3"/>
    <axis xyz="0 -1 0"/>
  </joint>
  <gazebo reference="rear_right_RR_link_3">
    <material>Gazebo/DarkGrey</material>
    <surface>
      <friction>
        <ode>
          <mu>1.0</mu>
          <mu2>0.1</mu2>
        </ode>
      </friction>
    </surface>
  </gazebo>
  <link name="rear_right_RR_link_4">
    <inertial>
      <origin rpy="0 0 0" xyz="0 0 0"/>
      <mass value="0.0343"/>
      <inertia ixx="0.00001147" ixy="0" ixz="0" iyy="0.000001312" iyz="0" izz="0.00001147"/>
    </inertial>
    <visual>
      <origin rpy="0 0 0" xyz="0 0 0"/>
      <geometry>
        <mesh filename="file:///home/imbatman/smdw_ws/src/left_smdw/meshes/FL_RR_link_4.STL"/>
      </geometry>
      <material name="rear_right_base_color"/>
    </visual>
    <collision>
      <origin rpy="0 0 0" xyz="0 0 0"/>
      <geometry>
        <mesh filename="file:///home/imbatman/smdw_ws/src/left_smdw/meshes/FL_RR_link_4.STL"/>
      </geometry>
    </collision>
  </link>
  <joint name="rear_right_RR_joint_4" type="continuous">
    <origin rpy="-1.0409 0.7119 -1.2053" xyz="0.0845 -0.0279 0.0350"/>
    <parent link="rear_right_base_link"/>
    <child link="rear_right_RR_link_4"/>
    <axis xyz="0 -1 0"/>
  </joint>
  <gazebo reference="rear_right_RR_link_4">
    <material>Gazebo/DarkGrey</material>
    <surface>
      <friction>
        <ode>
          <mu>1.0</mu>
          <mu2>0.1</mu2>
        </ode>
      </friction>
    </surface>
  </gazebo>
  <link name="rear_right_RR_link_5">
    <inertial>
      <origin rpy="0 0 0" xyz="0 0 0"/>
      <mass value="0.0343"/>
      <inertia ixx="0.00001147" ixy="0" ixz="0" iyy="0.000001312" iyz="0" izz="0.00001147"/>
    </inertial>
    <visual>
      <origin rpy="0 0 0" xyz="0 0 0"/>
      <geometry>
        <mesh filename="file:///home/imbatman/smdw_ws/src/left_smdw/meshes/FL_RR_link_5.STL"/>
      </geometry>
      <material name="rear_right_base_color"/>
    </visual>
    <collision>
      <origin rpy="0 0 0" xyz="0 0 0"/>
      <geometry>
        <mesh filename="file:///home/imbatman/smdw_ws/src/left_smdw/meshes/FL_RR_link_5.STL"/>
      </geometry>
    </collision>
  </link>
  <joint name="rear_right_RR_joint_5" type="continuous">
    <origin rpy="-1.5708 0.7854 -1.5708" xyz="0.0914 -0.0279 0.0000"/>
    <parent link="rear_right_base_link"/>
    <child link="rear_right_RR_link_5"/>
    <axis xyz="0 -1 0"/>
  </joint>
  <gazebo reference="rear_right_RR_link_5">
    <material>Gazebo/DarkGrey</material>
    <surface>
      <friction>
        <ode>
          <mu>1.0</mu>
          <mu2>0.1</mu2>
        </ode>
      </friction>
    </surface>
  </gazebo>
  <link name="rear_right_RR_link_6">
    <inertial>
      <origin rpy="0 0 0" xyz="0 0 0"/>
      <mass value="0.0343"/>
      <inertia ixx="0.00001147" ixy="0" ixz="0" iyy="0.000001312" iyz="0" izz="0.00001147"/>
    </inertial>
    <visual>
      <origin rpy="0 0 0" xyz="0 0 0"/>
      <geometry>
        <mesh filename="file:///home/imbatman/smdw_ws/src/left_smdw/meshes/FL_RR_link_6.STL"/>
      </geometry>
      <material name="rear_right_base_color"/>
    </visual>
    <collision>
      <origin rpy="0 0 0" xyz="0 0 0"/>
      <geometry>
        <mesh filename="file:///home/imbatman/smdw_ws/src/left_smdw/meshes/FL_RR_link_6.STL"/>
      </geometry>
    </collision>
  </link>
  <joint name="rear_right_RR_joint_6" type="continuous">
    <origin rpy="-2.7309 0.3798 -2.2762" xyz="0.0671 -0.0279 -0.0370"/>
    <parent link="rear_right_base_link"/>
    <child link="rear_right_RR_link_6"/>
    <axis xyz="0 -1 0"/>
  </joint>
  <gazebo reference="rear_right_RR_link_6">
    <material>Gazebo/DarkGrey</material>
    <surface>
      <friction>
        <ode>
          <mu>1.0</mu>
          <mu2>0.1</mu2>
        </ode>
      </friction>
    </surface>
  </gazebo>
  <link name="rear_right_RR_link_7">
    <inertial>
      <origin rpy="0 0 0" xyz="0 0 0"/>
      <mass value="0.0343"/>
      <inertia ixx="0.00001147" ixy="0" ixz="0" iyy="0.000001312" iyz="0" izz="0.00001147"/>
    </inertial>
    <visual>
      <origin rpy="0 0 0" xyz="0 0 0"/>
      <geometry>
        <mesh filename="file:///home/imbatman/smdw_ws/src/left_smdw/meshes/FL_RR_link_7.STL"/>
      </geometry>
      <material name="rear_right_base_color"/>
    </visual>
    <collision>
      <origin rpy="0 0 0" xyz="0 0 0"/>
      <geometry>
        <mesh filename="file:///home/imbatman/smdw_ws/src/left_smdw/meshes/FL_RR_link_7.STL"/>
      </geometry>
    </collision>
  </link>
  <joint name="rear_right_RR_joint_7" type="continuous">
    <origin rpy="-2.9882 0.1516 -2.3445" xyz="0.0320 -0.0261 -0.0502"/>
    <parent link="rear_right_base_link"/>
    <child link="rear_right_RR_link_7"/>
    <axis xyz="0 -1 0"/>
  </joint>
  <gazebo reference="rear_right_RR_link_7">
    <material>Gazebo/DarkGrey</material>
    <surface>
      <friction>
        <ode>
          <mu>1.0</mu>
          <mu2>0.1</mu2>
        </ode>
      </friction>
    </surface>
  </gazebo>
  <link name="rear_right_RR_link_8">
    <inertial>
      <origin rpy="0 0 0" xyz="0 0 0"/>
      <mass value="0.0343"/>
      <inertia ixx="0.00001147" ixy="0" ixz="0" iyy="0.000001312" iyz="0" izz="0.00001147"/>
    </inertial>
    <visual>
      <origin rpy="0 0 0" xyz="0 0 0"/>
      <geometry>
        <mesh filename="file:///home/imbatman/smdw_ws/src/left_smdw/meshes/FL_RR_link_8.STL"/>
      </geometry>
      <material name="rear_right_base_color"/>
    </visual>
    <collision>
      <origin rpy="0 0 0" xyz="0 0 0"/>
      <geometry>
        <mesh filename="file:///home/imbatman/smdw_ws/src/left_smdw/meshes/FL_RR_link_8.STL"/>
      </geometry>
    </collision>
  </link>
  <joint name="rear_right_RR_joint_8" type="continuous">
    <origin rpy="-3.1416 0.0000 -2.3562" xyz="0.0000 -0.0279 -0.0533"/>
    <parent link="rear_right_base_link"/>
    <child link="rear_right_RR_link_8"/>
    <axis xyz="0 -1 0"/>
  </joint>
  <gazebo reference="rear_right_RR_link_8">
    <material>Gazebo/DarkGrey</material>
    <surface>
      <friction>
        <ode>
          <mu>1.0</mu>
          <mu2>0.1</mu2>
        </ode>
      </friction>
    </surface>
  </gazebo>
  <link name="rear_right_RR_link_9">
    <inertial>
      <origin rpy="0 0 0" xyz="0 0 0"/>
      <mass value="0.0343"/>
      <inertia ixx="0.00001147" ixy="0" ixz="0" iyy="0.000001312" iyz="0" izz="0.00001147"/>
    </inertial>
    <visual>
      <origin rpy="0 0 0" xyz="0 0 0"/>
      <geometry>
        <mesh filename="file:///home/imbatman/smdw_ws/src/left_smdw/meshes/FL_RR_link_9.STL"/>
      </geometry>
      <material name="rear_right_base_color"/>
    </visual>
    <collision>
      <origin rpy="0 0 0" xyz="0 0 0"/>
      <geometry>
        <mesh filename="file:///home/imbatman/smdw_ws/src/left_smdw/meshes/FL_RR_link_9.STL"/>
      </geometry>
    </collision>
  </link>
  <joint name="rear_right_RR_joint_9" type="continuous">
    <origin rpy="2.9882 -0.1517 -2.3445" xyz="-0.0338 -0.0279 -0.0498"/>
    <parent link="rear_right_base_link"/>
    <child link="rear_right_RR_link_9"/>
    <axis xyz="0 -1 0"/>
  </joint>
  <gazebo reference="rear_right_RR_link_9">
    <material>Gazebo/DarkGrey</material>
    <surface>
      <friction>
        <ode>
          <mu>1.0</mu>
          <mu2>0.1</mu2>
        </ode>
      </friction>
    </surface>
  </gazebo>
  <link name="rear_right_RR_link_10">
    <inertial>
      <origin rpy="0 0 0" xyz="0 0 0"/>
      <mass value="0.0343"/>
      <inertia ixx="0.00001147" ixy="0" ixz="0" iyy="0.000001312" iyz="0" izz="0.00001147"/>
    </inertial>
    <visual>
      <origin rpy="0 0 0" xyz="0 0 0"/>
      <geometry>
        <mesh filename="file:///home/imbatman/smdw_ws/src/left_smdw/meshes/FL_RR_link_10.STL"/>
      </geometry>
      <material name="rear_right_base_color"/>
    </visual>
    <collision>
      <origin rpy="0 0 0" xyz="0 0 0"/>
      <geometry>
        <mesh filename="file:///home/imbatman/smdw_ws/src/left_smdw/meshes/FL_RR_link_10.STL"/>
      </geometry>
    </collision>
  </link>
  <joint name="rear_right_RR_joint_10" type="continuous">
    <origin rpy="2.7309 -0.3798 -2.2762" xyz="-0.0671 -0.0279 -0.0370"/>
    <parent link="rear_right_base_link"/>
    <child link="rear_right_RR_link_10"/>
    <axis xyz="0 -1 0"/>
  </joint>
  <gazebo reference="rear_right_RR_link_10">
    <material>Gazebo/DarkGrey</material>
    <surface>
      <friction>
        <ode>
          <mu>1.0</mu>
          <mu2>0.1</mu2>
        </ode>
      </friction>
    </surface>
  </gazebo>
  <link name="rear_right_RR_link_11">
    <inertial>
      <origin rpy="0 0 0" xyz="0 0 0"/>
      <mass value="0.0343"/>
      <inertia ixx="0.00001147" ixy="0" ixz="0" iyy="0.000001312" iyz="0" izz="0.00001147"/>
    </inertial>
    <visual>
      <origin rpy="0 0 0" xyz="0 0 0"/>
      <geometry>
        <mesh filename="file:///home/imbatman/smdw_ws/src/left_smdw/meshes/FL_RR_link_11.STL"/>
      </geometry>
      <material name="rear_right_base_color"/>
    </visual>
    <collision>
      <origin rpy="0 0 0" xyz="0 0 0"/>
      <geometry>
        <mesh filename="file:///home/imbatman/smdw_ws/src/left_smdw/meshes/FL_RR_link_11.STL"/>
      </geometry>
    </collision>
  </link>
  <joint name="rear_right_RR_joint_11" type="continuous">
    <origin rpy="1.5708 -0.7854 -1.5708" xyz="-0.0914 -0.0279 0.0000"/>
    <parent link="rear_right_base_link"/>
    <child link="rear_right_RR_link_11"/>
    <axis xyz="0 -1 0"/>
  </joint>
  <gazebo reference="rear_right_RR_link_11">
    <material>Gazebo/DarkGrey</material>
    <surface>
      <friction>
        <ode>
          <mu>1.0</mu>
          <mu2>0.1</mu2>
        </ode>
      </friction>
    </surface>
  </gazebo>
  <link name="rear_right_RR_link_12">
    <inertial>
      <origin rpy="0 0 0" xyz="0 0 0"/>
      <mass value="0.0343"/>
      <inertia ixx="0.00001147" ixy="0" ixz="0" iyy="0.000001312" iyz="0" izz="0.00001147"/>
    </inertial>
    <visual>
      <origin rpy="0 0 0" xyz="0 0 0"/>
      <geometry>
        <mesh filename="file:///home/imbatman/smdw_ws/src/left_smdw/meshes/FL_RR_link_12.STL"/>
      </geometry>
      <material name="rear_right_base_color"/>
    </visual>
    <collision>
      <origin rpy="0 0 0" xyz="0 0 0"/>
      <geometry>
        <mesh filename="file:///home/imbatman/smdw_ws/src/left_smdw/meshes/FL_RR_link_12.STL"/>
      </geometry>
    </collision>
  </link>
  <joint name="rear_right_RR_joint_12" type="continuous">
    <origin rpy="1.0409 -0.7119 -1.2053" xyz="-0.0845 -0.0279 0.0350"/>
    <parent link="rear_right_base_link"/>
    <child link="rear_right_RR_link_12"/>
    <axis xyz="0 -1 0"/>
  </joint>
  <gazebo reference="rear_right_RR_link_12">
    <material>Gazebo/DarkGrey</material>
    <surface>
      <friction>
        <ode>
          <mu>1.0</mu>
          <mu2>0.1</mu2>
        </ode>
      </friction>
    </surface>
  </gazebo>
  <link name="rear_right_RR_link_13">
    <inertial>
      <origin rpy="0 0 0" xyz="0 0 0"/>
      <mass value="0.0343"/>
      <inertia ixx="0.00001147" ixy="0" ixz="0" iyy="0.000001312" iyz="0" izz="0.00001147"/>
    </inertial>
    <visual>
      <origin rpy="0 0 0" xyz="0 0 0"/>
      <geometry>
        <mesh filename="file:///home/imbatman/smdw_ws/src/left_smdw/meshes/FL_RR_link_13.STL"/>
      </geometry>
      <material name="rear_right_base_color"/>
    </visual>
    <collision>
      <origin rpy="0 0 0" xyz="0 0 0"/>
      <geometry>
        <mesh filename="file:///home/imbatman/smdw_ws/src/left_smdw/meshes/FL_RR_link_13.STL"/>
      </geometry>
    </collision>
  </link>
  <joint name="rear_right_RR_joint_13" type="continuous">
    <origin rpy="0.6155 -0.5236 -0.9553" xyz="-0.0647 -0.0279 0.0647"/>
    <parent link="rear_right_base_link"/>
    <child link="rear_right_RR_link_13"/>
    <axis xyz="0 -1 0"/>
  </joint>
  <gazebo reference="rear_right_RR_link_13">
    <material>Gazebo/DarkGrey</material>
    <surface>
      <friction>
        <ode>
          <mu>1.0</mu>
          <mu2>0.1</mu2>
        </ode>
      </friction>
    </surface>
  </gazebo>
  <link name="rear_right_RR_link_14">
    <inertial>
      <origin rpy="0 0 0" xyz="0 0 0"/>
      <mass value="0.0343"/>
      <inertia ixx="0.00001147" ixy="0" ixz="0" iyy="0.000001312" iyz="0" izz="0.00001147"/>
    </inertial>
    <visual>
      <origin rpy="0 0 0" xyz="0 0 0"/>
      <geometry>
        <mesh filename="file:///home/imbatman/smdw_ws/src/left_smdw/meshes/FL_RR_link_14.STL"/>
      </geometry>
      <material name="rear_right_base_color"/>
    </visual>
    <collision>
      <origin rpy="0 0 0" xyz="0 0 0"/>
      <geometry>
        <mesh filename="file:///home/imbatman/smdw_ws/src/left_smdw/meshes/FL_RR_link_14.STL"/>
      </geometry>
    </collision>
  </link>
  <joint name="rear_right_RR_joint_14" type="continuous">
    <origin rpy="0.2849 -0.2740 -0.8249" xyz="-0.0350 -0.0279 0.0845"/>
    <parent link="rear_right_base_link"/>
    <child link="rear_right_RR_link_14"/>
    <axis xyz="0 -1 0"/>
  </joint>
  <gazebo reference="rear_right_RR_link_14">
    <material>Gazebo/DarkGrey</material>
    <surface>
      <friction>
        <ode>
          <mu>1.0</mu>
          <mu2>0.1</mu2>
        </ode>
      </friction>
    </surface>
  </gazebo>
  <link name="rear_right_LR_link_1">
    <inertial>
      <origin rpy="0 0 0" xyz="0 0 0"/>
      <mass value="0.0343"/>
      <inertia ixx="0.00001147" ixy="0" ixz="0" iyy="0.000001312" iyz="0" izz="0.00001147"/>
    </inertial>
    <visual>
      <origin rpy="0 0 0" xyz="0 0 0"/>
      <geometry>
        <mesh filename="file:///home/imbatman/smdw_ws/src/left_smdw/meshes/FL_LR_link_1.STL"/>
      </geometry>
      <material name="rear_right_base_color"/>
    </visual>
    <collision>
      <origin rpy="0 0 0" xyz="0 0 0"/>
      <geometry>
        <mesh filename="file:///home/imbatman/smdw_ws/src/left_smdw/meshes/FL_LR_link_1.STL"/>
      </geometry>
    </collision>
  </link>
  <joint name="rear_right_LR_joint_1" type="continuous">
    <origin rpy="0.0000 0.0000 -0.7854" xyz="0.0000 0.0279 0.0533"/>
    <parent link="rear_right_base_link"/>
    <child link="rear_right_LR_link_1"/>
    <axis xyz="0 -1 0"/>
  </joint>
  <gazebo reference="rear_right_LR_link_1">
    <material>Gazebo/DarkGrey</material>
    <surface>
      <friction>
        <ode>
          <mu>1.0</mu>
          <mu2>0.1</mu2>
        </ode>
      </friction>
    </surface>
  </gazebo>
  <link name="rear_right_LR_link_2">
    <inertial>
      <origin rpy="0 0 0" xyz="0 0 0"/>
      <mass value="0.0343"/>
      <inertia ixx="0.00001147" ixy="0" ixz="0" iyy="0.000001312" iyz="0" izz="0.00001147"/>
    </inertial>
    <visual>
      <origin rpy="0 0 0" xyz="0 0 0"/>
      <geometry>
        <mesh filename="file:///home/imbatman/smdw_ws/src/left_smdw/meshes/FL_LR_link_2.STL"/>
      </geometry>
      <material name="rear_right_base_color"/>
    </visual>
    <collision>
      <origin rpy="0 0 0" xyz="0 0 0"/>
      <geometry>
        <mesh filename="file:///home/imbatman/smdw_ws/src/left_smdw/meshes/FL_LR_link_2.STL"/>
      </geometry>
    </collision>
  </link>
  <joint name="rear_right_LR_joint_2" type="continuous">
    <origin rpy="-0.1534 0.1517 -0.7971" xyz="0.0338 0.0279 0.0498"/>
    <parent link="rear_right_base_link"/>
    <child link="rear_right_LR_link_2"/>
    <axis xyz="0 -1 0"/>
  </joint>
  <gazebo reference="rear_right_LR_link_2">
    <material>Gazebo/DarkGrey</material>
    <surface>
      <friction>
        <ode>
          <mu>1.0</mu>
          <mu2>0.1</mu2>
        </ode>
      </friction>
    </surface>
  </gazebo>
  <link name="rear_right_LR_link_3">
    <inertial>
      <origin rpy="0 0 0" xyz="0 0 0"/>
      <mass value="0.0343"/>
      <inertia ixx="0.00001147" ixy="0" ixz="0" iyy="0.000001312" iyz="0" izz="0.00001147"/>
    </inertial>
    <visual>
      <origin rpy="0 0 0" xyz="0 0 0"/>
      <geometry>
        <mesh filename="file:///home/imbatman/smdw_ws/src/left_smdw/meshes/FL_LR_link_3.STL"/>
      </geometry>
      <material name="rear_right_base_color"/>
    </visual>
    <collision>
      <origin rpy="0 0 0" xyz="0 0 0"/>
      <geometry>
        <mesh filename="file:///home/imbatman/smdw_ws/src/left_smdw/meshes/FL_LR_link_3.STL"/>
      </geometry>
    </collision>
  </link>
  <joint name="rear_right_LR_joint_3" type="continuous">
    <origin rpy="-0.4107 0.3798 -0.8654" xyz="0.0671 0.0279 0.0370"/>
    <parent link="rear_right_base_link"/>
    <child link="rear_right_LR_link_3"/>
    <axis xyz="0 -1 0"/>
  </joint>
  <gazebo reference="rear_right_LR_link_3">
    <material>Gazebo/DarkGrey</material>
    <surface>
      <friction>
        <ode>
          <mu>1.0</mu>
          <mu2>0.1</mu2>
        </ode>
      </friction>
    </surface>
  </gazebo>
  <link name="rear_right_LR_link_4">
    <inertial>
      <origin rpy="0 0 0" xyz="0 0 0"/>
      <mass value="0.0343"/>
      <inertia ixx="0.00001147" ixy="0" ixz="0" iyy="0.000001312" iyz="0" izz="0.00001147"/>
    </inertial>
    <visual>
      <origin rpy="0 0 0" xyz="0 0 0"/>
      <geometry>
        <mesh filename="file:///home/imbatman/smdw_ws/src/left_smdw/meshes/FL_LR_link_4.STL"/>
      </geometry>
      <material name="rear_right_base_color"/>
    </visual>
    <collision>
      <origin rpy="0 0 0" xyz="0 0 0"/>
      <geometry>
        <mesh filename="file:///home/imbatman/smdw_ws/src/left_smdw/meshes/FL_LR_link_4.STL"/>
      </geometry>
    </collision>
  </link>
  <joint name="rear_right_LR_joint_4" type="continuous">
    <origin rpy="-1.5708 0.7854 -1.5708" xyz="0.0914 0.0279 0.0000"/>
    <parent link="rear_right_base_link"/>
    <child link="rear_right_LR_link_4"/>
    <axis xyz="0 -1 0"/>
  </joint>
  <gazebo reference="rear_right_LR_link_4">
    <material>Gazebo/DarkGrey</material>
    <surface>
      <friction>
        <ode>
          <mu>1.0</mu>
          <mu2>0.1</mu2>
        </ode>
      </friction>
    </surface>
  </gazebo>
  <link name="rear_right_LR_link_5">
    <inertial>
      <origin rpy="0 0 0" xyz="0 0 0"/>
      <mass value="0.0343"/>
      <inertia ixx="0.00001147" ixy="0" ixz="0" iyy="0.000001312" iyz="0" izz="0.00001147"/>
    </inertial>
    <visual>
      <origin rpy="0 0 0" xyz="0 0 0"/>
      <geometry>
        <mesh filename="file:///home/imbatman/smdw_ws/src/left_smdw/meshes/FL_LR_link_5.STL"/>
      </geometry>
      <material name="rear_right_base_color"/>
    </visual>
    <collision>
      <origin rpy="0 0 0" xyz="0 0 0"/>
      <geometry>
        <mesh filename="file:///home/imbatman/smdw_ws/src/left_smdw/meshes/FL_LR_link_5.STL"/>
      </geometry>
    </collision>
  </link>
  <joint name="rear_right_LR_joint_5" type="continuous">
    <origin rpy="-2.1007 0.7119 -1.9363" xyz="0.0845 0.0279 -0.0350"/>
    <parent link="rear_right_base_link"/>
    <child link="rear_right_LR_link_5"/>
    <axis xyz="0 -1 0"/>
  </joint>
  <gazebo reference="rear_right_LR_link_5">
    <material>Gazebo/DarkGrey</material>
    <surface>
      <friction>
        <ode>
          <mu>1.0</mu>
          <mu2>0.1</mu2>
        </ode>
      </friction>
    </surface>
  </gazebo>
  <link name="rear_right_LR_link_6">
    <inertial>
      <origin rpy="0 0 0" xyz="0 0 0"/>
      <mass value="0.0343"/>
      <inertia ixx="0.00001147" ixy="0" ixz="0" iyy="0.000001312" iyz="0" izz="0.00001147"/>
    </inertial>
    <visual>
      <origin rpy="0 0 0" xyz="0 0 0"/>
      <geometry>
        <mesh filename="file:///home/imbatman/smdw_ws/src/left_smdw/meshes/FL_LR_link_6.STL"/>
      </geometry>
      <material name="rear_right_base_color"/>
    </visual>
    <collision>
      <origin rpy="0 0 0" xyz="0 0 0"/>
      <geometry>
        <mesh filename="file:///home/imbatman/smdw_ws/src/left_smdw/meshes/FL_LR_link_6.STL"/>
      </geometry>
    </collision>
  </link>
  <joint name="rear_right_LR_joint_6" type="continuous">
    <origin rpy="-2.5261 0.5236 -2.1863" xyz="0.0647 0.0279 -0.0647"/>
    <parent link="rear_right_base_link"/>
    <child link="rear_right_LR_link_6"/>
    <axis xyz="0 -1 0"/>
  </joint>
  <gazebo reference="rear_right_LR_link_6">
    <material>Gazebo/DarkGrey</material>
    <surface>
      <friction>
        <ode>
          <mu>1.0</mu>
          <mu2>0.1</mu2>
        </ode>
      </friction>
    </surface>
  </gazebo>
  <link name="rear_right_LR_link_7">
    <inertial>
      <origin rpy="0 0 0" xyz="0 0 0"/>
      <mass value="0.0343"/>
      <inertia ixx="0.00001147" ixy="0" ixz="0" iyy="0.000001312" iyz="0" izz="0.00001147"/>
    </inertial>
    <visual>
      <origin rpy="0 0 0" xyz="0 0 0"/>
      <geometry>
        <mesh filename="file:///home/imbatman/smdw_ws/src/left_smdw/meshes/FL_LR_link_7.STL"/>
      </geometry>
      <material name="rear_right_base_color"/>
    </visual>
    <collision>
      <origin rpy="0 0 0" xyz="0 0 0"/>
      <geometry>
        <mesh filename="file:///home/imbatman/smdw_ws/src/left_smdw/meshes/FL_LR_link_7.STL"/>
      </geometry>
    </collision>
  </link>
  <joint name="rear_right_LR_joint_7" type="continuous">
    <origin rpy="-2.8567 0.2740 -2.3166" xyz="0.0350 0.0279 -0.0845"/>
    <parent link="rear_right_base_link"/>
    <child link="rear_right_LR_link_7"/>
    <axis xyz="0 -1 0"/>
  </joint>
  <gazebo reference="rear_right_LR_link_7">
    <material>Gazebo/DarkGrey</material>
    <surface>
      <friction>
        <ode>
          <mu>1.0</mu>
          <mu2>0.1</mu2>
        </ode>
      </friction>
    </surface>
  </gazebo>
  <link name="rear_right_LR_link_8">
    <inertial>
      <origin rpy="0 0 0" xyz="0 0 0"/>
      <mass value="0.0343"/>
      <inertia ixx="0.00001147" ixy="0" ixz="0" iyy="0.000001312" iyz="0" izz="0.00001147"/>
    </inertial>
    <visual>
      <origin rpy="0 0 0" xyz="0 0 0"/>
      <geometry>
        <mesh filename="file:///home/imbatman/smdw_ws/src/left_smdw/meshes/FL_LR_link_8.STL"/>
      </geometry>
      <material name="rear_right_base_color"/>
    </visual>
    <collision>
      <origin rpy="0 0 0" xyz="0 0 0"/>
      <geometry>
        <mesh filename="file:///home/imbatman/smdw_ws/src/left_smdw/meshes/FL_LR_link_8.STL"/>
      </geometry>
    </collision>
  </link>
  <joint name="rear_right_LR_joint_8" type="continuous">
    <origin rpy="3.1416 0.0000 -2.3562" xyz="0.0000 0.0279 -0.0914"/>
    <parent link="rear_right_base_link"/>
    <child link="rear_right_LR_link_8"/>
    <axis xyz="0 -1 0"/>
  </joint>
  <gazebo reference="rear_right_LR_link_8">
    <material>Gazebo/DarkGrey</material>
    <surface>
      <friction>
        <ode>
          <mu>1.0</mu>
          <mu2>0.1</mu2>
        </ode>
      </friction>
    </surface>
  </gazebo>
  <link name="rear_right_LR_link_9">
    <inertial>
      <origin rpy="0 0 0" xyz="0 0 0"/>
      <mass value="0.0343"/>
      <inertia ixx="0.00001147" ixy="0" ixz="0" iyy="0.000001312" iyz="0" izz="0.00001147"/>
    </inertial>
    <visual>
      <origin rpy="0 0 0" xyz="0 0 0"/>
      <geometry>
        <mesh filename="file:///home/imbatman/smdw_ws/src/left_smdw/meshes/FL_LR_link_9.STL"/>
      </geometry>
      <material name="rear_right_base_color"/>
    </visual>
    <collision>
      <origin rpy="0 0 0" xyz="0 0 0"/>
      <geometry>
        <mesh filename="file:///home/imbatman/smdw_ws/src/left_smdw/meshes/FL_LR_link_9.STL"/>
      </geometry>
    </collision>
  </link>
  <joint name="rear_right_LR_joint_9" type="continuous">
    <origin rpy="2.8567 -0.2740 -2.3166" xyz="-0.0350 0.0279 -0.0845"/>
    <parent link="rear_right_base_link"/>
    <child link="rear_right_LR_link_9"/>
    <axis xyz="0 -1 0"/>
  </joint>
  <gazebo reference="rear_right_LR_link_9">
    <material>Gazebo/DarkGrey</material>
    <surface>
      <friction>
        <ode>
          <mu>1.0</mu>
          <mu2>0.1</mu2>
        </ode>
      </friction>
    </surface>
  </gazebo>
  <link name="rear_right_LR_link_10">
    <inertial>
      <origin rpy="0 0 0" xyz="0 0 0"/>
      <mass value="0.0343"/>
      <inertia ixx="0.00001147" ixy="0" ixz="0" iyy="0.000001312" iyz="0" izz="0.00001147"/>
    </inertial>
    <visual>
      <origin rpy="0 0 0" xyz="0 0 0"/>
      <geometry>
        <mesh filename="file:///home/imbatman/smdw_ws/src/left_smdw/meshes/FL_LR_link_10.STL"/>
      </geometry>
      <material name="rear_right_base_color"/>
    </visual>
    <collision>
      <origin rpy="0 0 0" xyz="0 0 0"/>
      <geometry>
        <mesh filename="file:///home/imbatman/smdw_ws/src/left_smdw/meshes/FL_LR_link_10.STL"/>
      </geometry>
    </collision>
  </link>
  <joint name="rear_right_LR_joint_10" type="continuous">
    <origin rpy="2.5261 -0.5236 -2.1863" xyz="-0.0647 0.0279 -0.0647"/>
    <parent link="rear_right_base_link"/>
    <child link="rear_right_LR_link_10"/>
    <axis xyz="0 -1 0"/>
  </joint>
  <gazebo reference="rear_right_LR_link_10">
    <material>Gazebo/DarkGrey</material>
    <surface>
      <friction>
        <ode>
          <mu>1.0</mu>
          <mu2>0.1</mu2>
        </ode>
      </friction>
    </surface>
  </gazebo>
  <link name="rear_right_LR_link_11">
    <inertial>
      <origin rpy="0 0 0" xyz="0 0 0"/>
      <mass value="0.0343"/>
      <inertia ixx="0.00001147" ixy="0" ixz="0" iyy="0.000001312" iyz="0" izz="0.00001147"/>
    </inertial>
    <visual>
      <origin rpy="0 0 0" xyz="0 0 0"/>
      <geometry>
        <mesh filename="file:///home/imbatman/smdw_ws/src/left_smdw/meshes/FL_LR_link_11.STL"/>
      </geometry>
      <material name="rear_right_base_color"/>
    </visual>
    <collision>
      <origin rpy="0 0 0" xyz="0 0 0"/>
      <geometry>
        <mesh filename="file:///home/imbatman/smdw_ws/src/left_smdw/meshes/FL_LR_link_11.STL"/>
      </geometry>
    </collision>
  </link>
  <joint name="rear_right_LR_joint_11" type="continuous">
    <origin rpy="2.1007 -0.7119 -1.9363" xyz="-0.0845 0.0279 -0.0350"/>
    <parent link="rear_right_base_link"/>
    <child link="rear_right_LR_link_11"/>
    <axis xyz="0 -1 0"/>
  </joint>
  <gazebo reference="rear_right_LR_link_11">
    <material>Gazebo/DarkGrey</material>
    <surface>
      <friction>
        <ode>
          <mu>1.0</mu>
          <mu2>0.1</mu2>
        </ode>
      </friction>
    </surface>
  </gazebo>
  <link name="rear_right_LR_link_12">
    <inertial>
      <origin rpy="0 0 0" xyz="0 0 0"/>
      <mass value="0.0343"/>
      <inertia ixx="0.00001147" ixy="0" ixz="0" iyy="0.000001312" iyz="0" izz="0.00001147"/>
    </inertial>
    <visual>
      <origin rpy="0 0 0" xyz="0 0 0"/>
      <geometry>
        <mesh filename="file:///home/imbatman/smdw_ws/src/left_smdw/meshes/FL_LR_link_12.STL"/>
      </geometry>
      <material name="rear_right_base_color"/>
    </visual>
    <collision>
      <origin rpy="0 0 0" xyz="0 0 0"/>
      <geometry>
        <mesh filename="file:///home/imbatman/smdw_ws/src/left_smdw/meshes/FL_LR_link_12.STL"/>
      </geometry>
    </collision>
  </link>
  <joint name="rear_right_LR_joint_12" type="continuous">
    <origin rpy="1.5708 -0.7854 -1.5708" xyz="-0.0914 0.0279 0.0000"/>
    <parent link="rear_right_base_link"/>
    <child link="rear_right_LR_link_12"/>
    <axis xyz="0 -1 0"/>
  </joint>
  <gazebo reference="rear_right_LR_link_12">
    <material>Gazebo/DarkGrey</material>
    <surface>
      <friction>
        <ode>
          <mu>1.0</mu>
          <mu2>0.1</mu2>
        </ode>
      </friction>
    </surface>
  </gazebo>
  <link name="rear_right_LR_link_13">
    <inertial>
      <origin rpy="0 0 0" xyz="0 0 0"/>
      <mass value="0.0343"/>
      <inertia ixx="0.00001147" ixy="0" ixz="0" iyy="0.000001312" iyz="0" izz="0.00001147"/>
    </inertial>
    <visual>
      <origin rpy="0 0 0" xyz="0 0 0"/>
      <geometry>
        <mesh filename="file:///home/imbatman/smdw_ws/src/left_smdw/meshes/FL_LR_link_13.STL"/>
      </geometry>
      <material name="rear_right_base_color"/>
    </visual>
    <collision>
      <origin rpy="0 0 0" xyz="0 0 0"/>
      <geometry>
        <mesh filename="file:///home/imbatman/smdw_ws/src/left_smdw/meshes/FL_LR_link_13.STL"/>
      </geometry>
    </collision>
  </link>
  <joint name="rear_right_LR_joint_13" type="continuous">
    <origin rpy="0.4107 -0.3798 -0.8654" xyz="-0.0671 0.0279 0.0370"/>
    <parent link="rear_right_base_link"/>
    <child link="rear_right_LR_link_13"/>
    <axis xyz="0 -1 0"/>
  </joint>
  <gazebo reference="rear_right_LR_link_13">
    <material>Gazebo/DarkGrey</material>
    <surface>
      <friction>
        <ode>
          <mu>1.0</mu>
          <mu2>0.1</mu2>
        </ode>
      </friction>
    </surface>
  </gazebo>
  <link name="rear_right_LR_link_14">
    <inertial>
      <origin rpy="0 0 0" xyz="0 0 0"/>
      <mass value="0.0343"/>
      <inertia ixx="0.00001147" ixy="0" ixz="0" iyy="0.000001312" iyz="0" izz="0.00001147"/>
    </inertial>
    <visual>
      <origin rpy="0 0 0" xyz="0 0 0"/>
      <geometry>
        <mesh filename="file:///home/imbatman/smdw_ws/src/left_smdw/meshes/FL_LR_link_14.STL"/>
      </geometry>
      <material name="rear_right_base_color"/>
    </visual>
    <collision>
      <origin rpy="0 0 0" xyz="0 0 0"/>
      <geometry>
        <mesh filename="file:///home/imbatman/smdw_ws/src/left_smdw/meshes/FL_LR_link_14.STL"/>
      </geometry>
    </collision>
  </link>
  <joint name="rear_right_LR_joint_14" type="continuous">
    <origin rpy="0.1534 -0.1517 -0.7971" xyz="-0.0338 0.0279 0.0498"/>
    <parent link="rear_right_base_link"/>
    <child link="rear_right_LR_link_14"/>
    <axis xyz="0 -1 0"/>
  </joint>
  <gazebo reference="rear_right_LR_link_14">
    <material>Gazebo/DarkGrey</material>
    <surface>
      <friction>
        <ode>
          <mu>1.0</mu>
          <mu2>0.1</mu2>
        </ode>
      </friction>
    </surface>
  </gazebo>
  <!-- Define materials -->
  <material name="front_right_base_color">
    <color rgba="0.79216 0.81961 0.93333 1"/>
  </material>
  <material name="front_right_wheel_color">
    <color rgba="0.25098 0.25098 0.25098 1"/>
  </material>
  <!-- Base link -->
  <link name="front_right_base_link">
    <inertial>
      <origin rpy="0 0 0" xyz="-4.3311E-18 1.504E-12 1.7857E-18"/>
      <mass value="1.9429"/>
      <inertia ixx="0.0019245" ixy="8.1609E-21" ixz="-8.1689E-08" iyy="0.0049239" iyz="-7.5092E-20" izz="0.0032216"/>
    </inertial>
    <visual>
      <origin rpy="0 0 0" xyz="0 0 0"/>
      <geometry>
        <mesh filename="file:///home/imbatman/smdw_ws/src/right_smdw/meshes/front_right_wheel_base_link.STL"/>
      </geometry>
      <material name="front_right_wheel_color"/>
    </visual>
    <collision>
      <origin rpy="0 0 0" xyz="0 0 0"/>
      <geometry>
        <mesh filename="file:///home/imbatman/smdw_ws/src/right_smdw/meshes/front_right_wheel_base_link.STL"/>
      </geometry>
    </collision>
  </link>
  <link name="front_right_RR_link_1">
    <inertial>
      <origin rpy="0 0 0" xyz="0 0 0"/>
      <mass value="0.0343"/>
      <inertia ixx="0.00001147" ixy="0" ixz="0" iyy="0.000001312" iyz="0" izz="0.00001147"/>
    </inertial>
    <visual>
      <origin rpy="0 0 0" xyz="0 0 0"/>
      <geometry>
        <mesh filename="file:///home/imbatman/smdw_ws/src/right_smdw/meshes/FR_RR_link_1.STL"/>
      </geometry>
      <material name="front_right_base_color"/>
    </visual>
    <collision>
      <origin rpy="0 0 0" xyz="0 0 0"/>
      <geometry>
        <mesh filename="file:///home/imbatman/smdw_ws/src/right_smdw/meshes/FR_RR_link_1.STL"/>
      </geometry>
    </collision>
  </link>
  <joint name="front_right_RR_joint_1" type="continuous">
    <origin rpy="0.0000 0.0000 0.7854" xyz="0.0000 -0.0279 0.0533"/>
    <parent link="front_right_base_link"/>
    <child link="front_right_RR_link_1"/>
    <axis xyz="0 -1 0"/>
  </joint>
  <gazebo reference="front_right_RR_link_1">
    <material>Gazebo/DarkGrey</material>
    <surface>
      <friction>
        <ode>
          <mu>1.0</mu>
          <mu2>0.1</mu2>
        </ode>
      </friction>
    </surface>
  </gazebo>
  <link name="front_right_RR_link_2">
    <inertial>
      <origin rpy="0 0 0" xyz="0 0 0"/>
      <mass value="0.0343"/>
      <inertia ixx="0.00001147" ixy="0" ixz="0" iyy="0.000001312" iyz="0" izz="0.00001147"/>
    </inertial>
    <visual>
      <origin rpy="0 0 0" xyz="0 0 0"/>
      <geometry>
        <mesh filename="file:///home/imbatman/smdw_ws/src/right_smdw/meshes/FR_RR_link_2.STL"/>
      </geometry>
      <material name="front_right_base_color"/>
    </visual>
    <collision>
      <origin rpy="0 0 0" xyz="0 0 0"/>
      <geometry>
        <mesh filename="file:///home/imbatman/smdw_ws/src/right_smdw/meshes/FR_RR_link_2.STL"/>
      </geometry>
    </collision>
  </link>
  <joint name="front_right_RR_joint_2" type="continuous">
    <origin rpy="0.1534 0.1516 0.7971" xyz="0.0338 -0.0279 0.0498"/>
    <parent link="front_right_base_link"/>
    <child link="front_right_RR_link_2"/>
    <axis xyz="0 -1 0"/>
  </joint>
  <gazebo reference="front_right_RR_link_2">
    <material>Gazebo/DarkGrey</material>
    <surface>
      <friction>
        <ode>
          <mu>1.0</mu>
          <mu2>0.1</mu2>
        </ode>
      </friction>
    </surface>
  </gazebo>
  <link name="front_right_RR_link_3">
    <inertial>
      <origin rpy="0 0 0" xyz="0 0 0"/>
      <mass value="0.0343"/>
      <inertia ixx="0.00001147" ixy="0" ixz="0" iyy="0.000001312" iyz="0" izz="0.00001147"/>
    </inertial>
    <visual>
      <origin rpy="0 0 0" xyz="0 0 0"/>
      <geometry>
        <mesh filename="file:///home/imbatman/smdw_ws/src/right_smdw/meshes/FR_RR_link_3.STL"/>
      </geometry>
      <material name="front_right_base_color"/>
    </visual>
    <collision>
      <origin rpy="0 0 0" xyz="0 0 0"/>
      <geometry>
        <mesh filename="file:///home/imbatman/smdw_ws/src/right_smdw/meshes/FR_RR_link_3.STL"/>
      </geometry>
    </collision>
  </link>
  <joint name="front_right_RR_joint_3" type="continuous">
    <origin rpy="0.4107 0.3798 0.8654" xyz="0.0671 -0.0279 0.0370"/>
    <parent link="front_right_base_link"/>
    <child link="front_right_RR_link_3"/>
    <axis xyz="0 -1 0"/>
  </joint>
  <gazebo reference="front_right_RR_link_3">
    <material>Gazebo/DarkGrey</material>
    <surface>
      <friction>
        <ode>
          <mu>1.0</mu>
          <mu2>0.1</mu2>
        </ode>
      </friction>
    </surface>
  </gazebo>
  <link name="front_right_RR_link_4">
    <inertial>
      <origin rpy="0 0 0" xyz="0 0 0"/>
      <mass value="0.0343"/>
      <inertia ixx="0.00001147" ixy="0" ixz="0" iyy="0.000001312" iyz="0" izz="0.00001147"/>
    </inertial>
    <visual>
      <origin rpy="0 0 0" xyz="0 0 0"/>
      <geometry>
        <mesh filename="file:///home/imbatman/smdw_ws/src/right_smdw/meshes/FR_RR_link_4.STL"/>
      </geometry>
      <material name="front_right_base_color"/>
    </visual>
    <collision>
      <origin rpy="0 0 0" xyz="0 0 0"/>
      <geometry>
        <mesh filename="file:///home/imbatman/smdw_ws/src/right_smdw/meshes/FR_RR_link_4.STL"/>
      </geometry>
    </collision>
  </link>
  <joint name="front_right_RR_joint_4" type="continuous">
    <origin rpy="1.5708 0.7854 1.5708" xyz="0.0914 -0.0279 0.0000"/>
    <parent link="front_right_base_link"/>
    <child link="front_right_RR_link_4"/>
    <axis xyz="0 -1 0"/>
  </joint>
  <gazebo reference="front_right_RR_link_4">
    <material>Gazebo/DarkGrey</material>
    <surface>
      <friction>
        <ode>
          <mu>1.0</mu>
          <mu2>0.1</mu2>
        </ode>
      </friction>
    </surface>
  </gazebo>
  <link name="front_right_RR_link_5">
    <inertial>
      <origin rpy="0 0 0" xyz="0 0 0"/>
      <mass value="0.0343"/>
      <inertia ixx="0.00001147" ixy="0" ixz="0" iyy="0.000001312" iyz="0" izz="0.00001147"/>
    </inertial>
    <visual>
      <origin rpy="0 0 0" xyz="0 0 0"/>
      <geometry>
        <mesh filename="file:///home/imbatman/smdw_ws/src/right_smdw/meshes/FR_RR_link_5.STL"/>
      </geometry>
      <material name="front_right_base_color"/>
    </visual>
    <collision>
      <origin rpy="0 0 0" xyz="0 0 0"/>
      <geometry>
        <mesh filename="file:///home/imbatman/smdw_ws/src/right_smdw/meshes/FR_RR_link_5.STL"/>
      </geometry>
    </collision>
  </link>
  <joint name="front_right_RR_joint_5" type="continuous">
    <origin rpy="2.1007 0.7119 1.9363" xyz="0.0845 -0.0279 -0.0350"/>
    <parent link="front_right_base_link"/>
    <child link="front_right_RR_link_5"/>
    <axis xyz="0 -1 0"/>
  </joint>
  <gazebo reference="front_right_RR_link_5">
    <material>Gazebo/DarkGrey</material>
    <surface>
      <friction>
        <ode>
          <mu>1.0</mu>
          <mu2>0.1</mu2>
        </ode>
      </friction>
    </surface>
  </gazebo>
  <link name="front_right_RR_link_6">
    <inertial>
      <origin rpy="0 0 0" xyz="0 0 0"/>
      <mass value="0.0343"/>
      <inertia ixx="0.00001147" ixy="0" ixz="0" iyy="0.000001312" iyz="0" izz="0.00001147"/>
    </inertial>
    <visual>
      <origin rpy="0 0 0" xyz="0 0 0"/>
      <geometry>
        <mesh filename="file:///home/imbatman/smdw_ws/src/right_smdw/meshes/FR_RR_link_6.STL"/>
      </geometry>
      <material name="front_right_base_color"/>
    </visual>
    <collision>
      <origin rpy="0 0 0" xyz="0 0 0"/>
      <geometry>
        <mesh filename="file:///home/imbatman/smdw_ws/src/right_smdw/meshes/FR_RR_link_6.STL"/>
      </geometry>
    </collision>
  </link>
  <joint name="front_right_RR_joint_6" type="continuous">
    <origin rpy="2.5261 0.5236 2.1863" xyz="0.0647 -0.0279 -0.0647"/>
    <parent link="front_right_base_link"/>
    <child link="front_right_RR_link_6"/>
    <axis xyz="0 -1 0"/>
  </joint>
  <gazebo reference="front_right_RR_link_6">
    <material>Gazebo/DarkGrey</material>
    <surface>
      <friction>
        <ode>
          <mu>1.0</mu>
          <mu2>0.1</mu2>
        </ode>
      </friction>
    </surface>
  </gazebo>
  <link name="front_right_RR_link_7">
    <inertial>
      <origin rpy="0 0 0" xyz="0 0 0"/>
      <mass value="0.0343"/>
      <inertia ixx="0.00001147" ixy="0" ixz="0" iyy="0.000001312" iyz="0" izz="0.00001147"/>
    </inertial>
    <visual>
      <origin rpy="0 0 0" xyz="0 0 0"/>
      <geometry>
        <mesh filename="file:///home/imbatman/smdw_ws/src/right_smdw/meshes/FR_RR_link_7.STL"/>
      </geometry>
      <material name="front_right_base_color"/>
    </visual>
    <collision>
      <origin rpy="0 0 0" xyz="0 0 0"/>
      <geometry>
        <mesh filename="file:///home/imbatman/smdw_ws/src/right_smdw/meshes/FR_RR_link_7.STL"/>
      </geometry>
    </collision>
  </link>
  <joint name="front_right_RR_joint_7" type="continuous">
    <origin rpy="2.8567 0.2740 2.3166" xyz="0.0350 -0.0279 -0.0845"/>
    <parent link="front_right_base_link"/>
    <child link="front_right_RR_link_7"/>
    <axis xyz="0 -1 0"/>
  </joint>
  <gazebo reference="front_right_RR_link_7">
    <material>Gazebo/DarkGrey</material>
    <surface>
      <friction>
        <ode>
          <mu>1.0</mu>
          <mu2>0.1</mu2>
        </ode>
      </friction>
    </surface>
  </gazebo>
  <link name="front_right_RR_link_8">
    <inertial>
      <origin rpy="0 0 0" xyz="0 0 0"/>
      <mass value="0.0343"/>
      <inertia ixx="0.00001147" ixy="0" ixz="0" iyy="0.000001312" iyz="0" izz="0.00001147"/>
    </inertial>
    <visual>
      <origin rpy="0 0 0" xyz="0 0 0"/>
      <geometry>
        <mesh filename="file:///home/imbatman/smdw_ws/src/right_smdw/meshes/FR_RR_link_8.STL"/>
      </geometry>
      <material name="front_right_base_color"/>
    </visual>
    <collision>
      <origin rpy="0 0 0" xyz="0 0 0"/>
      <geometry>
        <mesh filename="file:///home/imbatman/smdw_ws/src/right_smdw/meshes/FR_RR_link_8.STL"/>
      </geometry>
    </collision>
  </link>
  <joint name="front_right_RR_joint_8" type="continuous">
    <origin rpy="3.1416 0.0000 2.3562" xyz="0.0000 -0.0279 -0.0914"/>
    <parent link="front_right_base_link"/>
    <child link="front_right_RR_link_8"/>
    <axis xyz="0 -1 0"/>
  </joint>
  <gazebo reference="front_right_RR_link_8">
    <material>Gazebo/DarkGrey</material>
    <surface>
      <friction>
        <ode>
          <mu>1.0</mu>
          <mu2>0.1</mu2>
        </ode>
      </friction>
    </surface>
  </gazebo>
  <link name="front_right_RR_link_9">
    <inertial>
      <origin rpy="0 0 0" xyz="0 0 0"/>
      <mass value="0.0343"/>
      <inertia ixx="0.00001147" ixy="0" ixz="0" iyy="0.000001312" iyz="0" izz="0.00001147"/>
    </inertial>
    <visual>
      <origin rpy="0 0 0" xyz="0 0 0"/>
      <geometry>
        <mesh filename="file:///home/imbatman/smdw_ws/src/right_smdw/meshes/FR_RR_link_9.STL"/>
      </geometry>
      <material name="front_right_base_color"/>
    </visual>
    <collision>
      <origin rpy="0 0 0" xyz="0 0 0"/>
      <geometry>
        <mesh filename="file:///home/imbatman/smdw_ws/src/right_smdw/meshes/FR_RR_link_9.STL"/>
      </geometry>
    </collision>
  </link>
  <joint name="front_right_RR_joint_9" type="continuous">
    <origin rpy="-2.8567 -0.2740 2.3166" xyz="-0.0350 -0.0279 -0.0845"/>
    <parent link="front_right_base_link"/>
    <child link="front_right_RR_link_9"/>
    <axis xyz="0 -1 0"/>
  </joint>
  <gazebo reference="front_right_RR_link_9">
    <material>Gazebo/DarkGrey</material>
    <surface>
      <friction>
        <ode>
          <mu>1.0</mu>
          <mu2>0.1</mu2>
        </ode>
      </friction>
    </surface>
  </gazebo>
  <link name="front_right_RR_link_10">
    <inertial>
      <origin rpy="0 0 0" xyz="0 0 0"/>
      <mass value="0.0343"/>
      <inertia ixx="0.00001147" ixy="0" ixz="0" iyy="0.000001312" iyz="0" izz="0.00001147"/>
    </inertial>
    <visual>
      <origin rpy="0 0 0" xyz="0 0 0"/>
      <geometry>
        <mesh filename="file:///home/imbatman/smdw_ws/src/right_smdw/meshes/FR_RR_link_10.STL"/>
      </geometry>
      <material name="front_right_base_color"/>
    </visual>
    <collision>
      <origin rpy="0 0 0" xyz="0 0 0"/>
      <geometry>
        <mesh filename="file:///home/imbatman/smdw_ws/src/right_smdw/meshes/FR_RR_link_10.STL"/>
      </geometry>
    </collision>
  </link>
  <joint name="front_right_RR_joint_10" type="continuous">
    <origin rpy="-2.5261 -0.5236 2.1863" xyz="-0.0647 -0.0279 -0.0647"/>
    <parent link="front_right_base_link"/>
    <child link="front_right_RR_link_10"/>
    <axis xyz="0 -1 0"/>
  </joint>
  <gazebo reference="front_right_RR_link_10">
    <material>Gazebo/DarkGrey</material>
    <surface>
      <friction>
        <ode>
          <mu>1.0</mu>
          <mu2>0.1</mu2>
        </ode>
      </friction>
    </surface>
  </gazebo>
  <link name="front_right_RR_link_11">
    <inertial>
      <origin rpy="0 0 0" xyz="0 0 0"/>
      <mass value="0.0343"/>
      <inertia ixx="0.00001147" ixy="0" ixz="0" iyy="0.000001312" iyz="0" izz="0.00001147"/>
    </inertial>
    <visual>
      <origin rpy="0 0 0" xyz="0 0 0"/>
      <geometry>
        <mesh filename="file:///home/imbatman/smdw_ws/src/right_smdw/meshes/FR_RR_link_11.STL"/>
      </geometry>
      <material name="front_right_base_color"/>
    </visual>
    <collision>
      <origin rpy="0 0 0" xyz="0 0 0"/>
      <geometry>
        <mesh filename="file:///home/imbatman/smdw_ws/src/right_smdw/meshes/FR_RR_link_11.STL"/>
      </geometry>
    </collision>
  </link>
  <joint name="front_right_RR_joint_11" type="continuous">
    <origin rpy="-2.1007 -0.7119 1.9363" xyz="-0.0845 -0.0279 -0.0350"/>
    <parent link="front_right_base_link"/>
    <child link="front_right_RR_link_11"/>
    <axis xyz="0 -1 0"/>
  </joint>
  <gazebo reference="front_right_RR_link_11">
    <material>Gazebo/DarkGrey</material>
    <surface>
      <friction>
        <ode>
          <mu>1.0</mu>
          <mu2>0.1</mu2>
        </ode>
      </friction>
    </surface>
  </gazebo>
  <link name="front_right_RR_link_12">
    <inertial>
      <origin rpy="0 0 0" xyz="0 0 0"/>
      <mass value="0.0343"/>
      <inertia ixx="0.00001147" ixy="0" ixz="0" iyy="0.000001312" iyz="0" izz="0.00001147"/>
    </inertial>
    <visual>
      <origin rpy="0 0 0" xyz="0 0 0"/>
      <geometry>
        <mesh filename="file:///home/imbatman/smdw_ws/src/right_smdw/meshes/FR_RR_link_12.STL"/>
      </geometry>
      <material name="front_right_base_color"/>
    </visual>
    <collision>
      <origin rpy="0 0 0" xyz="0 0 0"/>
      <geometry>
        <mesh filename="file:///home/imbatman/smdw_ws/src/right_smdw/meshes/FR_RR_link_12.STL"/>
      </geometry>
    </collision>
  </link>
  <joint name="front_right_RR_joint_12" type="continuous">
    <origin rpy="-1.5708 -0.7854 1.5708" xyz="-0.0914 -0.0279 0.0000"/>
    <parent link="front_right_base_link"/>
    <child link="front_right_RR_link_12"/>
    <axis xyz="0 -1 0"/>
  </joint>
  <gazebo reference="front_right_RR_link_12">
    <material>Gazebo/DarkGrey</material>
    <surface>
      <friction>
        <ode>
          <mu>1.0</mu>
          <mu2>0.1</mu2>
        </ode>
      </friction>
    </surface>
  </gazebo>
  <link name="front_right_RR_link_13">
    <inertial>
      <origin rpy="0 0 0" xyz="0 0 0"/>
      <mass value="0.0343"/>
      <inertia ixx="0.00001147" ixy="0" ixz="0" iyy="0.000001312" iyz="0" izz="0.00001147"/>
    </inertial>
    <visual>
      <origin rpy="0 0 0" xyz="0 0 0"/>
      <geometry>
        <mesh filename="file:///home/imbatman/smdw_ws/src/right_smdw/meshes/FR_RR_link_13.STL"/>
      </geometry>
      <material name="front_right_base_color"/>
    </visual>
    <collision>
      <origin rpy="0 0 0" xyz="0 0 0"/>
      <geometry>
        <mesh filename="file:///home/imbatman/smdw_ws/src/right_smdw/meshes/FR_RR_link_13.STL"/>
      </geometry>
    </collision>
  </link>
  <joint name="front_right_RR_joint_13" type="continuous">
    <origin rpy="-0.4107 -0.3798 0.8654" xyz="-0.0671 -0.0279 0.0370"/>
    <parent link="front_right_base_link"/>
    <child link="front_right_RR_link_13"/>
    <axis xyz="0 -1 0"/>
  </joint>
  <gazebo reference="front_right_RR_link_13">
    <material>Gazebo/DarkGrey</material>
    <surface>
      <friction>
        <ode>
          <mu>1.0</mu>
          <mu2>0.1</mu2>
        </ode>
      </friction>
    </surface>
  </gazebo>
  <link name="front_right_RR_link_14">
    <inertial>
      <origin rpy="0 0 0" xyz="0 0 0"/>
      <mass value="0.0343"/>
      <inertia ixx="0.00001147" ixy="0" ixz="0" iyy="0.000001312" iyz="0" izz="0.00001147"/>
    </inertial>
    <visual>
      <origin rpy="0 0 0" xyz="0 0 0"/>
      <geometry>
        <mesh filename="file:///home/imbatman/smdw_ws/src/right_smdw/meshes/FR_RR_link_14.STL"/>
      </geometry>
      <material name="front_right_base_color"/>
    </visual>
    <collision>
      <origin rpy="0 0 0" xyz="0 0 0"/>
      <geometry>
        <mesh filename="file:///home/imbatman/smdw_ws/src/right_smdw/meshes/FR_RR_link_14.STL"/>
      </geometry>
    </collision>
  </link>
  <joint name="front_right_RR_joint_14" type="continuous">
    <origin rpy="-0.1534 -0.1516 0.7971" xyz="-0.0338 -0.0279 0.0498"/>
    <parent link="front_right_base_link"/>
    <child link="front_right_RR_link_14"/>
    <axis xyz="0 -1 0"/>
  </joint>
  <gazebo reference="front_right_RR_link_14">
    <material>Gazebo/DarkGrey</material>
    <surface>
      <friction>
        <ode>
          <mu>1.0</mu>
          <mu2>0.1</mu2>
        </ode>
      </friction>
    </surface>
  </gazebo>
  <link name="front_right_LR_link_1">
    <inertial>
      <origin rpy="0 0 0" xyz="0 0 0"/>
      <mass value="0.0343"/>
      <inertia ixx="0.00001147" ixy="0" ixz="0" iyy="0.000001312" iyz="0" izz="0.00001147"/>
    </inertial>
    <visual>
      <origin rpy="0 0 0" xyz="0 0 0"/>
      <geometry>
        <mesh filename="file:///home/imbatman/smdw_ws/src/right_smdw/meshes/FR_LR_link_1.STL"/>
      </geometry>
      <material name="front_right_base_color"/>
    </visual>
    <collision>
      <origin rpy="0 0 0" xyz="0 0 0"/>
      <geometry>
        <mesh filename="file:///home/imbatman/smdw_ws/src/right_smdw/meshes/FR_LR_link_1.STL"/>
      </geometry>
    </collision>
  </link>
  <joint name="front_right_LR_joint_1" type="continuous">
    <origin rpy="0.0000 0.0000 0.7854" xyz="0.0000 0.0279 0.0914"/>
    <parent link="front_right_base_link"/>
    <child link="front_right_LR_link_1"/>
    <axis xyz="0 -1 0"/>
  </joint>
  <gazebo reference="front_right_LR_link_1">
    <material>Gazebo/DarkGrey</material>
    <surface>
      <friction>
        <ode>
          <mu>1.0</mu>
          <mu2>0.1</mu2>
        </ode>
      </friction>
    </surface>
  </gazebo>
  <link name="front_right_LR_link_2">
    <inertial>
      <origin rpy="0 0 0" xyz="0 0 0"/>
      <mass value="0.0343"/>
      <inertia ixx="0.00001147" ixy="0" ixz="0" iyy="0.000001312" iyz="0" izz="0.00001147"/>
    </inertial>
    <visual>
      <origin rpy="0 0 0" xyz="0 0 0"/>
      <geometry>
        <mesh filename="file:///home/imbatman/smdw_ws/src/right_smdw/meshes/FR_LR_link_2.STL"/>
      </geometry>
      <material name="front_right_base_color"/>
    </visual>
    <collision>
      <origin rpy="0 0 0" xyz="0 0 0"/>
      <geometry>
        <mesh filename="file:///home/imbatman/smdw_ws/src/right_smdw/meshes/FR_LR_link_2.STL"/>
      </geometry>
    </collision>
  </link>
  <joint name="front_right_LR_joint_2" type="continuous">
    <origin rpy="0.2849 0.2740 0.8249" xyz="0.0350 0.0279 0.0845"/>
    <parent link="front_right_base_link"/>
    <child link="front_right_LR_link_2"/>
    <axis xyz="0 -1 0"/>
  </joint>
  <gazebo reference="front_right_LR_link_2">
    <material>Gazebo/DarkGrey</material>
    <surface>
      <friction>
        <ode>
          <mu>1.0</mu>
          <mu2>0.1</mu2>
        </ode>
      </friction>
    </surface>
  </gazebo>
  <link name="front_right_LR_link_3">
    <inertial>
      <origin rpy="0 0 0" xyz="0 0 0"/>
      <mass value="0.0343"/>
      <inertia ixx="0.00001147" ixy="0" ixz="0" iyy="0.000001312" iyz="0" izz="0.00001147"/>
    </inertial>
    <visual>
      <origin rpy="0 0 0" xyz="0 0 0"/>
      <geometry>
        <mesh filename="file:///home/imbatman/smdw_ws/src/right_smdw/meshes/FR_LR_link_3.STL"/>
      </geometry>
      <material name="front_right_base_color"/>
    </visual>
    <collision>
      <origin rpy="0 0 0" xyz="0 0 0"/>
      <geometry>
        <mesh filename="file:///home/imbatman/smdw_ws/src/right_smdw/meshes/FR_LR_link_3.STL"/>
      </geometry>
    </collision>
  </link>
  <joint name="front_right_LR_joint_3" type="continuous">
    <origin rpy="0.6155 0.5236 0.9553" xyz="0.0647 0.0279 0.0647"/>
    <parent link="front_right_base_link"/>
    <child link="front_right_LR_link_3"/>
    <axis xyz="0 -1 0"/>
  </joint>
  <gazebo reference="front_right_LR_link_3">
    <material>Gazebo/DarkGrey</material>
    <surface>
      <friction>
        <ode>
          <mu>1.0</mu>
          <mu2>0.1</mu2>
        </ode>
      </friction>
    </surface>
  </gazebo>
  <link name="front_right_LR_link_4">
    <inertial>
      <origin rpy="0 0 0" xyz="0 0 0"/>
      <mass value="0.0343"/>
      <inertia ixx="0.00001147" ixy="0" ixz="0" iyy="0.000001312" iyz="0" izz="0.00001147"/>
    </inertial>
    <visual>
      <origin rpy="0 0 0" xyz="0 0 0"/>
      <geometry>
        <mesh filename="file:///home/imbatman/smdw_ws/src/right_smdw/meshes/FR_LR_link_4.STL"/>
      </geometry>
      <material name="front_right_base_color"/>
    </visual>
    <collision>
      <origin rpy="0 0 0" xyz="0 0 0"/>
      <geometry>
        <mesh filename="file:///home/imbatman/smdw_ws/src/right_smdw/meshes/FR_LR_link_4.STL"/>
      </geometry>
    </collision>
  </link>
  <joint name="front_right_LR_joint_4" type="continuous">
    <origin rpy="1.0409 0.7119 1.2053" xyz="0.0845 0.0279 0.0350"/>
    <parent link="front_right_base_link"/>
    <child link="front_right_LR_link_4"/>
    <axis xyz="0 -1 0"/>
  </joint>
  <gazebo reference="front_right_LR_link_4">
    <material>Gazebo/DarkGrey</material>
    <surface>
      <friction>
        <ode>
          <mu>1.0</mu>
          <mu2>0.1</mu2>
        </ode>
      </friction>
    </surface>
  </gazebo>
  <link name="front_right_LR_link_5">
    <inertial>
      <origin rpy="0 0 0" xyz="0 0 0"/>
      <mass value="0.0343"/>
      <inertia ixx="0.00001147" ixy="0" ixz="0" iyy="0.000001312" iyz="0" izz="0.00001147"/>
    </inertial>
    <visual>
      <origin rpy="0 0 0" xyz="0 0 0"/>
      <geometry>
        <mesh filename="file:///home/imbatman/smdw_ws/src/right_smdw/meshes/FR_LR_link_5.STL"/>
      </geometry>
      <material name="front_right_base_color"/>
    </visual>
    <collision>
      <origin rpy="0 0 0" xyz="0 0 0"/>
      <geometry>
        <mesh filename="file:///home/imbatman/smdw_ws/src/right_smdw/meshes/FR_LR_link_5.STL"/>
      </geometry>
    </collision>
  </link>
  <joint name="front_right_LR_joint_5" type="continuous">
    <origin rpy="1.5708 0.7854 1.5708" xyz="0.0914 0.0279 0.0000"/>
    <parent link="front_right_base_link"/>
    <child link="front_right_LR_link_5"/>
    <axis xyz="0 -1 0"/>
  </joint>
  <gazebo reference="front_right_LR_link_5">
    <material>Gazebo/DarkGrey</material>
    <surface>
      <friction>
        <ode>
          <mu>1.0</mu>
          <mu2>0.1</mu2>
        </ode>
      </friction>
    </surface>
  </gazebo>
  <link name="front_right_LR_link_6">
    <inertial>
      <origin rpy="0 0 0" xyz="0 0 0"/>
      <mass value="0.0343"/>
      <inertia ixx="0.00001147" ixy="0" ixz="0" iyy="0.000001312" iyz="0" izz="0.00001147"/>
    </inertial>
    <visual>
      <origin rpy="0 0 0" xyz="0 0 0"/>
      <geometry>
        <mesh filename="file:///home/imbatman/smdw_ws/src/right_smdw/meshes/FR_LR_link_6.STL"/>
      </geometry>
      <material name="front_right_base_color"/>
    </visual>
    <collision>
      <origin rpy="0 0 0" xyz="0 0 0"/>
      <geometry>
        <mesh filename="file:///home/imbatman/smdw_ws/src/right_smdw/meshes/FR_LR_link_6.STL"/>
      </geometry>
    </collision>
  </link>
  <joint name="front_right_LR_joint_6" type="continuous">
    <origin rpy="2.7309 0.3798 2.2762" xyz="0.0671 0.0279 -0.0370"/>
    <parent link="front_right_base_link"/>
    <child link="front_right_LR_link_6"/>
    <axis xyz="0 -1 0"/>
  </joint>
  <gazebo reference="front_right_LR_link_6">
    <material>Gazebo/DarkGrey</material>
    <surface>
      <friction>
        <ode>
          <mu>1.0</mu>
          <mu2>0.1</mu2>
        </ode>
      </friction>
    </surface>
  </gazebo>
  <link name="front_right_LR_link_7">
    <inertial>
      <origin rpy="0 0 0" xyz="0 0 0"/>
      <mass value="0.0343"/>
      <inertia ixx="0.00001147" ixy="0" ixz="0" iyy="0.000001312" iyz="0" izz="0.00001147"/>
    </inertial>
    <visual>
      <origin rpy="0 0 0" xyz="0 0 0"/>
      <geometry>
        <mesh filename="file:///home/imbatman/smdw_ws/src/right_smdw/meshes/FR_LR_link_7.STL"/>
      </geometry>
      <material name="front_right_base_color"/>
    </visual>
    <collision>
      <origin rpy="0 0 0" xyz="0 0 0"/>
      <geometry>
        <mesh filename="file:///home/imbatman/smdw_ws/src/right_smdw/meshes/FR_LR_link_7.STL"/>
      </geometry>
    </collision>
  </link>
  <joint name="front_right_LR_joint_7" type="continuous">
    <origin rpy="2.9882 0.1516 2.3445" xyz="0.0338 0.0279 -0.0498"/>
    <parent link="front_right_base_link"/>
    <child link="front_right_LR_link_7"/>
    <axis xyz="0 -1 0"/>
  </joint>
  <gazebo reference="front_right_LR_link_7">
    <material>Gazebo/DarkGrey</material>
    <surface>
      <friction>
        <ode>
          <mu>1.0</mu>
          <mu2>0.1</mu2>
        </ode>
      </friction>
    </surface>
  </gazebo>
  <link name="front_right_LR_link_8">
    <inertial>
      <origin rpy="0 0 0" xyz="0 0 0"/>
      <mass value="0.0343"/>
      <inertia ixx="0.00001147" ixy="0" ixz="0" iyy="0.000001312" iyz="0" izz="0.00001147"/>
    </inertial>
    <visual>
      <origin rpy="0 0 0" xyz="0 0 0"/>
      <geometry>
        <mesh filename="file:///home/imbatman/smdw_ws/src/right_smdw/meshes/FR_LR_link_8.STL"/>
      </geometry>
      <material name="front_right_base_color"/>
    </visual>
    <collision>
      <origin rpy="0 0 0" xyz="0 0 0"/>
      <geometry>
        <mesh filename="file:///home/imbatman/smdw_ws/src/right_smdw/meshes/FR_LR_link_8.STL"/>
      </geometry>
    </collision>
  </link>
  <joint name="front_right_LR_joint_8" type="continuous">
    <origin rpy="3.1416 0.0000 2.3562" xyz="0.0000 0.0279 -0.0533"/>
    <parent link="front_right_base_link"/>
    <child link="front_right_LR_link_8"/>
    <axis xyz="0 -1 0"/>
  </joint>
  <gazebo reference="front_right_LR_link_8">
    <material>Gazebo/DarkGrey</material>
    <surface>
      <friction>
        <ode>
          <mu>1.0</mu>
          <mu2>0.1</mu2>
        </ode>
      </friction>
    </surface>
  </gazebo>
  <link name="front_right_LR_link_9">
    <inertial>
      <origin rpy="0 0 0" xyz="0 0 0"/>
      <mass value="0.0343"/>
      <inertia ixx="0.00001147" ixy="0" ixz="0" iyy="0.000001312" iyz="0" izz="0.00001147"/>
    </inertial>
    <visual>
      <origin rpy="0 0 0" xyz="0 0 0"/>
      <geometry>
        <mesh filename="file:///home/imbatman/smdw_ws/src/right_smdw/meshes/FR_LR_link_9.STL"/>
      </geometry>
      <material name="front_right_base_color"/>
    </visual>
    <collision>
      <origin rpy="0 0 0" xyz="0 0 0"/>
      <geometry>
        <mesh filename="file:///home/imbatman/smdw_ws/src/right_smdw/meshes/FR_LR_link_9.STL"/>
      </geometry>
    </collision>
  </link>
  <joint name="front_right_LR_joint_9" type="continuous">
    <origin rpy="-2.9882 -0.1516 2.3445" xyz="-0.0338 0.0279 -0.0498"/>
    <parent link="front_right_base_link"/>
    <child link="front_right_LR_link_9"/>
    <axis xyz="0 -1 0"/>
  </joint>
  <gazebo reference="front_right_LR_link_9">
    <material>Gazebo/DarkGrey</material>
    <surface>
      <friction>
        <ode>
          <mu>1.0</mu>
          <mu2>0.1</mu2>
        </ode>
      </friction>
    </surface>
  </gazebo>
  <link name="front_right_LR_link_10">
    <inertial>
      <origin rpy="0 0 0" xyz="0 0 0"/>
      <mass value="0.0343"/>
      <inertia ixx="0.00001147" ixy="0" ixz="0" iyy="0.000001312" iyz="0" izz="0.00001147"/>
    </inertial>
    <visual>
      <origin rpy="0 0 0" xyz="0 0 0"/>
      <geometry>
        <mesh filename="file:///home/imbatman/smdw_ws/src/right_smdw/meshes/FR_LR_link_10.STL"/>
      </geometry>
      <material name="front_right_base_color"/>
    </visual>
    <collision>
      <origin rpy="0 0 0" xyz="0 0 0"/>
      <geometry>
        <mesh filename="file:///home/imbatman/smdw_ws/src/right_smdw/meshes/FR_LR_link_10.STL"/>
      </geometry>
    </collision>
  </link>
  <joint name="front_right_LR_joint_10" type="continuous">
    <origin rpy="-2.7309 -0.3798 2.2762" xyz="-0.0671 0.0279 -0.0370"/>
    <parent link="front_right_base_link"/>
    <child link="front_right_LR_link_10"/>
    <axis xyz="0 -1 0"/>
  </joint>
  <gazebo reference="front_right_LR_link_10">
    <material>Gazebo/DarkGrey</material>
    <surface>
      <friction>
        <ode>
          <mu>1.0</mu>
          <mu2>0.1</mu2>
        </ode>
      </friction>
    </surface>
  </gazebo>
  <link name="front_right_LR_link_11">
    <inertial>
      <origin rpy="0 0 0" xyz="0 0 0"/>
      <mass value="0.0343"/>
      <inertia ixx="0.00001147" ixy="0" ixz="0" iyy="0.000001312" iyz="0" izz="0.00001147"/>
    </inertial>
    <visual>
      <origin rpy="0 0 0" xyz="0 0 0"/>
      <geometry>
        <mesh filename="file:///home/imbatman/smdw_ws/src/right_smdw/meshes/FR_LR_link_11.STL"/>
      </geometry>
      <material name="front_right_base_color"/>
    </visual>
    <collision>
      <origin rpy="0 0 0" xyz="0 0 0"/>
      <geometry>
        <mesh filename="file:///home/imbatman/smdw_ws/src/right_smdw/meshes/FR_LR_link_11.STL"/>
      </geometry>
    </collision>
  </link>
  <joint name="front_right_LR_joint_11" type="continuous">
    <origin rpy="-1.5708 -0.7854 1.5708" xyz="-0.0914 0.0279 0.0000"/>
    <parent link="front_right_base_link"/>
    <child link="front_right_LR_link_11"/>
    <axis xyz="0 -1 0"/>
  </joint>
  <gazebo reference="front_right_LR_link_11">
    <material>Gazebo/DarkGrey</material>
    <surface>
      <friction>
        <ode>
          <mu>1.0</mu>
          <mu2>0.1</mu2>
        </ode>
      </friction>
    </surface>
  </gazebo>
  <link name="front_right_LR_link_12">
    <inertial>
      <origin rpy="0 0 0" xyz="0 0 0"/>
      <mass value="0.0343"/>
      <inertia ixx="0.00001147" ixy="0" ixz="0" iyy="0.000001312" iyz="0" izz="0.00001147"/>
    </inertial>
    <visual>
      <origin rpy="0 0 0" xyz="0 0 0"/>
      <geometry>
        <mesh filename="file:///home/imbatman/smdw_ws/src/right_smdw/meshes/FR_LR_link_12.STL"/>
      </geometry>
      <material name="front_right_base_color"/>
    </visual>
    <collision>
      <origin rpy="0 0 0" xyz="0 0 0"/>
      <geometry>
        <mesh filename="file:///home/imbatman/smdw_ws/src/right_smdw/meshes/FR_LR_link_12.STL"/>
      </geometry>
    </collision>
  </link>
  <joint name="front_right_LR_joint_12" type="continuous">
    <origin rpy="-1.0409 -0.7119 1.2053" xyz="-0.0845 0.0279 0.0350"/>
    <parent link="front_right_base_link"/>
    <child link="front_right_LR_link_12"/>
    <axis xyz="0 -1 0"/>
  </joint>
  <gazebo reference="front_right_LR_link_12">
    <material>Gazebo/DarkGrey</material>
    <surface>
      <friction>
        <ode>
          <mu>1.0</mu>
          <mu2>0.1</mu2>
        </ode>
      </friction>
    </surface>
  </gazebo>
  <link name="front_right_LR_link_13">
    <inertial>
      <origin rpy="0 0 0" xyz="0 0 0"/>
      <mass value="0.0343"/>
      <inertia ixx="0.00001147" ixy="0" ixz="0" iyy="0.000001312" iyz="0" izz="0.00001147"/>
    </inertial>
    <visual>
      <origin rpy="0 0 0" xyz="0 0 0"/>
      <geometry>
        <mesh filename="file:///home/imbatman/smdw_ws/src/right_smdw/meshes/FR_LR_link_13.STL"/>
      </geometry>
      <material name="front_right_base_color"/>
    </visual>
    <collision>
      <origin rpy="0 0 0" xyz="0 0 0"/>
      <geometry>
        <mesh filename="file:///home/imbatman/smdw_ws/src/right_smdw/meshes/FR_LR_link_13.STL"/>
      </geometry>
    </collision>
  </link>
  <joint name="front_right_LR_joint_13" type="continuous">
    <origin rpy="-0.6155 -0.5236 0.9553" xyz="-0.0647 0.0279 0.0647"/>
    <parent link="front_right_base_link"/>
    <child link="front_right_LR_link_13"/>
    <axis xyz="0 -1 0"/>
  </joint>
  <gazebo reference="front_right_LR_link_13">
    <material>Gazebo/DarkGrey</material>
    <surface>
      <friction>
        <ode>
          <mu>1.0</mu>
          <mu2>0.1</mu2>
        </ode>
      </friction>
    </surface>
  </gazebo>
  <link name="front_right_LR_link_14">
    <inertial>
      <origin rpy="0 0 0" xyz="0 0 0"/>
      <mass value="0.0343"/>
      <inertia ixx="0.00001147" ixy="0" ixz="0" iyy="0.000001312" iyz="0" izz="0.00001147"/>
    </inertial>
    <visual>
      <origin rpy="0 0 0" xyz="0 0 0"/>
      <geometry>
        <mesh filename="file:///home/imbatman/smdw_ws/src/right_smdw/meshes/FR_LR_link_14.STL"/>
      </geometry>
      <material name="front_right_base_color"/>
    </visual>
    <collision>
      <origin rpy="0 0 0" xyz="0 0 0"/>
      <geometry>
        <mesh filename="file:///home/imbatman/smdw_ws/src/right_smdw/meshes/FR_LR_link_14.STL"/>
      </geometry>
    </collision>
  </link>
  <joint name="front_right_LR_joint_14" type="continuous">
    <origin rpy="-0.2849 -0.2740 0.8249" xyz="-0.0350 0.0279 0.0845"/>
    <parent link="front_right_base_link"/>
    <child link="front_right_LR_link_14"/>
    <axis xyz="0 -1 0"/>
  </joint>
  <gazebo reference="front_right_LR_link_14">
    <material>Gazebo/DarkGrey</material>
    <surface>
      <friction>
        <ode>
          <mu>1.0</mu>
          <mu2>0.1</mu2>
        </ode>
      </friction>
    </surface>
  </gazebo>
  <!-- Define materials -->
  <material name="rear_left_base_color">
    <color rgba="0.79216 0.81961 0.93333 1"/>
  </material>
  <material name="rear_left_wheel_color">
    <color rgba="0.25098 0.25098 0.25098 1"/>
  </material>
  <!-- Base link -->
  <link name="rear_left_base_link">
    <inertial>
      <origin rpy="0 0 0" xyz="-4.3311E-18 1.504E-12 1.7857E-18"/>
      <mass value="1.9429"/>
      <inertia ixx="0.0019245" ixy="8.1609E-21" ixz="-8.1689E-08" iyy="0.0049239" iyz="-7.5092E-20" izz="0.0032216"/>
    </inertial>
    <visual>
      <origin rpy="0 0 0" xyz="0 0 0"/>
      <geometry>
        <mesh filename="file:///home/imbatman/smdw_ws/src/right_smdw/meshes/front_right_wheel_base_link.STL"/>
      </geometry>
      <material name="rear_left_wheel_color"/>
    </visual>
    <collision>
      <origin rpy="0 0 0" xyz="0 0 0"/>
      <geometry>
        <mesh filename="file:///home/imbatman/smdw_ws/src/right_smdw/meshes/front_right_wheel_base_link.STL"/>
      </geometry>
    </collision>
  </link>
  <link name="rear_left_RR_link_1">
    <inertial>
      <origin rpy="0 0 0" xyz="0 0 0"/>
      <mass value="0.0343"/>
      <inertia ixx="0.00001147" ixy="0" ixz="0" iyy="0.000001312" iyz="0" izz="0.00001147"/>
    </inertial>
    <visual>
      <origin rpy="0 0 0" xyz="0 0 0"/>
      <geometry>
        <mesh filename="file:///home/imbatman/smdw_ws/src/right_smdw/meshes/FR_RR_link_1.STL"/>
      </geometry>
      <material name="rear_left_base_color"/>
    </visual>
    <collision>
      <origin rpy="0 0 0" xyz="0 0 0"/>
      <geometry>
        <mesh filename="file:///home/imbatman/smdw_ws/src/right_smdw/meshes/FR_RR_link_1.STL"/>
      </geometry>
    </collision>
  </link>
  <joint name="rear_left_RR_joint_1" type="continuous">
    <origin rpy="0.0000 0.0000 0.7854" xyz="0.0000 -0.0279 0.0533"/>
    <parent link="rear_left_base_link"/>
    <child link="rear_left_RR_link_1"/>
    <axis xyz="0 -1 0"/>
  </joint>
  <gazebo reference="rear_left_RR_link_1">
    <material>Gazebo/DarkGrey</material>
    <surface>
      <friction>
        <ode>
          <mu>1.0</mu>
          <mu2>0.1</mu2>
        </ode>
      </friction>
    </surface>
  </gazebo>
  <link name="rear_left_RR_link_2">
    <inertial>
      <origin rpy="0 0 0" xyz="0 0 0"/>
      <mass value="0.0343"/>
      <inertia ixx="0.00001147" ixy="0" ixz="0" iyy="0.000001312" iyz="0" izz="0.00001147"/>
    </inertial>
    <visual>
      <origin rpy="0 0 0" xyz="0 0 0"/>
      <geometry>
        <mesh filename="file:///home/imbatman/smdw_ws/src/right_smdw/meshes/FR_RR_link_2.STL"/>
      </geometry>
      <material name="rear_left_base_color"/>
    </visual>
    <collision>
      <origin rpy="0 0 0" xyz="0 0 0"/>
      <geometry>
        <mesh filename="file:///home/imbatman/smdw_ws/src/right_smdw/meshes/FR_RR_link_2.STL"/>
      </geometry>
    </collision>
  </link>
  <joint name="rear_left_RR_joint_2" type="continuous">
    <origin rpy="0.1534 0.1516 0.7971" xyz="0.0338 -0.0279 0.0498"/>
    <parent link="rear_left_base_link"/>
    <child link="rear_left_RR_link_2"/>
    <axis xyz="0 -1 0"/>
  </joint>
  <gazebo reference="rear_left_RR_link_2">
    <material>Gazebo/DarkGrey</material>
    <surface>
      <friction>
        <ode>
          <mu>1.0</mu>
          <mu2>0.1</mu2>
        </ode>
      </friction>
    </surface>
  </gazebo>
  <link name="rear_left_RR_link_3">
    <inertial>
      <origin rpy="0 0 0" xyz="0 0 0"/>
      <mass value="0.0343"/>
      <inertia ixx="0.00001147" ixy="0" ixz="0" iyy="0.000001312" iyz="0" izz="0.00001147"/>
    </inertial>
    <visual>
      <origin rpy="0 0 0" xyz="0 0 0"/>
      <geometry>
        <mesh filename="file:///home/imbatman/smdw_ws/src/right_smdw/meshes/FR_RR_link_3.STL"/>
      </geometry>
      <material name="rear_left_base_color"/>
    </visual>
    <collision>
      <origin rpy="0 0 0" xyz="0 0 0"/>
      <geometry>
        <mesh filename="file:///home/imbatman/smdw_ws/src/right_smdw/meshes/FR_RR_link_3.STL"/>
      </geometry>
    </collision>
  </link>
  <joint name="rear_left_RR_joint_3" type="continuous">
    <origin rpy="0.4107 0.3798 0.8654" xyz="0.0671 -0.0279 0.0370"/>
    <parent link="rear_left_base_link"/>
    <child link="rear_left_RR_link_3"/>
    <axis xyz="0 -1 0"/>
  </joint>
  <gazebo reference="rear_left_RR_link_3">
    <material>Gazebo/DarkGrey</material>
    <surface>
      <friction>
        <ode>
          <mu>1.0</mu>
          <mu2>0.1</mu2>
        </ode>
      </friction>
    </surface>
  </gazebo>
  <link name="rear_left_RR_link_4">
    <inertial>
      <origin rpy="0 0 0" xyz="0 0 0"/>
      <mass value="0.0343"/>
      <inertia ixx="0.00001147" ixy="0" ixz="0" iyy="0.000001312" iyz="0" izz="0.00001147"/>
    </inertial>
    <visual>
      <origin rpy="0 0 0" xyz="0 0 0"/>
      <geometry>
        <mesh filename="file:///home/imbatman/smdw_ws/src/right_smdw/meshes/FR_RR_link_4.STL"/>
      </geometry>
      <material name="rear_left_base_color"/>
    </visual>
    <collision>
      <origin rpy="0 0 0" xyz="0 0 0"/>
      <geometry>
        <mesh filename="file:///home/imbatman/smdw_ws/src/right_smdw/meshes/FR_RR_link_4.STL"/>
      </geometry>
    </collision>
  </link>
  <joint name="rear_left_RR_joint_4" type="continuous">
    <origin rpy="1.5708 0.7854 1.5708" xyz="0.0914 -0.0279 0.0000"/>
    <parent link="rear_left_base_link"/>
    <child link="rear_left_RR_link_4"/>
    <axis xyz="0 -1 0"/>
  </joint>
  <gazebo reference="rear_left_RR_link_4">
    <material>Gazebo/DarkGrey</material>
    <surface>
      <friction>
        <ode>
          <mu>1.0</mu>
          <mu2>0.1</mu2>
        </ode>
      </friction>
    </surface>
  </gazebo>
  <link name="rear_left_RR_link_5">
    <inertial>
      <origin rpy="0 0 0" xyz="0 0 0"/>
      <mass value="0.0343"/>
      <inertia ixx="0.00001147" ixy="0" ixz="0" iyy="0.000001312" iyz="0" izz="0.00001147"/>
    </inertial>
    <visual>
      <origin rpy="0 0 0" xyz="0 0 0"/>
      <geometry>
        <mesh filename="file:///home/imbatman/smdw_ws/src/right_smdw/meshes/FR_RR_link_5.STL"/>
      </geometry>
      <material name="rear_left_base_color"/>
    </visual>
    <collision>
      <origin rpy="0 0 0" xyz="0 0 0"/>
      <geometry>
        <mesh filename="file:///home/imbatman/smdw_ws/src/right_smdw/meshes/FR_RR_link_5.STL"/>
      </geometry>
    </collision>
  </link>
  <joint name="rear_left_RR_joint_5" type="continuous">
    <origin rpy="2.1007 0.7119 1.9363" xyz="0.0845 -0.0279 -0.0350"/>
    <parent link="rear_left_base_link"/>
    <child link="rear_left_RR_link_5"/>
    <axis xyz="0 -1 0"/>
  </joint>
  <gazebo reference="rear_left_RR_link_5">
    <material>Gazebo/DarkGrey</material>
    <surface>
      <friction>
        <ode>
          <mu>1.0</mu>
          <mu2>0.1</mu2>
        </ode>
      </friction>
    </surface>
  </gazebo>
  <link name="rear_left_RR_link_6">
    <inertial>
      <origin rpy="0 0 0" xyz="0 0 0"/>
      <mass value="0.0343"/>
      <inertia ixx="0.00001147" ixy="0" ixz="0" iyy="0.000001312" iyz="0" izz="0.00001147"/>
    </inertial>
    <visual>
      <origin rpy="0 0 0" xyz="0 0 0"/>
      <geometry>
        <mesh filename="file:///home/imbatman/smdw_ws/src/right_smdw/meshes/FR_RR_link_6.STL"/>
      </geometry>
      <material name="rear_left_base_color"/>
    </visual>
    <collision>
      <origin rpy="0 0 0" xyz="0 0 0"/>
      <geometry>
        <mesh filename="file:///home/imbatman/smdw_ws/src/right_smdw/meshes/FR_RR_link_6.STL"/>
      </geometry>
    </collision>
  </link>
  <joint name="rear_left_RR_joint_6" type="continuous">
    <origin rpy="2.5261 0.5236 2.1863" xyz="0.0647 -0.0279 -0.0647"/>
    <parent link="rear_left_base_link"/>
    <child link="rear_left_RR_link_6"/>
    <axis xyz="0 -1 0"/>
  </joint>
  <gazebo reference="rear_left_RR_link_6">
    <material>Gazebo/DarkGrey</material>
    <surface>
      <friction>
        <ode>
          <mu>1.0</mu>
          <mu2>0.1</mu2>
        </ode>
      </friction>
    </surface>
  </gazebo>
  <link name="rear_left_RR_link_7">
    <inertial>
      <origin rpy="0 0 0" xyz="0 0 0"/>
      <mass value="0.0343"/>
      <inertia ixx="0.00001147" ixy="0" ixz="0" iyy="0.000001312" iyz="0" izz="0.00001147"/>
    </inertial>
    <visual>
      <origin rpy="0 0 0" xyz="0 0 0"/>
      <geometry>
        <mesh filename="file:///home/imbatman/smdw_ws/src/right_smdw/meshes/FR_RR_link_7.STL"/>
      </geometry>
      <material name="rear_left_base_color"/>
    </visual>
    <collision>
      <origin rpy="0 0 0" xyz="0 0 0"/>
      <geometry>
        <mesh filename="file:///home/imbatman/smdw_ws/src/right_smdw/meshes/FR_RR_link_7.STL"/>
      </geometry>
    </collision>
  </link>
  <joint name="rear_left_RR_joint_7" type="continuous">
    <origin rpy="2.8567 0.2740 2.3166" xyz="0.0350 -0.0279 -0.0845"/>
    <parent link="rear_left_base_link"/>
    <child link="rear_left_RR_link_7"/>
    <axis xyz="0 -1 0"/>
  </joint>
  <gazebo reference="rear_left_RR_link_7">
    <material>Gazebo/DarkGrey</material>
    <surface>
      <friction>
        <ode>
          <mu>1.0</mu>
          <mu2>0.1</mu2>
        </ode>
      </friction>
    </surface>
  </gazebo>
  <link name="rear_left_RR_link_8">
    <inertial>
      <origin rpy="0 0 0" xyz="0 0 0"/>
      <mass value="0.0343"/>
      <inertia ixx="0.00001147" ixy="0" ixz="0" iyy="0.000001312" iyz="0" izz="0.00001147"/>
    </inertial>
    <visual>
      <origin rpy="0 0 0" xyz="0 0 0"/>
      <geometry>
        <mesh filename="file:///home/imbatman/smdw_ws/src/right_smdw/meshes/FR_RR_link_8.STL"/>
      </geometry>
      <material name="rear_left_base_color"/>
    </visual>
    <collision>
      <origin rpy="0 0 0" xyz="0 0 0"/>
      <geometry>
        <mesh filename="file:///home/imbatman/smdw_ws/src/right_smdw/meshes/FR_RR_link_8.STL"/>
      </geometry>
    </collision>
  </link>
  <joint name="rear_left_RR_joint_8" type="continuous">
    <origin rpy="3.1416 0.0000 2.3562" xyz="0.0000 -0.0279 -0.0914"/>
    <parent link="rear_left_base_link"/>
    <child link="rear_left_RR_link_8"/>
    <axis xyz="0 -1 0"/>
  </joint>
  <gazebo reference="rear_left_RR_link_8">
    <material>Gazebo/DarkGrey</material>
    <surface>
      <friction>
        <ode>
          <mu>1.0</mu>
          <mu2>0.1</mu2>
        </ode>
      </friction>
    </surface>
  </gazebo>
  <link name="rear_left_RR_link_9">
    <inertial>
      <origin rpy="0 0 0" xyz="0 0 0"/>
      <mass value="0.0343"/>
      <inertia ixx="0.00001147" ixy="0" ixz="0" iyy="0.000001312" iyz="0" izz="0.00001147"/>
    </inertial>
    <visual>
      <origin rpy="0 0 0" xyz="0 0 0"/>
      <geometry>
        <mesh filename="file:///home/imbatman/smdw_ws/src/right_smdw/meshes/FR_RR_link_9.STL"/>
      </geometry>
      <material name="rear_left_base_color"/>
    </visual>
    <collision>
      <origin rpy="0 0 0" xyz="0 0 0"/>
      <geometry>
        <mesh filename="file:///home/imbatman/smdw_ws/src/right_smdw/meshes/FR_RR_link_9.STL"/>
      </geometry>
    </collision>
  </link>
  <joint name="rear_left_RR_joint_9" type="continuous">
    <origin rpy="-2.8567 -0.2740 2.3166" xyz="-0.0350 -0.0279 -0.0845"/>
    <parent link="rear_left_base_link"/>
    <child link="rear_left_RR_link_9"/>
    <axis xyz="0 -1 0"/>
  </joint>
  <gazebo reference="rear_left_RR_link_9">
    <material>Gazebo/DarkGrey</material>
    <surface>
      <friction>
        <ode>
          <mu>1.0</mu>
          <mu2>0.1</mu2>
        </ode>
      </friction>
    </surface>
  </gazebo>
  <link name="rear_left_RR_link_10">
    <inertial>
      <origin rpy="0 0 0" xyz="0 0 0"/>
      <mass value="0.0343"/>
      <inertia ixx="0.00001147" ixy="0" ixz="0" iyy="0.000001312" iyz="0" izz="0.00001147"/>
    </inertial>
    <visual>
      <origin rpy="0 0 0" xyz="0 0 0"/>
      <geometry>
        <mesh filename="file:///home/imbatman/smdw_ws/src/right_smdw/meshes/FR_RR_link_10.STL"/>
      </geometry>
      <material name="rear_left_base_color"/>
    </visual>
    <collision>
      <origin rpy="0 0 0" xyz="0 0 0"/>
      <geometry>
        <mesh filename="file:///home/imbatman/smdw_ws/src/right_smdw/meshes/FR_RR_link_10.STL"/>
      </geometry>
    </collision>
  </link>
  <joint name="rear_left_RR_joint_10" type="continuous">
    <origin rpy="-2.5261 -0.5236 2.1863" xyz="-0.0647 -0.0279 -0.0647"/>
    <parent link="rear_left_base_link"/>
    <child link="rear_left_RR_link_10"/>
    <axis xyz="0 -1 0"/>
  </joint>
  <gazebo reference="rear_left_RR_link_10">
    <material>Gazebo/DarkGrey</material>
    <surface>
      <friction>
        <ode>
          <mu>1.0</mu>
          <mu2>0.1</mu2>
        </ode>
      </friction>
    </surface>
  </gazebo>
  <link name="rear_left_RR_link_11">
    <inertial>
      <origin rpy="0 0 0" xyz="0 0 0"/>
      <mass value="0.0343"/>
      <inertia ixx="0.00001147" ixy="0" ixz="0" iyy="0.000001312" iyz="0" izz="0.00001147"/>
    </inertial>
    <visual>
      <origin rpy="0 0 0" xyz="0 0 0"/>
      <geometry>
        <mesh filename="file:///home/imbatman/smdw_ws/src/right_smdw/meshes/FR_RR_link_11.STL"/>
      </geometry>
      <material name="rear_left_base_color"/>
    </visual>
    <collision>
      <origin rpy="0 0 0" xyz="0 0 0"/>
      <geometry>
        <mesh filename="file:///home/imbatman/smdw_ws/src/right_smdw/meshes/FR_RR_link_11.STL"/>
      </geometry>
    </collision>
  </link>
  <joint name="rear_left_RR_joint_11" type="continuous">
    <origin rpy="-2.1007 -0.7119 1.9363" xyz="-0.0845 -0.0279 -0.0350"/>
    <parent link="rear_left_base_link"/>
    <child link="rear_left_RR_link_11"/>
    <axis xyz="0 -1 0"/>
  </joint>
  <gazebo reference="rear_left_RR_link_11">
    <material>Gazebo/DarkGrey</material>
    <surface>
      <friction>
        <ode>
          <mu>1.0</mu>
          <mu2>0.1</mu2>
        </ode>
      </friction>
    </surface>
  </gazebo>
  <link name="rear_left_RR_link_12">
    <inertial>
      <origin rpy="0 0 0" xyz="0 0 0"/>
      <mass value="0.0343"/>
      <inertia ixx="0.00001147" ixy="0" ixz="0" iyy="0.000001312" iyz="0" izz="0.00001147"/>
    </inertial>
    <visual>
      <origin rpy="0 0 0" xyz="0 0 0"/>
      <geometry>
        <mesh filename="file:///home/imbatman/smdw_ws/src/right_smdw/meshes/FR_RR_link_12.STL"/>
      </geometry>
      <material name="rear_left_base_color"/>
    </visual>
    <collision>
      <origin rpy="0 0 0" xyz="0 0 0"/>
      <geometry>
        <mesh filename="file:///home/imbatman/smdw_ws/src/right_smdw/meshes/FR_RR_link_12.STL"/>
      </geometry>
    </collision>
  </link>
  <joint name="rear_left_RR_joint_12" type="continuous">
    <origin rpy="-1.5708 -0.7854 1.5708" xyz="-0.0914 -0.0279 0.0000"/>
    <parent link="rear_left_base_link"/>
    <child link="rear_left_RR_link_12"/>
    <axis xyz="0 -1 0"/>
  </joint>
  <gazebo reference="rear_left_RR_link_12">
    <material>Gazebo/DarkGrey</material>
    <surface>
      <friction>
        <ode>
          <mu>1.0</mu>
          <mu2>0.1</mu2>
        </ode>
      </friction>
    </surface>
  </gazebo>
  <link name="rear_left_RR_link_13">
    <inertial>
      <origin rpy="0 0 0" xyz="0 0 0"/>
      <mass value="0.0343"/>
      <inertia ixx="0.00001147" ixy="0" ixz="0" iyy="0.000001312" iyz="0" izz="0.00001147"/>
    </inertial>
    <visual>
      <origin rpy="0 0 0" xyz="0 0 0"/>
      <geometry>
        <mesh filename="file:///home/imbatman/smdw_ws/src/right_smdw/meshes/FR_RR_link_13.STL"/>
      </geometry>
      <material name="rear_left_base_color"/>
    </visual>
    <collision>
      <origin rpy="0 0 0" xyz="0 0 0"/>
      <geometry>
        <mesh filename="file:///home/imbatman/smdw_ws/src/right_smdw/meshes/FR_RR_link_13.STL"/>
      </geometry>
    </collision>
  </link>
  <joint name="rear_left_RR_joint_13" type="continuous">
    <origin rpy="-0.4107 -0.3798 0.8654" xyz="-0.0671 -0.0279 0.0370"/>
    <parent link="rear_left_base_link"/>
    <child link="rear_left_RR_link_13"/>
    <axis xyz="0 -1 0"/>
  </joint>
  <gazebo reference="rear_left_RR_link_13">
    <material>Gazebo/DarkGrey</material>
    <surface>
      <friction>
        <ode>
          <mu>1.0</mu>
          <mu2>0.1</mu2>
        </ode>
      </friction>
    </surface>
  </gazebo>
  <link name="rear_left_RR_link_14">
    <inertial>
      <origin rpy="0 0 0" xyz="0 0 0"/>
      <mass value="0.0343"/>
      <inertia ixx="0.00001147" ixy="0" ixz="0" iyy="0.000001312" iyz="0" izz="0.00001147"/>
    </inertial>
    <visual>
      <origin rpy="0 0 0" xyz="0 0 0"/>
      <geometry>
        <mesh filename="file:///home/imbatman/smdw_ws/src/right_smdw/meshes/FR_RR_link_14.STL"/>
      </geometry>
      <material name="rear_left_base_color"/>
    </visual>
    <collision>
      <origin rpy="0 0 0" xyz="0 0 0"/>
      <geometry>
        <mesh filename="file:///home/imbatman/smdw_ws/src/right_smdw/meshes/FR_RR_link_14.STL"/>
      </geometry>
    </collision>
  </link>
  <joint name="rear_left_RR_joint_14" type="continuous">
    <origin rpy="-0.1534 -0.1516 0.7971" xyz="-0.0338 -0.0279 0.0498"/>
    <parent link="rear_left_base_link"/>
    <child link="rear_left_RR_link_14"/>
    <axis xyz="0 -1 0"/>
  </joint>
  <gazebo reference="rear_left_RR_link_14">
    <material>Gazebo/DarkGrey</material>
    <surface>
      <friction>
        <ode>
          <mu>1.0</mu>
          <mu2>0.1</mu2>
        </ode>
      </friction>
    </surface>
  </gazebo>
  <link name="rear_left_LR_link_1">
    <inertial>
      <origin rpy="0 0 0" xyz="0 0 0"/>
      <mass value="0.0343"/>
      <inertia ixx="0.00001147" ixy="0" ixz="0" iyy="0.000001312" iyz="0" izz="0.00001147"/>
    </inertial>
    <visual>
      <origin rpy="0 0 0" xyz="0 0 0"/>
      <geometry>
        <mesh filename="file:///home/imbatman/smdw_ws/src/right_smdw/meshes/FR_LR_link_1.STL"/>
      </geometry>
      <material name="rear_left_base_color"/>
    </visual>
    <collision>
      <origin rpy="0 0 0" xyz="0 0 0"/>
      <geometry>
        <mesh filename="file:///home/imbatman/smdw_ws/src/right_smdw/meshes/FR_LR_link_1.STL"/>
      </geometry>
    </collision>
  </link>
  <joint name="rear_left_LR_joint_1" type="continuous">
    <origin rpy="0.0000 0.0000 0.7854" xyz="0.0000 0.0279 0.0914"/>
    <parent link="rear_left_base_link"/>
    <child link="rear_left_LR_link_1"/>
    <axis xyz="0 -1 0"/>
  </joint>
  <gazebo reference="rear_left_LR_link_1">
    <material>Gazebo/DarkGrey</material>
    <surface>
      <friction>
        <ode>
          <mu>1.0</mu>
          <mu2>0.1</mu2>
        </ode>
      </friction>
    </surface>
  </gazebo>
  <link name="rear_left_LR_link_2">
    <inertial>
      <origin rpy="0 0 0" xyz="0 0 0"/>
      <mass value="0.0343"/>
      <inertia ixx="0.00001147" ixy="0" ixz="0" iyy="0.000001312" iyz="0" izz="0.00001147"/>
    </inertial>
    <visual>
      <origin rpy="0 0 0" xyz="0 0 0"/>
      <geometry>
        <mesh filename="file:///home/imbatman/smdw_ws/src/right_smdw/meshes/FR_LR_link_2.STL"/>
      </geometry>
      <material name="rear_left_base_color"/>
    </visual>
    <collision>
      <origin rpy="0 0 0" xyz="0 0 0"/>
      <geometry>
        <mesh filename="file:///home/imbatman/smdw_ws/src/right_smdw/meshes/FR_LR_link_2.STL"/>
      </geometry>
    </collision>
  </link>
  <joint name="rear_left_LR_joint_2" type="continuous">
    <origin rpy="0.2849 0.2740 0.8249" xyz="0.0350 0.0279 0.0845"/>
    <parent link="rear_left_base_link"/>
    <child link="rear_left_LR_link_2"/>
    <axis xyz="0 -1 0"/>
  </joint>
  <gazebo reference="rear_left_LR_link_2">
    <material>Gazebo/DarkGrey</material>
    <surface>
      <friction>
        <ode>
          <mu>1.0</mu>
          <mu2>0.1</mu2>
        </ode>
      </friction>
    </surface>
  </gazebo>
  <link name="rear_left_LR_link_3">
    <inertial>
      <origin rpy="0 0 0" xyz="0 0 0"/>
      <mass value="0.0343"/>
      <inertia ixx="0.00001147" ixy="0" ixz="0" iyy="0.000001312" iyz="0" izz="0.00001147"/>
    </inertial>
    <visual>
      <origin rpy="0 0 0" xyz="0 0 0"/>
      <geometry>
        <mesh filename="file:///home/imbatman/smdw_ws/src/right_smdw/meshes/FR_LR_link_3.STL"/>
      </geometry>
      <material name="rear_left_base_color"/>
    </visual>
    <collision>
      <origin rpy="0 0 0" xyz="0 0 0"/>
      <geometry>
        <mesh filename="file:///home/imbatman/smdw_ws/src/right_smdw/meshes/FR_LR_link_3.STL"/>
      </geometry>
    </collision>
  </link>
  <joint name="rear_left_LR_joint_3" type="continuous">
    <origin rpy="0.6155 0.5236 0.9553" xyz="0.0647 0.0279 0.0647"/>
    <parent link="rear_left_base_link"/>
    <child link="rear_left_LR_link_3"/>
    <axis xyz="0 -1 0"/>
  </joint>
  <gazebo reference="rear_left_LR_link_3">
    <material>Gazebo/DarkGrey</material>
    <surface>
      <friction>
        <ode>
          <mu>1.0</mu>
          <mu2>0.1</mu2>
        </ode>
      </friction>
    </surface>
  </gazebo>
  <link name="rear_left_LR_link_4">
    <inertial>
      <origin rpy="0 0 0" xyz="0 0 0"/>
      <mass value="0.0343"/>
      <inertia ixx="0.00001147" ixy="0" ixz="0" iyy="0.000001312" iyz="0" izz="0.00001147"/>
    </inertial>
    <visual>
      <origin rpy="0 0 0" xyz="0 0 0"/>
      <geometry>
        <mesh filename="file:///home/imbatman/smdw_ws/src/right_smdw/meshes/FR_LR_link_4.STL"/>
      </geometry>
      <material name="rear_left_base_color"/>
    </visual>
    <collision>
      <origin rpy="0 0 0" xyz="0 0 0"/>
      <geometry>
        <mesh filename="file:///home/imbatman/smdw_ws/src/right_smdw/meshes/FR_LR_link_4.STL"/>
      </geometry>
    </collision>
  </link>
  <joint name="rear_left_LR_joint_4" type="continuous">
    <origin rpy="1.0409 0.7119 1.2053" xyz="0.0845 0.0279 0.0350"/>
    <parent link="rear_left_base_link"/>
    <child link="rear_left_LR_link_4"/>
    <axis xyz="0 -1 0"/>
  </joint>
  <gazebo reference="rear_left_LR_link_4">
    <material>Gazebo/DarkGrey</material>
    <surface>
      <friction>
        <ode>
          <mu>1.0</mu>
          <mu2>0.1</mu2>
        </ode>
      </friction>
    </surface>
  </gazebo>
  <link name="rear_left_LR_link_5">
    <inertial>
      <origin rpy="0 0 0" xyz="0 0 0"/>
      <mass value="0.0343"/>
      <inertia ixx="0.00001147" ixy="0" ixz="0" iyy="0.000001312" iyz="0" izz="0.00001147"/>
    </inertial>
    <visual>
      <origin rpy="0 0 0" xyz="0 0 0"/>
      <geometry>
        <mesh filename="file:///home/imbatman/smdw_ws/src/right_smdw/meshes/FR_LR_link_5.STL"/>
      </geometry>
      <material name="rear_left_base_color"/>
    </visual>
    <collision>
      <origin rpy="0 0 0" xyz="0 0 0"/>
      <geometry>
        <mesh filename="file:///home/imbatman/smdw_ws/src/right_smdw/meshes/FR_LR_link_5.STL"/>
      </geometry>
    </collision>
  </link>
  <joint name="rear_left_LR_joint_5" type="continuous">
    <origin rpy="1.5708 0.7854 1.5708" xyz="0.0914 0.0279 0.0000"/>
    <parent link="rear_left_base_link"/>
    <child link="rear_left_LR_link_5"/>
    <axis xyz="0 -1 0"/>
  </joint>
  <gazebo reference="rear_left_LR_link_5">
    <material>Gazebo/DarkGrey</material>
    <surface>
      <friction>
        <ode>
          <mu>1.0</mu>
          <mu2>0.1</mu2>
        </ode>
      </friction>
    </surface>
  </gazebo>
  <link name="rear_left_LR_link_6">
    <inertial>
      <origin rpy="0 0 0" xyz="0 0 0"/>
      <mass value="0.0343"/>
      <inertia ixx="0.00001147" ixy="0" ixz="0" iyy="0.000001312" iyz="0" izz="0.00001147"/>
    </inertial>
    <visual>
      <origin rpy="0 0 0" xyz="0 0 0"/>
      <geometry>
        <mesh filename="file:///home/imbatman/smdw_ws/src/right_smdw/meshes/FR_LR_link_6.STL"/>
      </geometry>
      <material name="rear_left_base_color"/>
    </visual>
    <collision>
      <origin rpy="0 0 0" xyz="0 0 0"/>
      <geometry>
        <mesh filename="file:///home/imbatman/smdw_ws/src/right_smdw/meshes/FR_LR_link_6.STL"/>
      </geometry>
    </collision>
  </link>
  <joint name="rear_left_LR_joint_6" type="continuous">
    <origin rpy="2.7309 0.3798 2.2762" xyz="0.0671 0.0279 -0.0370"/>
    <parent link="rear_left_base_link"/>
    <child link="rear_left_LR_link_6"/>
    <axis xyz="0 -1 0"/>
  </joint>
  <gazebo reference="rear_left_LR_link_6">
    <material>Gazebo/DarkGrey</material>
    <surface>
      <friction>
        <ode>
          <mu>1.0</mu>
          <mu2>0.1</mu2>
        </ode>
      </friction>
    </surface>
  </gazebo>
  <link name="rear_left_LR_link_7">
    <inertial>
      <origin rpy="0 0 0" xyz="0 0 0"/>
      <mass value="0.0343"/>
      <inertia ixx="0.00001147" ixy="0" ixz="0" iyy="0.000001312" iyz="0" izz="0.00001147"/>
    </inertial>
    <visual>
      <origin rpy="0 0 0" xyz="0 0 0"/>
      <geometry>
        <mesh filename="file:///home/imbatman/smdw_ws/src/right_smdw/meshes/FR_LR_link_7.STL"/>
      </geometry>
      <material name="rear_left_base_color"/>
    </visual>
    <collision>
      <origin rpy="0 0 0" xyz="0 0 0"/>
      <geometry>
        <mesh filename="file:///home/imbatman/smdw_ws/src/right_smdw/meshes/FR_LR_link_7.STL"/>
      </geometry>
    </collision>
  </link>
  <joint name="rear_left_LR_joint_7" type="continuous">
    <origin rpy="2.9882 0.1516 2.3445" xyz="0.0338 0.0279 -0.0498"/>
    <parent link="rear_left_base_link"/>
    <child link="rear_left_LR_link_7"/>
    <axis xyz="0 -1 0"/>
  </joint>
  <gazebo reference="rear_left_LR_link_7">
    <material>Gazebo/DarkGrey</material>
    <surface>
      <friction>
        <ode>
          <mu>1.0</mu>
          <mu2>0.1</mu2>
        </ode>
      </friction>
    </surface>
  </gazebo>
  <link name="rear_left_LR_link_8">
    <inertial>
      <origin rpy="0 0 0" xyz="0 0 0"/>
      <mass value="0.0343"/>
      <inertia ixx="0.00001147" ixy="0" ixz="0" iyy="0.000001312" iyz="0" izz="0.00001147"/>
    </inertial>
    <visual>
      <origin rpy="0 0 0" xyz="0 0 0"/>
      <geometry>
        <mesh filename="file:///home/imbatman/smdw_ws/src/right_smdw/meshes/FR_LR_link_8.STL"/>
      </geometry>
      <material name="rear_left_base_color"/>
    </visual>
    <collision>
      <origin rpy="0 0 0" xyz="0 0 0"/>
      <geometry>
        <mesh filename="file:///home/imbatman/smdw_ws/src/right_smdw/meshes/FR_LR_link_8.STL"/>
      </geometry>
    </collision>
  </link>
  <joint name="rear_left_LR_joint_8" type="continuous">
    <origin rpy="3.1416 0.0000 2.3562" xyz="0.0000 0.0279 -0.0533"/>
    <parent link="rear_left_base_link"/>
    <child link="rear_left_LR_link_8"/>
    <axis xyz="0 -1 0"/>
  </joint>
  <gazebo reference="rear_left_LR_link_8">
    <material>Gazebo/DarkGrey</material>
    <surface>
      <friction>
        <ode>
          <mu>1.0</mu>
          <mu2>0.1</mu2>
        </ode>
      </friction>
    </surface>
  </gazebo>
  <link name="rear_left_LR_link_9">
    <inertial>
      <origin rpy="0 0 0" xyz="0 0 0"/>
      <mass value="0.0343"/>
      <inertia ixx="0.00001147" ixy="0" ixz="0" iyy="0.000001312" iyz="0" izz="0.00001147"/>
    </inertial>
    <visual>
      <origin rpy="0 0 0" xyz="0 0 0"/>
      <geometry>
        <mesh filename="file:///home/imbatman/smdw_ws/src/right_smdw/meshes/FR_LR_link_9.STL"/>
      </geometry>
      <material name="rear_left_base_color"/>
    </visual>
    <collision>
      <origin rpy="0 0 0" xyz="0 0 0"/>
      <geometry>
        <mesh filename="file:///home/imbatman/smdw_ws/src/right_smdw/meshes/FR_LR_link_9.STL"/>
      </geometry>
    </collision>
  </link>
  <joint name="rear_left_LR_joint_9" type="continuous">
    <origin rpy="-2.9882 -0.1516 2.3445" xyz="-0.0338 0.0279 -0.0498"/>
    <parent link="rear_left_base_link"/>
    <child link="rear_left_LR_link_9"/>
    <axis xyz="0 -1 0"/>
  </joint>
  <gazebo reference="rear_left_LR_link_9">
    <material>Gazebo/DarkGrey</material>
    <surface>
      <friction>
        <ode>
          <mu>1.0</mu>
          <mu2>0.1</mu2>
        </ode>
      </friction>
    </surface>
  </gazebo>
  <link name="rear_left_LR_link_10">
    <inertial>
      <origin rpy="0 0 0" xyz="0 0 0"/>
      <mass value="0.0343"/>
      <inertia ixx="0.00001147" ixy="0" ixz="0" iyy="0.000001312" iyz="0" izz="0.00001147"/>
    </inertial>
    <visual>
      <origin rpy="0 0 0" xyz="0 0 0"/>
      <geometry>
        <mesh filename="file:///home/imbatman/smdw_ws/src/right_smdw/meshes/FR_LR_link_10.STL"/>
      </geometry>
      <material name="rear_left_base_color"/>
    </visual>
    <collision>
      <origin rpy="0 0 0" xyz="0 0 0"/>
      <geometry>
        <mesh filename="file:///home/imbatman/smdw_ws/src/right_smdw/meshes/FR_LR_link_10.STL"/>
      </geometry>
    </collision>
  </link>
  <joint name="rear_left_LR_joint_10" type="continuous">
    <origin rpy="-2.7309 -0.3798 2.2762" xyz="-0.0671 0.0279 -0.0370"/>
    <parent link="rear_left_base_link"/>
    <child link="rear_left_LR_link_10"/>
    <axis xyz="0 -1 0"/>
  </joint>
  <gazebo reference="rear_left_LR_link_10">
    <material>Gazebo/DarkGrey</material>
    <surface>
      <friction>
        <ode>
          <mu>1.0</mu>
          <mu2>0.1</mu2>
        </ode>
      </friction>
    </surface>
  </gazebo>
  <link name="rear_left_LR_link_11">
    <inertial>
      <origin rpy="0 0 0" xyz="0 0 0"/>
      <mass value="0.0343"/>
      <inertia ixx="0.00001147" ixy="0" ixz="0" iyy="0.000001312" iyz="0" izz="0.00001147"/>
    </inertial>
    <visual>
      <origin rpy="0 0 0" xyz="0 0 0"/>
      <geometry>
        <mesh filename="file:///home/imbatman/smdw_ws/src/right_smdw/meshes/FR_LR_link_11.STL"/>
      </geometry>
      <material name="rear_left_base_color"/>
    </visual>
    <collision>
      <origin rpy="0 0 0" xyz="0 0 0"/>
      <geometry>
        <mesh filename="file:///home/imbatman/smdw_ws/src/right_smdw/meshes/FR_LR_link_11.STL"/>
      </geometry>
    </collision>
  </link>
  <joint name="rear_left_LR_joint_11" type="continuous">
    <origin rpy="-1.5708 -0.7854 1.5708" xyz="-0.0914 0.0279 0.0000"/>
    <parent link="rear_left_base_link"/>
    <child link="rear_left_LR_link_11"/>
    <axis xyz="0 -1 0"/>
  </joint>
  <gazebo reference="rear_left_LR_link_11">
    <material>Gazebo/DarkGrey</material>
    <surface>
      <friction>
        <ode>
          <mu>1.0</mu>
          <mu2>0.1</mu2>
        </ode>
      </friction>
    </surface>
  </gazebo>
  <link name="rear_left_LR_link_12">
    <inertial>
      <origin rpy="0 0 0" xyz="0 0 0"/>
      <mass value="0.0343"/>
      <inertia ixx="0.00001147" ixy="0" ixz="0" iyy="0.000001312" iyz="0" izz="0.00001147"/>
    </inertial>
    <visual>
      <origin rpy="0 0 0" xyz="0 0 0"/>
      <geometry>
        <mesh filename="file:///home/imbatman/smdw_ws/src/right_smdw/meshes/FR_LR_link_12.STL"/>
      </geometry>
      <material name="rear_left_base_color"/>
    </visual>
    <collision>
      <origin rpy="0 0 0" xyz="0 0 0"/>
      <geometry>
        <mesh filename="file:///home/imbatman/smdw_ws/src/right_smdw/meshes/FR_LR_link_12.STL"/>
      </geometry>
    </collision>
  </link>
  <joint name="rear_left_LR_joint_12" type="continuous">
    <origin rpy="-1.0409 -0.7119 1.2053" xyz="-0.0845 0.0279 0.0350"/>
    <parent link="rear_left_base_link"/>
    <child link="rear_left_LR_link_12"/>
    <axis xyz="0 -1 0"/>
  </joint>
  <gazebo reference="rear_left_LR_link_12">
    <material>Gazebo/DarkGrey</material>
    <surface>
      <friction>
        <ode>
          <mu>1.0</mu>
          <mu2>0.1</mu2>
        </ode>
      </friction>
    </surface>
  </gazebo>
  <link name="rear_left_LR_link_13">
    <inertial>
      <origin rpy="0 0 0" xyz="0 0 0"/>
      <mass value="0.0343"/>
      <inertia ixx="0.00001147" ixy="0" ixz="0" iyy="0.000001312" iyz="0" izz="0.00001147"/>
    </inertial>
    <visual>
      <origin rpy="0 0 0" xyz="0 0 0"/>
      <geometry>
        <mesh filename="file:///home/imbatman/smdw_ws/src/right_smdw/meshes/FR_LR_link_13.STL"/>
      </geometry>
      <material name="rear_left_base_color"/>
    </visual>
    <collision>
      <origin rpy="0 0 0" xyz="0 0 0"/>
      <geometry>
        <mesh filename="file:///home/imbatman/smdw_ws/src/right_smdw/meshes/FR_LR_link_13.STL"/>
      </geometry>
    </collision>
  </link>
  <joint name="rear_left_LR_joint_13" type="continuous">
    <origin rpy="-0.6155 -0.5236 0.9553" xyz="-0.0647 0.0279 0.0647"/>
    <parent link="rear_left_base_link"/>
    <child link="rear_left_LR_link_13"/>
    <axis xyz="0 -1 0"/>
  </joint>
  <gazebo reference="rear_left_LR_link_13">
    <material>Gazebo/DarkGrey</material>
    <surface>
      <friction>
        <ode>
          <mu>1.0</mu>
          <mu2>0.1</mu2>
        </ode>
      </friction>
    </surface>
  </gazebo>
  <link name="rear_left_LR_link_14">
    <inertial>
      <origin rpy="0 0 0" xyz="0 0 0"/>
      <mass value="0.0343"/>
      <inertia ixx="0.00001147" ixy="0" ixz="0" iyy="0.000001312" iyz="0" izz="0.00001147"/>
    </inertial>
    <visual>
      <origin rpy="0 0 0" xyz="0 0 0"/>
      <geometry>
        <mesh filename="file:///home/imbatman/smdw_ws/src/right_smdw/meshes/FR_LR_link_14.STL"/>
      </geometry>
      <material name="rear_left_base_color"/>
    </visual>
    <collision>
      <origin rpy="0 0 0" xyz="0 0 0"/>
      <geometry>
        <mesh filename="file:///home/imbatman/smdw_ws/src/right_smdw/meshes/FR_LR_link_14.STL"/>
      </geometry>
    </collision>
  </link>
  <joint name="rear_left_LR_joint_14" type="continuous">
    <origin rpy="-0.2849 -0.2740 0.8249" xyz="-0.0350 0.0279 0.0845"/>
    <parent link="rear_left_base_link"/>
    <child link="rear_left_LR_link_14"/>
    <axis xyz="0 -1 0"/>
  </joint>
  <gazebo reference="rear_left_LR_link_14">
    <material>Gazebo/DarkGrey</material>
    <surface>
      <friction>
        <ode>
          <mu>1.0</mu>
          <mu2>0.1</mu2>
        </ode>
      </friction>
    </surface>
  </gazebo>
  <!-- Attach wheels to base_link -->
  <joint name="front_left_wheel_joint" type="continuous">
    <parent link="base_link"/>
    <child link="front_left_base_link"/>
    <origin rpy="0 0 0" xyz="0.2159 0.3175 0.0508"/>
    <axis xyz="0 1 0"/>
    <limit effort="100.0" velocity="10.0"/>
    <dynamics friction="0.01"/>
  </joint>
  <joint name="rear_left_wheel_joint" type="continuous">
    <parent link="base_link"/>
    <child link="rear_left_base_link"/>
    <origin rpy="0 0 0" xyz="-0.2159 0.3175 0.0508"/>
    <axis xyz="0 1 0"/>
    <limit effort="100.0" velocity="10.0"/>
    <dynamics friction="0.01"/>
  </joint>
  <joint name="front_right_wheel_joint" type="continuous">
    <parent link="base_link"/>
    <child link="front_right_base_link"/>
    <origin rpy="0 0 0" xyz="0.2159 -0.3175 0.0508"/>
    <axis xyz="0 1 0"/>
    <limit effort="100.0" velocity="10.0"/>
    <dynamics friction="0.01"/>
  </joint>
  <joint name="rear_right_wheel_joint" type="continuous">
    <parent link="base_link"/>
    <child link="rear_right_base_link"/>
    <origin rpy="0 0 0" xyz="-0.2159 -0.3175 0.0508"/>
    <axis xyz="0 1 0"/>
    <limit effort="100.0" velocity="10.0"/>
    <dynamics friction="0.01"/>
  </joint>
</robot>
