<?xml version="1.0"?>
<robot xmlns:xacro="http://www.ros.org/wiki/xacro" name="xaarm">

  <xacro:property name="mesh_path" value="file:///home/imbatman/agribot_ws/src/xaarm/meshes"/>


  <!-- remove this comment to only use arm/ comment this when to attach with mobile base robot -->
<!-- 
  <link name="world" />
  <joint name="base_joint" type="fixed">
      <parent link="world" />
      <child link="xaarm_base_link" />
    <origin rpy="0 0 0" xyz="0.0 0.0 0.0" />
  </joint> -->
<!-- _______________________________________________________________________________________________________________ -->

  <link name="xaarm_base_link">
    <inertial>
      <origin xyz="0 0.0003 0.0726" rpy="0 0 0"/>
      <mass value="8.3079"/>
      <inertia ixx="0.0224" ixy="0" ixz="0" iyy="0.0223" iyz="0.0001" izz="0.0103"/>
    </inertial>
    <visual>
      <origin xyz="0 0 0" rpy="0 0 0"/>
      <geometry>
        <mesh filename="${mesh_path}/xaarm_base_link.STL"/>
      </geometry>
      <material name="">
        <color rgba="0.6471 0.6196 0.5882 1"/>
      </material>
    </visual>
    <collision>
      <origin xyz="0 0 0" rpy="0 0 0"/>
      <geometry>
        <mesh filename="${mesh_path}/xaarm_base_link.STL"/>
      </geometry>
    </collision>
  </link>

  <link name="link_1">
    <inertial>
      <origin xyz="-0.0016 -0.0004 0.0844" rpy="0 0 0"/>
      <mass value="2.4510"/>
      <inertia ixx="0.0065" ixy="-0.0002" ixz="0.0004" iyy="0.0073" iyz="0.0001" izz="0.0037"/>
    </inertial>
    <visual>
      <origin xyz="0 0 0" rpy="0 0 0"/>
      <geometry>
        <mesh filename="${mesh_path}/link_1.STL"/>
      </geometry>
      <material name="">
        <color rgba="1 1 1 1"/>
      </material>
    </visual>
    <collision>
      <origin xyz="0 0 0" rpy="0 0 0"/>
      <geometry>
        <mesh filename="${mesh_path}/link_1.STL"/>
      </geometry>
    </collision>
  </link>

  <link name="link_2">
    <inertial>
      <origin xyz="0.0436 -0.1601 0.0408" rpy="0 0 0"/>
      <mass value="5.5903"/>
      <inertia ixx="0.0535" ixy="0.0093" ixz="-0.0030" iyy="0.0208" iyz="0.0144" izz="0.0577"/>
    </inertial>
    <visual>
      <origin xyz="0 0 0" rpy="0 0 0"/>
      <geometry>
        <mesh filename="${mesh_path}/link_2.STL"/>
      </geometry>
      <material name="">
        <color rgba="1 1 1 1"/>
      </material>
    </visual>
    <collision>
      <origin xyz="0 0 0" rpy="0 0 0"/>
      <geometry>
        <mesh filename="${mesh_path}/link_2.STL"/>
      </geometry>
    </collision>
  </link>

  <link name="link_3">
    <inertial>
      <origin xyz="-0.0018 0.0824 0.0571" rpy="0 0 0"/>
      <mass value="2.7405"/>
      <inertia ixx="0.0123" ixy="-0.0028" ixz="-0.0020" iyy="0.0087" iyz="-0.0043" izz="0.0119"/>
    </inertial>
    <visual>
      <origin xyz="0 0 0" rpy="0 0 0"/>
      <geometry>
        <mesh filename="${mesh_path}/link_3.STL"/>
      </geometry>
      <material name="">
        <color rgba="1 1 1 1"/>
      </material>
    </visual>
    <collision>
      <origin xyz="0 0 0" rpy="0 0 0"/>
      <geometry>
        <mesh filename="${mesh_path}/link_3.STL"/>
      </geometry>
    </collision>
  </link>

  <link name="link_4">
    <inertial>
      <origin xyz="-0.0071 0.0238 0.1233" rpy="0 0 0"/>
      <mass value="1.2807"/>
      <inertia ixx="0.0094" ixy="0.0001" ixz="0" iyy="0.0091" iyz="-0.0007" izz="0.0014"/>
    </inertial>
    <visual>
      <origin xyz="0 0 0" rpy="0 0 0"/>
      <geometry>
        <mesh filename="${mesh_path}/link_4.STL"/>
      </geometry>
      <material name="">
        <color rgba="1 1 1 1"/>
      </material>
    </visual>
    <collision>
      <origin xyz="0 0 0" rpy="0 0 0"/>
      <geometry>
        <mesh filename="${mesh_path}/link_4.STL"/>
      </geometry>
    </collision>
  </link>

  <link name="link_5">
    <inertial>
      <origin xyz="-0.0122 -0.0571 0.0108" rpy="0 0 0"/>
      <mass value="1.2585"/>
      <inertia ixx="0.0022" ixy="-0.0004" ixz="0.0001" iyy="0.0015" iyz="-0.0002" izz="0.0027"/>
    </inertial>
    <visual>
      <origin xyz="0 0 0" rpy="0 0 0"/>
      <geometry>
        <mesh filename="${mesh_path}/link_5.STL"/>
      </geometry>
      <material name="">
        <color rgba="1 1 1 1"/>
      </material>
    </visual>
    <collision>
      <origin xyz="0 0 0" rpy="0 0 0"/>
      <geometry>
        <mesh filename="${mesh_path}/link_5.STL"/>
      </geometry>
    </collision>
  </link>

  <link name="end_effector">
    <inertial>
      <origin xyz="-0.0001 0 0.0096" rpy="0 0 0"/>
      <mass value="0.1516"/>
      <inertia ixx="0.0001" ixy="0" ixz="0" iyy="0.0001" iyz="0" izz="0.0001"/>
    </inertial>
    <visual>
      <origin xyz="0 0 0" rpy="0 0 0"/>
      <geometry>
        <mesh filename="${mesh_path}/end_effector.STL"/>
      </geometry>
      <material name="">
        <color rgba="1 1 1 1"/>
      </material>
    </visual>
    <collision>
      <origin xyz="0 0 0" rpy="0 0 0"/>
      <geometry>
        <mesh filename="${mesh_path}/end_effector.STL"/>
      </geometry>
    </collision>
  </link>

  <link name="gripper_base">
    <inertial>
      <origin xyz="0.0002 0 0.0346" rpy="0 0 0"/>
      <mass value="0.1959"/>
      <inertia ixx="0.0002" ixy="0" ixz="0" iyy="0.0003" iyz="0" izz="0.0001"/>
    </inertial>
    <visual>
      <origin xyz="0 0 0" rpy="0 0 0"/>
      <geometry>
        <mesh filename="${mesh_path}/gripper_base.STL"/>
      </geometry>
      <material name="">
        <color rgba="1 1 1 1"/>
      </material>
    </visual>
    <collision>
      <origin xyz="0 0 0" rpy="0 0 0"/>
      <geometry>
        <mesh filename="${mesh_path}/gripper_base.STL"/>
      </geometry>
    </collision>
  </link>

  <link name="right_gripper_arm">
    <inertial>
      <origin xyz="0.0426 0.0216 0" rpy="0 0 0"/>
      <mass value="0.0124"/>
      <inertia
        ixx="2.10000431804118E-06"
        ixy="-1.9640172280351E-06"
        ixz="-1.27319639884162E-20"
        iyy="8.48619770875024E-06"
        iyz="-2.01170324972896E-20"
        izz="1.03749899733759E-05" />
    </inertial>
    <visual>
      <origin xyz="0 0 0" rpy="0 0 0"/>
      <geometry>
        <mesh filename="${mesh_path}/right_gripper_arm.STL"/>
      </geometry>
      <material name="">
        <color rgba="1 1 1 1"/>
      </material>
    </visual>
    <collision>
      <origin xyz="0 0 0" rpy="0 0 0"/>
      <geometry>
        <mesh filename="${mesh_path}/right_gripper_arm.STL"/>
      </geometry>
    </collision>
  </link>

  <link name="right_tip">
    <inertial>
      <origin xyz="0.0225 0.0082 -0.0050" rpy="0 0 0"/>
      <mass value="0.0068"/>
      <inertia ixx="0" ixy="-0.0001" ixz="0" iyy="0.0001" iyz="0" izz="0.0001"/>
    </inertial>
    <visual>
      <origin xyz="0 0 0" rpy="0 0 0"/>
      <geometry>
        <mesh filename="${mesh_path}/right_tip.STL"/>
      </geometry>
      <material name="">
        <color rgba="0.2510 0.2510 0.2510 1"/>
      </material>
    </visual>
    <collision>
      <origin xyz="0 0 0" rpy="0 0 0"/>
      <geometry>
        <mesh filename="${mesh_path}/right_tip.STL"/>
      </geometry>
    </collision>
  </link>

  <link name="left_gripper_arm">
    <inertial>
      <origin xyz="0.0426 0.0216 0" rpy="0 0 0"/>
      <mass value="0.0124"/>
      <inertia
        ixx="2.10000431804118E-06"
        ixy="-1.96401722803509E-06"
        ixz="-5.29395592033938E-23"
        iyy="8.48619770875023E-06"
        iyz="-8.470329472543E-22"
        izz="1.03749899733759E-05" />    
      </inertial>
    <visual>
      <origin xyz="0 0 0" rpy="0 0 0"/>
      <geometry>
        <mesh filename="${mesh_path}/left_gripper_arm.STL"/>
      </geometry>
      <material name="">
        <color rgba="1 1 1 1"/>
      </material>
    </visual>
    <collision>
      <origin xyz="0 0 0" rpy="0 0 0"/>
      <geometry>
        <mesh filename="${mesh_path}/left_gripper_arm.STL"/>
      </geometry>
    </collision>
  </link>

  <link name="left_tip">
    <inertial>
      <origin xyz="0.0225 -0.0082 0" rpy="0 0 0"/>
      <mass value="0.0068"/>
      <inertia ixx="0" ixy="0.0001" ixz="0" iyy="0.0001" iyz="0" izz="0.0001"/>
    </inertial>
    <visual>
      <origin xyz="0 0 0" rpy="0 0 0"/>
      <geometry>
        <mesh filename="${mesh_path}/left_tip.STL"/>
      </geometry>
      <material name="">
        <color rgba="0.2510 0.2510 0.2510 1"/>
      </material>
    </visual>
    <collision>
      <origin xyz="0 0 0" rpy="0 0 0"/>
      <geometry>
        <mesh filename="${mesh_path}/left_tip.STL"/>
      </geometry>
    </collision>
  </link>

  <link name="gripper_camera">
    <inertial>
      <origin xyz="-0.0088 0 0" rpy="0 0 0"/>
      <mass value="0.0208"/>
      <inertia ixx="0" ixy="0" ixz="0" iyy="0" iyz="0" izz="0"/>
    </inertial>
    <visual>
      <origin xyz="0 0 0" rpy="0 0 0"/>
      <geometry>
        <mesh filename="${mesh_path}/gripper_camera.STL"/>
      </geometry>
      <material name="">
        <color rgba="0.7922 0.8196 0.9333 1"/>
      </material>
    </visual>
    <collision>
      <origin xyz="0 0 0" rpy="0 0 0"/>
      <geometry>
        <mesh filename="${mesh_path}/gripper_camera.STL"/>
      </geometry>
    </collision>
  </link>



  <joint name="joint_1" type="revolute">
    <origin xyz="0 0 0.1540" rpy="0 0 0"/>
    <parent link="xaarm_base_link"/>
    <child link="link_1"/>
    <axis xyz="0 0 -1"/>
    <limit lower="0" upper="6.28" effort="11" velocity="5.0" />
    <dynamics damping="0.5" friction="0.1"/> 
  </joint>

  <joint name="joint_2" type="revolute">
    <origin xyz="-0.0630 -0.0176 0.1150" rpy="-1.5708 0 0"/>
    <parent link="link_1"/>
    <child link="link_2"/>
    <axis xyz="0.9633 0 0.2685"/>
    <limit lower="0" upper="2.059" effort="11" velocity="5.0" />
    <dynamics damping="0.5" friction="0.1"/> 
  </joint>

  <joint name="joint_3" type="revolute">
    <origin xyz="-0.0226 -0.2769 0.0812" rpy="0 0 0"/>
    <parent link="link_2"/>
    <child link="link_3"/>
    <axis xyz="0.9633 0 0.2685"/>
    <limit lower="0.1" upper="3.8" effort="11" velocity="5.0" />
    <dynamics damping="0.5" friction="0.1"/>     
  </joint>

  <joint name="joint_4" type="revolute">
    <origin xyz="0.0374 0.1795 0.0779" rpy="-1.6771 0 0"/>
    <parent link="link_3"/>
    <child link="link_4"/>
    <axis xyz="-0.0296 0 -0.9996"/>
    <limit lower="0" upper="6.28" effort="11" velocity="5.0" />
    <dynamics damping="0.5" friction="0.1"/> 
  </joint>

  <joint name="joint_5" type="revolute">
    <origin xyz="0.0113 -0.0124 0.1998" rpy="1.5837 0 0"/>
    <parent link="link_4"/>
    <child link="link_5"/>
    <axis xyz="-0.4001 0 -0.9165"/>
    <limit lower="-0.58" upper="2.9" effort="11" velocity="5.0" />
    <dynamics damping="0.5" friction="0.1"/> 
  </joint>

  <joint name="end_effector_joint" type="revolute">
    <origin xyz="-0.0661 -0.0711 0.0289" rpy="0.6174 1.0599 -2.5487"/>
    <parent link="link_5"/>
    <child link="end_effector"/>
    <axis xyz="0 0 -1"/>
    <limit lower="0.271" upper="6.28" effort="11" velocity="5.0" />
    <dynamics damping="0.5" friction="0.1"/> 
  </joint>

  <joint name="gripper_base_joint" type="fixed">
    <origin xyz="-0.0002 0 0.0203" rpy="0 0 0"/>
    <parent link="end_effector"/>
    <child link="gripper_base"/>
    <axis xyz="0 0 0"/>
  </joint>

  <joint name="right_gripper_arm_joint" type="prismatic">
    <origin xyz="-0.0084 0.0010 0.0320" rpy="1.5708 -1.5708 0"/>
    <parent link="gripper_base"/>
    <child link="right_gripper_arm"/>
    <axis xyz="0 1 0"/>
    <limit lower="0.0010" upper="0.0380" effort="2" velocity="0.5"/>
    <dynamics damping="0.2" friction="0.05"/> 
  </joint>

  <joint name="left_gripper_arm_joint" type="prismatic">
    <origin xyz="0.0087 0.0010 0.0320" rpy="-1.5708 -1.5708 0"/>
    <parent link="gripper_base"/>
    <child link="left_gripper_arm"/>
    <axis xyz="0 1 0"/>
    <limit lower="0.0010" upper="0.0380" effort="2" velocity="0.5"/>
    <mimic joint="right_gripper_arm_joint" multiplier="1" offset="0"/>
    <dynamics damping="0.2" friction="0.05"/> 
  </joint>

  <joint name="right_tip_joint" type="fixed">
    <origin xyz="0.0740 0.0060 -0.0050" rpy="3.1416 0 0"/>
    <parent link="right_gripper_arm"/>
    <child link="right_tip"/>
    <axis xyz="0 0 0"/>
  </joint>  

  <joint name="left_tip_joint" type="fixed">
    <origin xyz="0.0740 0.0060 0" rpy="0 0 0"/>
    <parent link="left_gripper_arm"/>
    <child link="left_tip"/>
    <axis xyz="0 0 0"/>
  </joint>

  <joint name="gripper_camera_joint" type="fixed">
    <origin xyz="0.0002 0.0329 0.0612" rpy="1.5708 -1.5708 0"/>
    <parent link="gripper_base"/>
    <child link="gripper_camera"/>
    <axis xyz="0 0 0"/>
  </joint>
</robot>
